Workbook

Sheet Valores Gerais
A1: Segmento | B1: Turma | C1: Nome | D1: Disciplina | E1: Didática | F1: Apoio | G1: Tempo | H1: Avaliação | I1: Clima | J1: Respeito | K1: Domínio | L1: Média Geral por turma | M1: Média geral do ano
A2: Ensino Fundamental | B2: 6°A | C2: Alice | D2: Arte e Dança | E2: =AVERAGE('6°Ano'!B3:B27) -> 3.4166667 | F2: =AVERAGE('6°Ano'!C3:C27) -> 3.2 | G2: =AVERAGE('6°Ano'!D3:D27) -> 3.3333333 | H2: =AVERAGE('6°Ano'!E3:E27) -> 3.16 | I2: =AVERAGE('6°Ano'!F3:F27) -> 3.4 | J2: =AVERAGE('6°Ano'!G3:G27) -> 2.6521739 | K2: =AVERAGE('6°Ano'!H3:H27) -> 3.375 | L2: =AVERAGE(E2:K2) -> 3.2195963 | M2: =AVERAGE(L2:L5) -> 3.2388666
A3: Ensino Fundamental | B3: 6°B | C3: Alice | D3: Arte e Dança | E3: =AVERAGE('6°Ano'!B28:B48) -> 3.1904762 | F3: =AVERAGE('6°Ano'!C28:C48) -> 3.3 | G3: =AVERAGE('6°Ano'!D28:D48) -> 3.3333333 | H3: =AVERAGE('6°Ano'!E28:E48) -> 3.1428571 | I3: =AVERAGE('6°Ano'!F28:F48) -> 3.4761905 | J3: =AVERAGE('6°Ano'!G28:G48) -> 2.4285714 | K3: =AVERAGE('6°Ano'!H28:H48) -> 3.5238095 | L3: =AVERAGE(E3:K3) -> 3.1993197
A4: Ensino Fundamental | B4: 6°C | C4: Alice | D4: Arte e Dança | E4: =AVERAGE('6°Ano'!B49:B75) -> 3.3076923 | F4: =AVERAGE('6°Ano'!C49:C75) -> 3.4230769 | G4: =AVERAGE('6°Ano'!D49:D75) -> 3.6923077 | H4: =AVERAGE('6°Ano'!E49:E75) -> 3.2692308 | I4: =AVERAGE('6°Ano'!F49:F75) -> 3.4615385 | J4: =AVERAGE('6°Ano'!G49:G75) -> 2.5769231 | K4: =AVERAGE('6°Ano'!H49:H75) -> 3.8076923 | L4: =AVERAGE(E4:K4) -> 3.3626374
A5: Ensino Fundamental | B5: 6°D | C5: Alice | D5: Arte e Dança | E5: =AVERAGE('6°Ano'!B76:B98) -> 3.2173913 | F5: =AVERAGE('6°Ano'!C76:C98) -> 3.0869565 | G5: =AVERAGE('6°Ano'!D76:D98) -> 3.5217391 | H5: =AVERAGE('6°Ano'!E76:E98) -> 2.9565217 | I5: =AVERAGE('6°Ano'!F76:F98) -> 3.3913043 | J5: =AVERAGE('6°Ano'!G76:G98) -> 2.3913043 | K5: =AVERAGE('6°Ano'!H76:H98) -> 3.6521739 | L5: =AVERAGE(E5:K5) -> 3.173913
A6: Ensino Fundamental | B6: 6°A | C6: Daniela | D6: Ciências e Ciência Aplicada | E6: =AVERAGE('6°Ano'!I3:I27) -> 2.28 | F6: =AVERAGE('6°Ano'!J3:J27) -> 1.88 | G6: =AVERAGE('6°Ano'!K3:K27) -> 2.4 | H6: =AVERAGE('6°Ano'!L3:L27) -> 2.56 | I6: =AVERAGE('6°Ano'!M3:M27) -> 2.84 | J6: =AVERAGE('6°Ano'!N3:N27) -> 2.2 | K6: =AVERAGE('6°Ano'!O3:O27) -> 2.68 | L6: =AVERAGE(E6:K6) -> 2.4057143 | M6: =AVERAGE(L6:L9) -> 2.7098626
A7: Ensino Fundamental | B7: 6°B | C7: Daniela | D7: Ciências e Ciência Aplicada | E7: =AVERAGE('6°Ano'!I28:I48) -> 2.5238095 | F7: =AVERAGE('6°Ano'!J28:J48) -> 2.0952381 | G7: =AVERAGE('6°Ano'!K28:K48) -> 2.4285714 | H7: =AVERAGE('6°Ano'!L28:L48) -> 2.8095238 | I7: =AVERAGE('6°Ano'!M28:M48) -> 2.9047619 | J7: =AVERAGE('6°Ano'!N28:N48) -> 2.3809524 | K7: =AVERAGE('6°Ano'!O28:O48) -> 2.6190476 | L7: =AVERAGE(E7:K7) -> 2.537415
A8: Ensino Fundamental | B8: 6°C | C8: Daniela | D8: Ciências e Ciência Aplicada | E8: =AVERAGE('6°Ano'!I49:I75) -> 3.0384615 | F8: =AVERAGE('6°Ano'!J49:J75) -> 2.3461538 | G8: =AVERAGE('6°Ano'!K49:K75) -> 3.1153846 | H8: =AVERAGE('6°Ano'!L49:L75) -> 3.1923077 | I8: =AVERAGE('6°Ano'!M49:M75) -> 3.5384615 | J8: =AVERAGE('6°Ano'!N49:N75) -> 2.8076923 | K8: =AVERAGE('6°Ano'!O49:O75) -> 3.1923077 | L8: =AVERAGE(E8:K8) -> 3.032967
A9: Ensino Fundamental | B9: 6°D | C9: Daniela | D9: Ciências e Ciência Aplicada | E9: =AVERAGE('6°Ano'!I76:I98) -> 2.9130435 | F9: =AVERAGE('6°Ano'!J76:J98) -> 2.4782609 | G9: =AVERAGE('6°Ano'!K76:K98) -> 2.7826087 | H9: =AVERAGE('6°Ano'!L76:L98) -> 3.0434783 | I9: =AVERAGE('6°Ano'!M76:M98) -> 3.2608696 | J9: =AVERAGE('6°Ano'!N76:N98) -> 2.3913043 | K9: =AVERAGE('6°Ano'!O76:O98) -> 3.173913 | L9: =AVERAGE(E9:K9) -> 2.863354
A10: Ensino Fundamental | B10: 6°A | C10: Danielle | D10: Ciências e Ciência Aplicada | E10: =AVERAGE('6°Ano'!P3:P27) -> 3.12 | F10: =AVERAGE('6°Ano'!Q3:Q27) -> 3.04 | G10: =AVERAGE('6°Ano'!R3:R27) -> 3.16 | H10: =AVERAGE('6°Ano'!S3:S27) -> 3.08 | I10: =AVERAGE('6°Ano'!T3:T27) -> 2.88 | J10: =AVERAGE('6°Ano'!U3:U27) -> 2.88 | K10: =AVERAGE('6°Ano'!V3:V27) -> 3.04 | L10: =AVERAGE(E10:K10) -> 3.0285714 | M10: =AVERAGE(L10:L13) -> 3.3158056
A11: Ensino Fundamental | B11: 6°B | C11: Danielle | D11: Ciências e Ciência Aplicada | E11: =AVERAGE('6°Ano'!P28:P48) -> 3.5 | F11: =AVERAGE('6°Ano'!Q28:Q48) -> 3.3 | G11: =AVERAGE('6°Ano'!R28:R48) -> 3.55 | H11: =AVERAGE('6°Ano'!S28:S48) -> 3.5 | I11: =AVERAGE('6°Ano'!T28:T48) -> 3.2 | J11: =AVERAGE('6°Ano'!U28:U48) -> 3.35 | K11: =AVERAGE('6°Ano'!V28:V48) -> 3.55 | L11: =AVERAGE(E11:K11) -> 3.4214286
A12: Ensino Fundamental | B12: 6°C | C12: Danielle | D12: Ciências e Ciência Aplicada | E12: =AVERAGE('6°Ano'!P49:P75) -> 3.6538462 | F12: =AVERAGE('6°Ano'!Q49:Q75) -> 3.3076923 | G12: =AVERAGE('6°Ano'!R49:R75) -> 3.5 | H12: =AVERAGE('6°Ano'!S49:S75) -> 3.4615385 | I12: =AVERAGE('6°Ano'!T49:T75) -> 3.88 | J12: =AVERAGE('6°Ano'!U49:U75) -> 3.1538462 | K12: =AVERAGE('6°Ano'!V49:V75) -> 3.7692308 | L12: =AVERAGE(E12:K12) -> 3.5323077
A13: Ensino Fundamental | B13: 6°D | C13: Danielle | D13: Ciências e Ciência Aplicada | E13: =AVERAGE('6°Ano'!P76:P98) -> 3.3478261 | F13: =AVERAGE('6°Ano'!Q76:Q98) -> 2.9090909 | G13: =AVERAGE('6°Ano'!R76:R98) -> 3.3181818 | H13: =AVERAGE('6°Ano'!S76:S98) -> 3.3913043 | I13: =AVERAGE('6°Ano'!T76:T98) -> 3.4782609 | J13: =AVERAGE('6°Ano'!U76:U98) -> 3 | K13: =AVERAGE('6°Ano'!V76:V98) -> 3.5217391 | L13: =AVERAGE(E13:K13) -> 3.2809147
A14: Ensino Fundamental | B14: 6°A | C14: Diego | D14: Matemática | E14: =AVERAGE('6°Ano'!W3:W27) -> 3.64 | F14: =AVERAGE('6°Ano'!X3:X27) -> 3.6 | G14: =AVERAGE('6°Ano'!Y3:Y27) -> 3.64 | H14: =AVERAGE('6°Ano'!Z3:Z27) -> 3.48 | I14: =AVERAGE('6°Ano'!AA3:AA27) -> 3.6 | J14: =AVERAGE('6°Ano'!AB3:AB27) -> 3.44 | K14: =AVERAGE('6°Ano'!AC3:AC27) -> 3.64 | L14: =AVERAGE(E14:K14) -> 3.5771429 | M14: =AVERAGE(L14:L17) -> 3.6525755
A15: Ensino Fundamental | B15: 6°B | C15: Diego | D15: Matemática | E15: =AVERAGE('6°Ano'!W28:W48) -> 3.8095238 | F15: =AVERAGE('6°Ano'!X28:X48) -> 3.4761905 | G15: =AVERAGE('6°Ano'!Y28:Y48) -> 3.8571429 | H15: =AVERAGE('6°Ano'!Z28:Z48) -> 3.7619048 | I15: =AVERAGE('6°Ano'!AA28:AA48) -> 3.6666667 | J15: =AVERAGE('6°Ano'!AB28:AB48) -> 3.5238095 | K15: =AVERAGE('6°Ano'!AC28:AC48) -> 3.6666667 | L15: =AVERAGE(E15:K15) -> 3.6802721
A16: Ensino Fundamental | B16: 6°C | C16: Diego | D16: Matemática | E16: =AVERAGE('6°Ano'!W49:W75) -> 3.8888889 | F16: =AVERAGE('6°Ano'!X49:X75) -> 3.3703704 | G16: =AVERAGE('6°Ano'!Y49:Y75) -> 3.5925926 | H16: =AVERAGE('6°Ano'!Z49:Z75) -> 3.7037037 | I16: =AVERAGE('6°Ano'!AA49:AA75) -> 3.8518519 | J16: =AVERAGE('6°Ano'!AB49:AB75) -> 3.4814815 | K16: =AVERAGE('6°Ano'!AC49:AC75) -> 3.4074074 | L16: =AVERAGE(E16:K16) -> 3.6137566
A17: Ensino Fundamental | B17: 6°D | C17: Diego | D17: Matemática | E17: =AVERAGE('6°Ano'!W76:W98) -> 3.9130435 | F17: =AVERAGE('6°Ano'!X76:X98) -> 3.7826087 | G17: =AVERAGE('6°Ano'!Y76:Y98) -> 3.8695652 | H17: =AVERAGE('6°Ano'!Z76:Z98) -> 3.5217391 | I17: =AVERAGE('6°Ano'!AA76:AA98) -> 3.9130435 | J17: =AVERAGE('6°Ano'!AB76:AB98) -> 3.3478261 | K17: =AVERAGE('6°Ano'!AC76:AC98) -> 3.826087 | L17: =AVERAGE(E17:K17) -> 3.7391304
A18: Ensino Fundamental | B18: 6°A | C18: Karen | D18: Redação | E18: =AVERAGE('6°Ano'!AD3:AD27) -> 2.16 | F18: =AVERAGE('6°Ano'!AE3:AE27) -> 1.88 | G18: =AVERAGE('6°Ano'!AF3:AF27) -> 2.32 | H18: =AVERAGE('6°Ano'!AG3:AG27) -> 2.56 | I18: =AVERAGE('6°Ano'!AH3:AH27) -> 2.52 | J18: =AVERAGE('6°Ano'!AI3:AI27) -> 2.04 | K18: =AVERAGE('6°Ano'!AJ3:AJ27) -> 2.52 | L18: =AVERAGE(E18:K18) -> 2.2857143 | M18: =AVERAGE(L18:L21) -> 2.8255102
A19: Ensino Fundamental | B19: 6°B | C19: Karen | D19: Redação | E19: =AVERAGE('6°Ano'!AD28:AD48) -> 2.3809524 | F19: =AVERAGE('6°Ano'!AE28:AE48) -> 1.8095238 | G19: =AVERAGE('6°Ano'!AF28:AF48) -> 2.5714286 | H19: =AVERAGE('6°Ano'!AG28:AG48) -> 3 | I19: =AVERAGE('6°Ano'!AH28:AH48) -> 2.7142857 | J19: =AVERAGE('6°Ano'!AI28:AI48) -> 2.5238095 | K19: =AVERAGE('6°Ano'!AJ28:AJ48) -> 2.952381 | L19: =AVERAGE(E19:K19) -> 2.5646259
A20: Ensino Fundamental | B20: 6°C | C20: Karen | D20: Redação | E20: =AVERAGE('6°Ano'!AD49:AD75) -> 3.3461538 | F20: =AVERAGE('6°Ano'!AE49:AE75) -> 2.3461538 | G20: =AVERAGE('6°Ano'!AF49:AF75) -> 3.4230769 | H20: =AVERAGE('6°Ano'!AG49:AG75) -> 3.3461538 | I20: =AVERAGE('6°Ano'!AH49:AH75) -> 3.8076923 | J20: =AVERAGE('6°Ano'!AI49:AI75) -> 3.0384615 | K20: =AVERAGE('6°Ano'!AJ49:AJ75) -> 3.7692308 | L20: =AVERAGE(E20:K20) -> 3.2967033
A21: Ensino Fundamental | B21: 6°D | C21: Karen | D21: Redação | E21: =AVERAGE('6°Ano'!AD76:AD98) -> 3.3043478 | F21: =AVERAGE('6°Ano'!AE76:AE98) -> 2.6956522 | G21: =AVERAGE('6°Ano'!AF76:AF98) -> 3.3043478 | H21: =AVERAGE('6°Ano'!AG76:AG98) -> 2.9545455 | I21: =AVERAGE('6°Ano'!AH76:AH98) -> 3.6521739 | J21: =AVERAGE('6°Ano'!AI76:AI98) -> 2.7391304 | K21: =AVERAGE('6°Ano'!AJ76:AJ98) -> 3.4347826 | L21: =AVERAGE(E21:K21) -> 3.1549972
A22: Ensino Fundamental | B22: 6°A | C22: Luana | D22: Ciência Aplicada | E22: =AVERAGE('6°Ano'!AK3:AK27) -> 3.48 | F22: =AVERAGE('6°Ano'!AL3:AL27) -> 3.56 | G22: =AVERAGE('6°Ano'!AM3:AM27) -> 3.52 | H22: =AVERAGE('6°Ano'!AN3:AN27) -> 3.48 | I22: =AVERAGE('6°Ano'!AO3:AO27) -> 3.56 | J22: =AVERAGE('6°Ano'!AP3:AP27) -> 3.25 | K22: =AVERAGE('6°Ano'!AQ3:AQ27) -> 3.56 | L22: =AVERAGE(E22:K22) -> 3.4871429 | M22: =AVERAGE(L22:L25) -> 3.4212806
A23: Ensino Fundamental | B23: 6°B | C23: Luana | D23: Ciência Aplicada | E23: =AVERAGE('6°Ano'!AK28:AK48) -> 3.3333333 | F23: =AVERAGE('6°Ano'!AL28:AL48) -> 3.4285714 | G23: =AVERAGE('6°Ano'!AM28:AM48) -> 2.952381 | H23: =AVERAGE('6°Ano'!AN28:AN48) -> 3.3333333 | I23: =AVERAGE('6°Ano'!AO28:AO48) -> 3.2857143 | J23: =AVERAGE('6°Ano'!AP28:AP48) -> 3.2 | K23: =AVERAGE('6°Ano'!AQ28:AQ48) -> 3.55 | L23: =AVERAGE(E23:K23) -> 3.297619
A24: Ensino Fundamental | B24: 6°C | C24: Luana | D24: Ciência Aplicada | E24: =AVERAGE('6°Ano'!AK49:AK75) -> 3.3461538 | F24: =AVERAGE('6°Ano'!AL49:AL75) -> 3.2307692 | G24: =AVERAGE('6°Ano'!AM49:AM75) -> 3.2692308 | H24: =AVERAGE('6°Ano'!AN49:AN75) -> 3.3461538 | I24: =AVERAGE('6°Ano'!AO49:AO75) -> 3.5384615 | J24: =AVERAGE('6°Ano'!AP49:AP75) -> 3.1153846 | K24: =AVERAGE('6°Ano'!AQ49:AQ75) -> 3.5769231 | L24: =AVERAGE(E24:K24) -> 3.3461538
A25: Ensino Fundamental | B25: 6°D | C25: Luana | D25: Ciência Aplicada | E25: =AVERAGE('6°Ano'!AK76:AK98) -> 3.5217391 | F25: =AVERAGE('6°Ano'!AL76:AL98) -> 3.3913043 | G25: =AVERAGE('6°Ano'!AM76:AM98) -> 3.5652174 | H25: =AVERAGE('6°Ano'!AN76:AN98) -> 3.5217391 | I25: =AVERAGE('6°Ano'!AO76:AO98) -> 3.7826087 | J25: =AVERAGE('6°Ano'!AP76:AP98) -> 3.2272727 | K25: =AVERAGE('6°Ano'!AQ76:AQ98) -> 3.8695652 | L25: =AVERAGE(E25:K25) -> 3.5542067
A26: Ensino Fundamental | B26: 6°A | C26: Marcia | D26: Arte Visual | E26: =AVERAGE('6°Ano'!AR3:AR27) -> 3.12 | F26: =AVERAGE('6°Ano'!AS3:AS27) -> 3.24 | G26: =AVERAGE('6°Ano'!AT3:AT27) -> 3.36 | H26: =AVERAGE('6°Ano'!AU3:AU27) -> 2.7916667 | I26: =AVERAGE('6°Ano'!AV3:AV27) -> 3.32 | J26: =AVERAGE('6°Ano'!AW3:AW27) -> 2.96 | K26: =AVERAGE('6°Ano'!AX3:AX27) -> 3.24 | L26: =AVERAGE(E26:K26) -> 3.147381 | M26: =AVERAGE(L26:L29) -> 2.8849418
A27: Ensino Fundamental | B27: 6°B | C27: Marcia | D27: Arte Visual | E27: =AVERAGE('6°Ano'!AR28:AR48) -> 2.6666667 | F27: =AVERAGE('6°Ano'!AS28:AS48) -> 2.7142857 | G27: =AVERAGE('6°Ano'!AT28:AT48) -> 2.7619048 | H27: =AVERAGE('6°Ano'!AU28:AU48) -> 2.6190476 | I27: =AVERAGE('6°Ano'!AV28:AV48) -> 3 | J27: =AVERAGE('6°Ano'!AW28:AW48) -> 2.5714286 | K27: =AVERAGE('6°Ano'!AX28:AX48) -> 3.047619 | L27: =AVERAGE(E27:K27) -> 2.7687075
A28: Ensino Fundamental | B28: 6°C | C28: Marcia | D28: Arte Visual | E28: =AVERAGE('6°Ano'!AR49:AR75) -> 3.1153846 | F28: =AVERAGE('6°Ano'!AS49:AS75) -> 3.2307692 | G28: =AVERAGE('6°Ano'!AT49:AT75) -> 3.0769231 | H28: =AVERAGE('6°Ano'!AU49:AU75) -> 3 | I28: =AVERAGE('6°Ano'!AV49:AV75) -> 3.64 | J28: =AVERAGE('6°Ano'!AW49:AW75) -> 2.8076923 | K28: =AVERAGE('6°Ano'!AX49:AX75) -> 3.5384615 | L28: =AVERAGE(E28:K28) -> 3.2013187
A29: Ensino Fundamental | B29: 6°D | C29: Marcia | D29: Arte Visual | E29: =AVERAGE('6°Ano'!AR76:AR98) -> 2.3043478 | F29: =AVERAGE('6°Ano'!AS76:AS98) -> 2.6086957 | G29: =AVERAGE('6°Ano'!AT76:AT98) -> 2.0869565 | H29: =AVERAGE('6°Ano'!AU76:AU98) -> 2.3043478 | I29: =AVERAGE('6°Ano'!AV76:AV98) -> 3.1304348 | J29: =AVERAGE('6°Ano'!AW76:AW98) -> 2.2608696 | K29: =AVERAGE('6°Ano'!AX76:AX98) -> 2.2608696 | L29: =AVERAGE(E29:K29) -> 2.4223602
A30: Ensino Fundamental | B30: 6°A | C30: Mário | D30: Geografia | E30: =AVERAGE('6°Ano'!AY3:AY27) -> 2.88 | F30: =AVERAGE('6°Ano'!AZ3:AZ27) -> 2.72 | G30: =AVERAGE('6°Ano'!BA3:BA27) -> 3.04 | H30: =AVERAGE('6°Ano'!BB3:BB27) -> 3.52 | I30: =AVERAGE('6°Ano'!BC3:BC27) -> 3.36 | J30: =AVERAGE('6°Ano'!BD3:BD27) -> 3.64 | K30: =AVERAGE('6°Ano'!BE3:BE27) -> 3.08 | L30: =AVERAGE(E30:K30) -> 3.1771429 | M30: =AVERAGE(L30:L33) -> 3.1490252
A31: Ensino Fundamental | B31: 6°B | C31: Mário | D31: Geografia | E31: =AVERAGE('6°Ano'!AY28:AY48) -> 2.9047619 | F31: =AVERAGE('6°Ano'!AZ28:AZ48) -> 2.1904762 | G31: =AVERAGE('6°Ano'!BA28:BA48) -> 2.7619048 | H31: =AVERAGE('6°Ano'!BB28:BB48) -> 3.3809524 | I31: =AVERAGE('6°Ano'!BC28:BC48) -> 3.1904762 | J31: =AVERAGE('6°Ano'!BD28:BD48) -> 3.2380952 | K31: =AVERAGE('6°Ano'!BE28:BE48) -> 3 | L31: =AVERAGE(E31:K31) -> 2.952381
A32: Ensino Fundamental | B32: 6°C | C32: Mário | D32: Geografia | E32: =AVERAGE('6°Ano'!AY49:AY75) -> 3.4230769 | F32: =AVERAGE('6°Ano'!AZ49:AZ75) -> 2.8076923 | G32: =AVERAGE('6°Ano'!BA49:BA75) -> 3.0769231 | H32: =AVERAGE('6°Ano'!BB49:BB75) -> 3.9230769 | I32: =AVERAGE('6°Ano'!BC49:BC75) -> 3.5384615 | J32: =AVERAGE('6°Ano'!BD49:BD75) -> 4 | K32: =AVERAGE('6°Ano'!BE49:BE75) -> 3.6153846 | L32: =AVERAGE(E32:K32) -> 3.4835165
A33: Ensino Fundamental | B33: 6°D | C33: Mário | D33: Geografia | E33: =AVERAGE('6°Ano'!AY76:AY98) -> 2.7391304 | F33: =AVERAGE('6°Ano'!AZ76:AZ98) -> 2.6086957 | G33: =AVERAGE('6°Ano'!BA76:BA98) -> 2.6086957 | H33: =AVERAGE('6°Ano'!BB76:BB98) -> 3.3478261 | I33: =AVERAGE('6°Ano'!BC76:BC98) -> 3.3478261 | J33: =AVERAGE('6°Ano'!BD76:BD98) -> 3.2727273 | K33: =AVERAGE('6°Ano'!BE76:BE98) -> 2.9565217 | L33: =AVERAGE(E33:K33) -> 2.9830604
A34: Ensino Fundamental | B34: 6°A | C34: Monique | D34: LIV | E34: =AVERAGE('6°Ano'!BF3:BF27) -> 3.72 | F34: =AVERAGE('6°Ano'!BG3:BG27) -> 3.84 | G34: =AVERAGE('6°Ano'!BH3:BH27) -> 3.96 | H34: =AVERAGE('6°Ano'!BI3:BI27) -> 3.84 | I34: =AVERAGE('6°Ano'!BJ3:BJ27) -> 3.8333333 | J34: =AVERAGE('6°Ano'!BK3:BK27) -> 3.8 | K34: =AVERAGE('6°Ano'!BL3:BL27) -> 3.9166667 | L34: =AVERAGE(E34:K34) -> 3.8442857 | M34: =AVERAGE(L34:L37) -> 3.784096
A35: Ensino Fundamental | B35: 6°B | C35: Monique | D35: LIV | E35: =AVERAGE('6°Ano'!BF28:BF48) -> 3.7619048 | F35: =AVERAGE('6°Ano'!BG28:BG48) -> 3.7142857 | G35: =AVERAGE('6°Ano'!BH28:BH48) -> 3.8095238 | H35: =AVERAGE('6°Ano'!BI28:BI48) -> 3.4285714 | I35: =AVERAGE('6°Ano'!BJ28:BJ48) -> 3.4 | J35: =AVERAGE('6°Ano'!BK28:BK48) -> 3.4285714 | K35: =AVERAGE('6°Ano'!BL28:BL48) -> 3.8095238 | L35: =AVERAGE(E35:K35) -> 3.6217687
A36: Ensino Fundamental | B36: 6°C | C36: Monique | D36: LIV | E36: =AVERAGE('6°Ano'!BF49:BF75) -> 3.9230769 | F36: =AVERAGE('6°Ano'!BG49:BG75) -> 3.8461538 | G36: =AVERAGE('6°Ano'!BH49:BH75) -> 3.9230769 | H36: =AVERAGE('6°Ano'!BI49:BI75) -> 3.6923077 | I36: =AVERAGE('6°Ano'!BJ49:BJ75) -> 3.8076923 | J36: =AVERAGE('6°Ano'!BK49:BK75) -> 3.5384615 | K36: =AVERAGE('6°Ano'!BL49:BL75) -> 3.9615385 | L36: =AVERAGE(E36:K36) -> 3.8131868
A37: Ensino Fundamental | B37: 6°D | C37: Monique | D37: LIV | E37: =AVERAGE('6°Ano'!BF76:BF98) -> 3.9130435 | F37: =AVERAGE('6°Ano'!BG76:BG98) -> 3.9565217 | G37: =AVERAGE('6°Ano'!BH76:BH98) -> 3.9565217 | H37: =AVERAGE('6°Ano'!BI76:BI98) -> 3.6086957 | I37: =AVERAGE('6°Ano'!BJ76:BJ98) -> 3.9565217 | J37: =AVERAGE('6°Ano'!BK76:BK98) -> 3.6086957 | K37: =AVERAGE('6°Ano'!BL76:BL98) -> 4 | L37: =AVERAGE(E37:K37) -> 3.8571429
A38: Ensino Fundamental | B38: 6°A | C38: Pavarina | D38: Educação Física | E38: =AVERAGE('6°Ano'!BM3:BM27) -> 3.52 | F38: =AVERAGE('6°Ano'!BN3:BN27) -> 3.48 | G38: =AVERAGE('6°Ano'!BO3:BO27) -> 3.32 | H38: =AVERAGE('6°Ano'!BP3:BP27) -> 3.68 | I38: =AVERAGE('6°Ano'!BQ3:BQ27) -> 3.4 | J38: =AVERAGE('6°Ano'!BR3:BR27) -> 3.56 | K38: =AVERAGE('6°Ano'!BS3:BS27) -> 3.36 | L38: =AVERAGE(E38:K38) -> 3.4742857 | M38: =AVERAGE(L38:L41) -> 3.4671487
A39: Ensino Fundamental | B39: 6°B | C39: Pavarina | D39: Educação Física | E39: =AVERAGE('6°Ano'!BM28:BM48) -> 3.7 | F39: =AVERAGE('6°Ano'!BN28:BN48) -> 3.6190476 | G39: =AVERAGE('6°Ano'!BO28:BO48) -> 3.1904762 | H39: =AVERAGE('6°Ano'!BP28:BP48) -> 3.5238095 | I39: =AVERAGE('6°Ano'!BQ28:BQ48) -> 3.5714286 | J39: =AVERAGE('6°Ano'!BR28:BR48) -> 3.047619 | K39: =AVERAGE('6°Ano'!BS28:BS48) -> 3 | L39: =AVERAGE(E39:K39) -> 3.3789116
A40: Ensino Fundamental | B40: 6°C | C40: Pavarina | D40: Educação Física | E40: =AVERAGE('6°Ano'!BM49:BM75) -> 3.8461538 | F40: =AVERAGE('6°Ano'!BN49:BN75) -> 3.6923077 | G40: =AVERAGE('6°Ano'!BO49:BO75) -> 3.6923077 | H40: =AVERAGE('6°Ano'!BP49:BP75) -> 3.8076923 | I40: =AVERAGE('6°Ano'!BQ49:BQ75) -> 3.5 | J40: =AVERAGE('6°Ano'!BR49:BR75) -> 3.5384615 | K40: =AVERAGE('6°Ano'!BS49:BS75) -> 3.3846154 | L40: =AVERAGE(E40:K40) -> 3.6373626
...

Sheet 6°Ano
B1: Alice - Arte e Dança | I1: Daniela - Ciências e Ciências Aplicada | P1: Danielle - Ciências e Ciências Aplicada | W1: Diego - Matemática | AD1: Karen - Redação | AK1: Luana - Ciência Aplicada | AR1: Márcia - Arte Visual | AY1: Mário - Geografia | BF1: Monique - LIV | BM1: Pavarina - Educação Física | BT1: Renata - Inglês CLIL | CA1: Ricardo - História | CH1: Rita - Leitura e Gramática | CO1: Valeska - Inglês Language
A2: Perguntas | B2: 1 | C2: 2 | D2: 3 | E2: 4 | F2: 5 | G2: 6 | H2: 7 | I2: 1 | J2: 2 | K2: 3 | L2: 4 | M2: 5 | N2: 6 | O2: 7 | P2: 1 | Q2: 2 | R2: 3 | S2: 4 | T2: 5 | U2: 6 | V2: 7 | W2: 1 | X2: 2 | Y2: 3 | Z2: 4 | AA2: 5 | AB2: 6 | AC2: 7 | AD2: 1 | AE2: 2 | AF2: 3 | AG2: 4 | AH2: 5 | AI2: 6 | AJ2: 7 | AK2: 1 | AL2: 2 | AM2: 3 | AN2: 4 | AO2: 5 | AP2: 6 | AQ2: 7 | AR2: 1 | AS2: 2 | AT2: 3 | AU2: 4 | AV2: 5 | AW2: 6 | AX2: 7 | AY2: 1 | AZ2: 2 | BA2: 3 | BB2: 4 | BC2: 5 | BD2: 6 | BE2: 7 | BF2: 1 | BG2: 2 | BH2: 3 | BI2: 4 | BJ2: 5 | BK2: 6 | BL2: 7 | BM2: 1 | BN2: 2 | BO2: 3 | BP2: 4 | BQ2: 5 | BR2: 6 | BS2: 7 | BT2: 1 | BU2: 2 | BV2: 3 | BW2: 4 | BX2: 5 | BY2: 6 | BZ2: 7 | CA2: 1 | CB2: 2 | CC2: 3 | CD2: 4 | CE2: 5 | CF2: 6 | CG2: 7 | CH2: 1 | CI2: 2 | CJ2: 3 | CK2: 4 | CL2: 5 | CM2: 6 | CN2: 7 | CO2: 1 | CP2: 2 | CQ2: 3 | CR2: 4 | CS2: 5 | CT2: 6 | CU2: 7
A3: 6º ano A | B3: 4 | C3: 3 | D3: 3 | E3: 3 | F3: 3 | G3: 3 | H3: 3 | I3: 3 | J3: 2 | K3: 3 | L3: 3 | M3: 3 | N3: 3 | O3: 3 | P3: 3 | Q3: 4 | R3: 3 | S3: 3 | T3: 3 | U3: 3 | V3: 3 | W3: 3 | X3: 3 | Y3: 3 | Z3: 3 | AA3: 3 | AB3: 3 | AC3: 3 | AD3: 3 | AE3: 3 | AF3: 3 | AG3: 3 | AH3: 3 | AI3: 3 | AJ3: 3 | AK3: 3 | AL3: 3 | AM3: 3 | AN3: 3 | AO3: 3 | AP3: 3 | AQ3: 3 | AR3: 3 | AS3: 3 | AT3: 3 | AU3: 3 | AV3: 3 | AW3: 3 | AX3: 3 | AY3: 3 | AZ3: 3 | BA3: 3 | BB3: 3 | BC3: 3 | BD3: 3 | BE3: 3 | BF3: 4 | BG3: 4 | BH3: 4 | BI3: 4 | BJ3: 4 | BK3: 4 | BL3: 4 | BM3: 4 | BN3: 4 | BO3: 4 | BP3: 4 | BQ3: 4 | BR3: 4 | BS3: 4 | BT3: 4 | BU3: 4 | BV3: 4 | BW3: 4 | BX3: 4 | BY3: 4 | BZ3: 4 | CA3: 4 | CB3: 4 | CC3: 4 | CD3: 4 | CE3: 4 | CF3: 4 | CG3: 4 | CH3: 4 | CI3: 4 | CJ3: 4 | CK3: 4 | CL3: 4 | CM3: 4 | CN3: 4 | CO3: 3 | CP3: 3 | CQ3: 3 | CR3: 3 | CS3: 3 | CT3: 3 | CU3: 3
A4: 6º ano A | B4: 2 | C4: 3 | D4: 4 | E4: 3 | F4: 4 | G4: 3 | H4: 4 | I4: 1 | J4: 2 | K4: 3 | L4: 2 | M4: 4 | N4: 2 | O4: 2 | P4: 4 | Q4: 4 | R4: 4 | S4: 4 | T4: 4 | U4: 4 | V4: 4 | W4: 4 | X4: 4 | Y4: 4 | Z4: 4 | AA4: 4 | AB4: 4 | AC4: 4 | AD4: 2 | AE4: 2 | AF4: 2 | AG4: 2 | AH4: 1 | AI4: 1 | AJ4: 3 | AK4: 3 | AL4: 3 | AM4: 3 | AN4: 3 | AO4: 3 | AP4: 3 | AQ4: 3 | AR4: 3 | AS4: 2 | AT4: 3 | AU4: 2 | AV4: 3 | AW4: 2 | AX4: 3 | AY4: 3 | AZ4: 3 | BA4: 3 | BB4: 3 | BC4: 4 | BD4: 4 | BE4: 2 | BF4: 4 | BG4: 4 | BH4: 4 | BI4: 4 | BJ4: 4 | BK4: 4 | BL4: 4 | BM4: 4 | BN4: 4 | BO4: 4 | BP4: 4 | BQ4: 4 | BR4: 4 | BS4: 4 | BT4: 3 | BU4: 3 | BV4: 3 | BW4: 3 | BX4: 3 | BY4: 3 | BZ4: 4 | CA4: 4 | CB4: 4 | CC4: 4 | CD4: 4 | CE4: 4 | CF4: 4 | CG4: 4 | CH4: 4 | CI4: 4 | CJ4: 4 | CK4: 4 | CL4: 4 | CM4: 4 | CN4: 4 | CO4: 2 | CP4: 3 | CQ4: 2 | CR4: 3 | CS4: 2 | CT4: 3 | CU4: 2
A5: 6º ano A | B5: 4 | C5: 2 | D5: 4 | E5: 4 | F5: 4 | G5: 3 | H5: 4 | I5: 4 | J5: 4 | K5: 4 | L5: 4 | M5: 4 | N5: 4 | O5: 4 | P5: 4 | Q5: 4 | R5: 4 | S5: 4 | T5: 4 | U5: 4 | V5: 4 | W5: 4 | X5: 4 | Y5: 4 | Z5: 4 | AA5: 4 | AB5: 4 | AC5: 4 | AD5: 4 | AE5: 4 | AF5: 4 | AG5: 4 | AH5: 4 | AI5: 4 | AJ5: 4 | AK5: 4 | AL5: 4 | AM5: 4 | AN5: 4 | AO5: 4 | AP5: 4 | AQ5: 4 | AR5: 4 | AS5: 4 | AT5: 4 | AU5: 4 | AV5: 4 | AW5: 4 | AX5: 4 | AY5: 4 | AZ5: 4 | BA5: 4 | BB5: 4 | BC5: 4 | BD5: 4 | BE5: 4 | BF5: 4 | BG5: 4 | BH5: 4 | BI5: 4 | BJ5: 4 | BK5: 4 | BL5: 4 | BM5: 4 | BN5: 4 | BO5: 4 | BP5: 4 | BQ5: 4 | BR5: 4 | BS5: 4 | BT5: 4 | BU5: 4 | BV5: 4 | BW5: 4 | BX5: 4 | BY5: 4 | BZ5: 4 | CA5: 4 | CB5: 4 | CC5: 4 | CD5: 4 | CE5: 4 | CF5: 4 | CG5: 4 | CH5: 4 | CI5: 4 | CJ5: 4 | CK5: 4 | CL5: 4 | CM5: 4 | CN5: 4 | CO5: 4 | CP5: 4 | CQ5: 4 | CR5: 4 | CS5: 4 | CT5: 4 | CU5: 4
A6: 6º ano A | B6: 4 | C6: 4 | D6: 4 | E6: 4 | F6: 4 | G6: 4 | H6: 4 | I6: 1 | J6: 1 | K6: 1 | L6: 1 | M6: 1 | N6: 1 | O6: 1 | P6: 1 | Q6: 1 | R6: 1 | S6: 1 | T6: 1 | U6: 1 | V6: 1 | W6: 4 | X6: 4 | Y6: 4 | Z6: 4 | AA6: 4 | AB6: 4 | AC6: 4 | AD6: 2 | AE6: 2 | AF6: 2 | AG6: 2 | AH6: 2 | AI6: 2 | AJ6: 2 | AK6: 4 | AL6: 4 | AM6: 4 | AN6: 4 | AO6: 4 | AP6: 4 | AQ6: 4 | AR6: 4 | AS6: 4 | AT6: 4 | AU6: 4 | AV6: 4 | AW6: 4 | AX6: 4 | AY6: 4 | AZ6: 4 | BA6: 4 | BB6: 4 | BC6: 4 | BD6: 4 | BE6: 4 | BF6: 4 | BG6: 4 | BH6: 4 | BI6: 4 | BJ6: 4 | BK6: 4 | BL6: 4 | BM6: 4 | BN6: 4 | BO6: 4 | BP6: 4 | BQ6: 4 | BR6: 4 | BS6: 4 | BT6: 4 | BU6: 4 | BV6: 4 | BW6: 4 | BX6: 4 | BY6: 4 | BZ6: 4 | CA6: 4 | CB6: 4 | CC6: 4 | CD6: 4 | CE6: 4 | CF6: 4 | CG6: 4 | CH6: 4 | CI6: 4 | CJ6: 4 | CK6: 4 | CL6: 4 | CM6: 4 | CN6: 4 | CO6: 4 | CP6: 4 | CQ6: 4 | CR6: 4 | CS6: 4 | CT6: 4 | CU6: 4
A7: 6º ano A | B7: 4 | C7: 4 | D7: 4 | E7: 3 | F7: 4 | G7: 3 | H7: 4 | I7: 2 | J7: 1 | K7: 2 | L7: 1 | M7: 1 | N7: 1 | O7: 2 | P7: 4 | Q7: 3 | R7: 3 | S7: 4 | T7: 3 | U7: 4 | V7: 2 | W7: 4 | X7: 4 | Y7: 4 | Z7: 4 | AA7: 4 | AB7: 4 | AC7: 4 | AD7: 1 | AE7: 1 | AF7: 1 | AG7: 1 | AH7: 1 | AI7: 1 | AJ7: 1 | AK7: 3 | AL7: 3 | AM7: 4 | AN7: 4 | AO7: 4 | AP7: 4 | AQ7: 3 | AR7: 2 | AS7: 2 | AT7: 4 | AU7: 1 | AV7: 1 | AW7: 2 | AX7: 1 | AY7: 3 | AZ7: 2 | BA7: 2 | BB7: 4 | BC7: 4 | BD7: 4 | BE7: 2 | BF7: 4 | BG7: 4 | BH7: 4 | BI7: 4 | BJ7: 4 | BK7: 4 | BL7: 4 | BM7: 4 | BN7: 2 | BO7: 3 | BP7: 2 | BQ7: 4 | BR7: 4 | BS7: 4 | BT7: 4 | BU7: 4 | BV7: 4 | BW7: 4 | BX7: 4 | BY7: 4 | BZ7: 4 | CA7: 4 | CB7: 4 | CC7: 4 | CD7: 4 | CE7: 4 | CF7: 4 | CG7: 4 | CH7: 4 | CI7: 4 | CJ7: 4 | CK7: 4 | CL7: 4 | CM7: 4 | CN7: 4 | CO7: 3 | CP7: 3 | CQ7: 4 | CR7: 4 | CS7: 4 | CT7: 4 | CU7: 4
A8: 6º ano A | B8: 4 | C8: 3 | D8: 2 | E8: 4 | F8: 4 | G8: 2 | H8: 3 | I8: 2 | J8: 1 | K8: 2 | L8: 3 | M8: 4 | N8: 1 | O8: 3 | P8: 4 | Q8: 4 | R8: 4 | S8: 4 | T8: 4 | U8: 4 | V8: 4 | W8: 4 | X8: 4 | Y8: 4 | Z8: 4 | AA8: 4 | AB8: 4 | AC8: 4 | AD8: 1 | AE8: 1 | AF8: 1 | AG8: 1 | AH8: 1 | AI8: 1 | AJ8: 1 | AK8: 4 | AL8: 3 | AM8: 4 | AN8: 3 | AO8: 4 | AP8: 3 | AQ8: 4 | AR8: 2 | AS8: 2 | AT8: 2 | AU8: 4 | AV8: 2 | AW8: 2 | AX8: 2 | AY8: 3 | AZ8: 3 | BA8: 4 | BB8: 4 | BC8: 1 | BD8: 4 | BE8: 3 | BF8: 4 | BG8: 4 | BH8: 4 | BI8: 4 | BJ8: 4 | BK8: 4 | BL8: 4 | BM8: 4 | BN8: 4 | BO8: 4 | BP8: 4 | BQ8: 4 | BR8: 4 | BS8: 4 | BT8: 4 | BU8: 4 | BV8: 4 | BW8: 4 | BX8: 4 | BY8: 4 | BZ8: 4 | CA8: 4 | CB8: 4 | CC8: 4 | CD8: 4 | CE8: 4 | CF8: 4 | CG8: 4 | CH8: 4 | CI8: 4 | CJ8: 4 | CK8: 4 | CL8: 4 | CM8: 4 | CN8: 4 | CO8: 2 | CP8: 3 | CQ8: 2 | CR8: 3 | CS8: 2 | CT8: 3 | CU8: 3
A9: 6º ano A | B9: 4 | C9: 4 | D9: 4 | E9: 4 | F9: 4 | G9: 4 | H9: 4 | I9: 4 | J9: 4 | K9: 4 | L9: 4 | M9: 4 | N9: 4 | O9: 4 | P9: 4 | Q9: 4 | R9: 4 | S9: 4 | T9: 4 | U9: 4 | V9: 4 | W9: 4 | X9: 4 | Y9: 4 | Z9: 4 | AA9: 4 | AB9: 4 | AC9: 4 | AD9: 1 | AE9: 1 | AF9: 4 | AG9: 4 | AH9: 4 | AI9: 4 | AJ9: 4 | AK9: 4 | AL9: 4 | AM9: 4 | AN9: 4 | AO9: 4 | AP9: 4 | AQ9: 4 | AR9: 4 | AS9: 4 | AT9: 4 | AU9: 4 | AV9: 4 | AW9: 4 | AX9: 4 | AY9: 4 | AZ9: 4 | BA9: 4 | BB9: 4 | BC9: 4 | BD9: 4 | BE9: 4 | BF9: 4 | BG9: 4 | BH9: 4 | BI9: 4 | BJ9: 4 | BK9: 4 | BL9: 4 | BM9: 4 | BN9: 4 | BO9: 4 | BP9: 4 | BQ9: 4 | BR9: 4 | BS9: 4 | BT9: 4 | BU9: 4 | BV9: 4 | BW9: 4 | BX9: 4 | BY9: 4 | CA9: 4 | CB9: 4 | CC9: 4 | CD9: 4 | CE9: 4 | CF9: 4 | CG9: 4 | CH9: 4 | CI9: 4 | CJ9: 4 | CK9: 4 | CL9: 4 | CM9: 4 | CN9: 4 | CO9: 4 | CP9: 4 | CQ9: 4 | CR9: 4 | CS9: 4 | CT9: 4 | CU9: 4
A10: 6º ano A | B10: 3 | C10: 1 | D10: 1 | E10: 2 | F10: 4 | G10: 2 | H10: 3 | I10: 1 | J10: 2 | K10: 2 | L10: 2 | M10: 4 | N10: 3 | O10: 3 | P10: 4 | Q10: 3 | R10: 4 | S10: 4 | T10: 3 | U10: 2 | V10: 1 | W10: 3 | X10: 4 | Y10: 3 | Z10: 2 | AA10: 4 | AB10: 2 | AC10: 4 | AD10: 1 | AE10: 1 | AF10: 1 | AG10: 1 | AH10: 1 | AI10: 1 | AJ10: 1 | AK10: 2 | AL10: 3 | AM10: 1 | AN10: 4 | AO10: 3 | AP10: 2 | AQ10: 2 | AR10: 4 | AS10: 4 | AT10: 4 | AU10: 4 | AV10: 4 | AW10: 4 | AX10: 4 | AY10: 1 | AZ10: 1 | BA10: 3 | BB10: 3 | BC10: 2 | BD10: 4 | BE10: 4 | BF10: 4 | BG10: 1 | BH10: 3 | BI10: 2 | BJ10: 4 | BK10: 1 | BL10: 2 | BM10: 1 | BN10: 4 | BO10: 4 | BP10: 4 | BQ10: 4 | BR10: 4 | BS10: 1 | BT10: 4 | BU10: 4 | BV10: 4 | BW10: 4 | BX10: 4 | BY10: 4 | BZ10: 4 | CA10: 1 | CB10: 3 | CC10: 4 | CD10: 2 | CE10: 1 | CF10: 4 | CG10: 1 | CH10: 4 | CI10: 4 | CJ10: 4 | CK10: 4 | CL10: 4 | CM10: 4 | CN10: 4 | CO10: 2 | CP10: 1 | CQ10: 2 | CR10: 3 | CS10: 3 | CT10: 4 | CU10: 1
A11: 6º ano A | B11: 4 | C11: 4 | D11: 2 | E11: 3 | F11: 4 | G11: 3 | H11: 3 | I11: 1 | J11: 1 | K11: 1 | L11: 1 | M11: 1 | N11: 1 | O11: 1 | P11: 1 | Q11: 1 | R11: 1 | S11: 1 | T11: 1 | U11: 2 | V11: 2 | W11: 4 | X11: 4 | Y11: 4 | Z11: 4 | AA11: 4 | AB11: 4 | AC11: 4 | AD11: 1 | AE11: 1 | AF11: 1 | AG11: 1 | AH11: 1 | AI11: 2 | AJ11: 3 | AK11: 4 | AL11: 4 | AM11: 4 | AN11: 4 | AO11: 4 | AP11: 4 | AQ11: 4 | AR11: 4 | AS11: 4 | AT11: 3 | AU11: 3 | AV11: 4 | AW11: 3 | AX11: 4 | AY11: 4 | AZ11: 4 | BA11: 4 | BB11: 4 | BC11: 4 | BD11: 4 | BE11: 4 | BF11: 4 | BG11: 4 | BH11: 4 | BI11: 4 | BJ11: 4 | BK11: 4 | BL11: 4 | BM11: 4 | BN11: 4 | BO11: 4 | BP11: 4 | BQ11: 4 | BR11: 4 | BS11: 4 | BT11: 4 | BU11: 4 | BV11: 4 | BW11: 4 | BX11: 4 | BY11: 4 | BZ11: 4 | CA11: 4 | CB11: 4 | CC11: 4 | CD11: 4 | CE11: 3 | CF11: 3 | CG11: 4 | CH11: 4 | CI11: 4 | CJ11: 4 | CK11: 4 | CL11: 4 | CM11: 4 | CN11: 4 | CO11: 3 | CP11: 3 | CQ11: 3 | CR11: 4 | CS11: 3 | CT11: 3 | CU11: 4
A12: 6º ano A | B12: 4 | C12: 4 | D12: 4 | E12: 4 | F12: 4 | I12: 1 | J12: 1 | K12: 1 | L12: 1 | M12: 1 | N12: 1 | O12: 1 | P12: 1 | Q12: 1 | R12: 1 | S12: 1 | T12: 1 | U12: 1 | V12: 1 | W12: 1 | X12: 1 | Y12: 1 | Z12: 1 | AA12: 1 | AB12: 1 | AC12: 1 | AD12: 1 | AE12: 1 | AF12: 1 | AG12: 1 | AH12: 1 | AI12: 1 | AJ12: 1 | AK12: 4 | AL12: 4 | AM12: 4 | AN12: 4 | AO12: 4 | AP12: 4 | AQ12: 4 | AR12: 4 | AS12: 4 | AT12: 4 | AU12: 4 | AV12: 4 | AW12: 4 | AX12: 4 | AY12: 3 | AZ12: 3 | BA12: 3 | BB12: 4 | BC12: 3 | BD12: 4 | BE12: 3 | BF12: 4 | BG12: 4 | BH12: 4 | BI12: 4 | BJ12: 4 | BK12: 4 | BL12: 4 | BM12: 3 | BN12: 3 | BO12: 3 | BP12: 3 | BQ12: 3 | BR12: 3 | BS12: 3 | BT12: 4 | BU12: 3 | BV12: 4 | BW12: 3 | BX12: 4 | BY12: 3 | BZ12: 4 | CA12: 4 | CB12: 4 | CC12: 4 | CD12: 4 | CE12: 4 | CF12: 4 | CG12: 4 | CH12: 4 | CI12: 4 | CJ12: 4 | CK12: 4 | CL12: 4 | CM12: 4 | CN12: 4 | CO12: 4 | CP12: 4 | CQ12: 4 | CR12: 4 | CS12: 4 | CT12: 4 | CU12: 4
A13: 6º ano A | B13: 4 | C13: 4 | D13: 4 | E13: 3 | F13: 4 | G13: 3 | H13: 3 | I13: 2 | J13: 2 | K13: 2 | L13: 2 | M13: 2 | N13: 2 | O13: 2 | P13: 4 | Q13: 4 | R13: 4 | S13: 4 | T13: 4 | U13: 4 | V13: 4 | W13: 4 | X13: 4 | Y13: 4 | Z13: 4 | AA13: 4 | AB13: 4 | AC13: 4 | AD13: 2 | AE13: 2 | AF13: 2 | AG13: 2 | AH13: 3 | AI13: 2 | AJ13: 2 | AK13: 4 | AL13: 4 | AM13: 4 | AN13: 4 | AO13: 4 | AP13: 4 | AQ13: 4 | AR13: 3 | AS13: 2 | AT13: 3 | AU13: 3 | AV13: 3 | AW13: 3 | AX13: 3 | AY13: 2 | AZ13: 3 | BA13: 3 | BB13: 3 | BC13: 3 | BD13: 3 | BE13: 3 | BF13: 4 | BG13: 4 | BH13: 4 | BI13: 4 | BJ13: 4 | BK13: 4 | BL13: 4 | BM13: 4 | BN13: 4 | BO13: 4 | BP13: 4 | BQ13: 4 | BR13: 4 | BS13: 4 | BT13: 4 | BU13: 4 | BV13: 4 | BW13: 4 | BX13: 4 | BY13: 4 | BZ13: 4 | CA13: 4 | CB13: 4 | CC13: 4 | CD13: 3 | CE13: 4 | CF13: 4 | CG13: 4 | CH13: 4 | CI13: 4 | CJ13: 3 | CK13: 4 | CL13: 4 | CM13: 4 | CN13: 4 | CO13: 3 | CP13: 4 | CQ13: 3 | CR13: 4 | CS13: 3 | CT13: 4 | CU13: 3
A14: 6º ano A | B14: 3 | C14: 4 | D14: 3 | E14: 4 | F14: 3 | G14: 4 | H14: 3 | I14: 2 | J14: 2 | K14: 2 | L14: 3 | M14: 3 | N14: 2 | O14: 3 | P14: 2 | Q14: 2 | R14: 3 | S14: 3 | T14: 2 | U14: 3 | V14: 3 | W14: 2 | X14: 2 | Y14: 2 | Z14: 2 | AA14: 2 | AB14: 2 | AC14: 2 | AD14: 3 | AE14: 3 | AF14: 3 | AG14: 3 | AH14: 3 | AI14: 3 | AJ14: 3 | AK14: 4 | AL14: 4 | AM14: 4 | AN14: 4 | AO14: 4 | AP14: 4 | AQ14: 4 | AR14: 3 | AS14: 3 | AT14: 3 | AU14: 2 | AV14: 3 | AW14: 3 | AX14: 3 | AY14: 2 | AZ14: 2 | BA14: 2 | BB14: 2 | BC14: 2 | BD14: 2 | BE14: 2 | BF14: 4 | BG14: 4 | BH14: 4 | BI14: 4 | BJ14: 4 | BK14: 4 | BL14: 4 | BM14: 4 | BN14: 4 | BO14: 4 | BP14: 4 | BQ14: 4 | BR14: 4 | BS14: 4 | BT14: 4 | BU14: 4 | BV14: 4 | BW14: 4 | BX14: 4 | BY14: 4 | BZ14: 4 | CA14: 4 | CB14: 4 | CC14: 4 | CD14: 4 | CE14: 4 | CF14: 4 | CG14: 4 | CH14: 4 | CI14: 4 | CJ14: 4 | CK14: 4 | CL14: 4 | CM14: 4 | CN14: 4 | CO14: 4 | CP14: 4 | CQ14: 4 | CR14: 4 | CS14: 4 | CT14: 4 | CU14: 4
A15: 6º ano A | B15: 4 | C15: 4 | D15: 4 | E15: 4 | F15: 4 | G15: 3 | H15: 4 | I15: 3 | J15: 3 | K15: 2 | L15: 3 | M15: 4 | N15: 3 | O15: 4 | P15: 4 | Q15: 4 | R15: 4 | S15: 4 | T15: 4 | U15: 4 | V15: 4 | W15: 4 | X15: 4 | Y15: 4 | Z15: 4 | AA15: 4 | AB15: 4 | AC15: 4 | AD15: 2 | AE15: 2 | AF15: 4 | AG15: 4 | AH15: 4 | AI15: 2 | AJ15: 4 | AK15: 4 | AL15: 4 | AM15: 4 | AN15: 4 | AO15: 4 | AP15: 4 | AQ15: 4 | AR15: 4 | AS15: 4 | AT15: 4 | AU15: 4 | AV15: 4 | AW15: 4 | AX15: 4 | AY15: 3 | AZ15: 2 | BA15: 3 | BB15: 4 | BC15: 4 | BD15: 3 | BE15: 4 | BF15: 4 | BG15: 4 | BH15: 4 | BI15: 4 | BJ15: 4 | BK15: 4 | BL15: 4 | BM15: 4 | BN15: 4 | BO15: 3 | BP15: 4 | BQ15: 2 | BR15: 4 | BS15: 3 | BT15: 4 | BU15: 4 | BV15: 4 | BW15: 4 | BX15: 4 | BY15: 4 | BZ15: 4 | CA15: 3 | CB15: 2 | CC15: 2 | CD15: 4 | CE15: 4 | CF15: 3 | CG15: 3 | CH15: 4 | CI15: 4 | CJ15: 4 | CK15: 4 | CL15: 4 | CM15: 4 | CN15: 4 | CO15: 4 | CP15: 3 | CQ15: 4 | CR15: 4 | CS15: 4 | CT15: 2 | CU15: 4
A16: 6º ano A | B16: 3 | C16: 3 | D16: 2 | E16: 3 | F16: 3 | G16: 1 | H16: 2 | I16: 1 | J16: 1 | K16: 2 | L16: 2 | M16: 2 | N16: 1 | O16: 2 | P16: 1 | Q16: 2 | R16: 2 | S16: 1 | T16: 1 | U16: 2 | V16: 1 | W16: 4 | X16: 3 | Y16: 3 | Z16: 3 | AA16: 3 | AB16: 2 | AC16: 3 | AD16: 1 | AE16: 2 | AF16: 1 | AG16: 1 | AH16: 1 | AI16: 1 | AJ16: 1 | AK16: 3 | AL16: 4 | AM16: 3 | AN16: 2 | AO16: 3 | AP16: 2 | AQ16: 3 | AR16: 1 | AS16: 3 | AT16: 1 | AU16: 2 | AV16: 1 | AW16: 2 | AX16: 1 | AY16: 2 | AZ16: 1 | BA16: 2 | BB16: 3 | BC16: 4 | BD16: 4 | BE16: 2 | BF16: 3 | BG16: 4 | BH16: 4 | BI16: 4 | BJ16: 3 | BK16: 2 | BL16: 4 | BM16: 3 | BN16: 3 | BO16: 2 | BP16: 3 | BQ16: 4 | BR16: 2 | BS16: 3 | BT16: 4 | BU16: 2 | BV16: 3 | BW16: 3 | BX16: 2 | BY16: 3 | BZ16: 3 | CA16: 4 | CB16: 3 | CC16: 3 | CD16: 3 | CE16: 3 | CF16: 4 | CG16: 3 | CH16: 4 | CI16: 4 | CJ16: 4 | CK16: 4 | CL16: 4 | CM16: 4 | CN16: 4 | CO16: 3 | CP16: 3 | CQ16: 4 | CR16: 3 | CS16: 4 | CT16: 4 | CU16: 4
A17: 6º ano A | B17: 4 | C17: 4 | D17: 3 | E17: 3 | F17: 4 | G17: 2 | H17: 4 | I17: 2 | J17: 2 | K17: 4 | L17: 2 | M17: 4 | N17: 2 | O17: 2 | P17: 4 | Q17: 4 | R17: 4 | S17: 3 | T17: 4 | U17: 3 | V17: 4 | W17: 4 | X17: 4 | Y17: 4 | Z17: 4 | AA17: 4 | AB17: 3 | AC17: 4 | AD17: 3 | AE17: 3 | AF17: 2 | AG17: 3 | AH17: 4 | AI17: 2 | AJ17: 3 | AK17: 4 | AL17: 4 | AM17: 4 | AN17: 3 | AO17: 4 | AP17: 3 | AQ17: 4 | AR17: 3 | AS17: 4 | AT17: 3 | AU17: 4 | AV17: 4 | AW17: 3 | AX17: 3 | AY17: 4 | AZ17: 4 | BA17: 4 | BB17: 4 | BC17: 4 | BD17: 4 | BE17: 4 | BF17: 4 | BG17: 4 | BH17: 4 | BI17: 4 | BJ17: 4 | BK17: 4 | BL17: 4 | BM17: 4 | BN17: 4 | BO17: 3 | BP17: 4 | BQ17: 4 | BR17: 4 | BS17: 4 | BT17: 3 | BU17: 3 | BV17: 4 | BW17: 4 | BX17: 4 | BY17: 3 | BZ17: 4 | CA17: 4 | CB17: 4 | CC17: 4 | CD17: 4 | CE17: 4 | CF17: 4 | CG17: 4 | CH17: 4 | CI17: 4 | CJ17: 4 | CK17: 4 | CL17: 4 | CM17: 4 | CN17: 4 | CO17: 4 | CP17: 4 | CQ17: 4 | CR17: 4 | CS17: 4 | CT17: 4 | CU17: 4
A18: 6º ano A | B18: 3 | C18: 3 | D18: 3 | E18: 3 | F18: 3 | G18: 3 | H18: 3 | I18: 2 | J18: 1 | K18: 2 | L18: 2 | M18: 3 | N18: 2 | O18: 2 | P18: 3 | Q18: 3 | R18: 3 | S18: 3 | T18: 3 | U18: 3 | V18: 3 | W18: 4 | X18: 4 | Y18: 4 | Z18: 4 | AA18: 4 | AB18: 4 | AC18: 4 | AD18: 2 | AE18: 1 | AF18: 2 | AG18: 2 | AH18: 4 | AI18: 2 | AJ18: 1 | AK18: 4 | AL18: 3 | AM18: 3 | AN18: 3 | AO18: 3 | AP18: 3 | AQ18: 3 | AR18: 3 | AS18: 2 | AT18: 2 | AU18: 2 | AV18: 4 | AW18: 2 | AX18: 3 | AY18: 3 | AZ18: 3 | BA18: 2 | BB18: 4 | BC18: 4 | BD18: 4 | BE18: 4 | BF18: 4 | BG18: 4 | BH18: 4 | BI18: 4 | BJ18: 4 | BK18: 4 | BL18: 4 | BM18: 4 | BN18: 4 | BO18: 4 | BP18: 4 | BQ18: 4 | BR18: 4 | BS18: 4 | BT18: 4 | BU18: 4 | BV18: 4 | BW18: 4 | BX18: 4 | BY18: 4 | BZ18: 4 | CA18: 4 | CB18: 4 | CC18: 4 | CD18: 4 | CE18: 4 | CF18: 4 | CG18: 4 | CH18: 4 | CI18: 4 | CJ18: 4 | CK18: 4 | CL18: 4 | CM18: 4 | CN18: 4 | CO18: 4 | CP18: 3 | CQ18: 4 | CR18: 4 | CS18: 4 | CT18: 3 | CU18: 3
A19: 6º ano A | B19: 3 | C19: 3 | D19: 4 | E19: 2 | F19: 4 | G19: 2 | H19: 4 | I19: 4 | J19: 2 | K19: 3 | L19: 3 | M19: 4 | N19: 2 | O19: 3 | P19: 1 | Q19: 1 | R19: 3 | S19: 3 | T19: 2 | U19: 2 | V19: 2 | W19: 4 | X19: 4 | Y19: 4 | Z19: 4 | AA19: 4 | AB19: 4 | AC19: 4 | AD19: 2 | AE19: 1 | AF19: 3 | AG19: 3 | AH19: 4 | AI19: 3 | AJ19: 4 | AK19: 3 | AL19: 3 | AM19: 2 | AN19: 3 | AO19: 2 | AQ19: 3 | AR19: 2 | AS19: 4 | AT19: 4 | AU19: 2 | AV19: 4 | AW19: 3 | AX19: 4 | AY19: 1 | AZ19: 1 | BA19: 1 | BB19: 3 | BC19: 3 | BD19: 2 | BE19: 1 | BF19: 4 | BG19: 4 | BH19: 4 | BI19: 4 | BJ19: 4 | BK19: 4 | BL19: 4 | BM19: 2 | BN19: 3 | BO19: 4 | BP19: 4 | BQ19: 2 | BR19: 4 | BS19: 1 | BT19: 4 | BU19: 4 | BV19: 4 | BW19: 3 | BX19: 3 | BY19: 3 | BZ19: 4 | CA19: 2 | CB19: 2 | CC19: 3 | CD19: 3 | CE19: 3 | CF19: 4 | CG19: 4 | CH19: 3 | CI19: 1 | CJ19: 3 | CK19: 2 | CL19: 4 | CM19: 3 | CN19: 4 | CO19: 2 | CP19: 1 | CQ19: 1 | CR19: 1 | CS19: 1 | CT19: 1 | CU19: 1
A20: 6º ano A | B20: 2 | C20: 3 | D20: 4 | E20: 2 | F20: 4 | G20: 3 | H20: 3 | I20: 3 | J20: 2 | K20: 1 | L20: 4 | M20: 3 | N20: 2 | O20: 3 | P20: 3 | Q20: 2 | R20: 2 | S20: 4 | T20: 3 | U20: 1 | V20: 2 | W20: 3 | X20: 4 | Y20: 4 | Z20: 4 | AA20: 4 | AB20: 4 | AC20: 4 | AD20: 4 | AE20: 1 | AF20: 2 | AG20: 4 | AH20: 2 | AI20: 1 | AJ20: 1 | AK20: 2 | AL20: 3 | AM20: 4 | AN20: 3 | AO20: 3 | AP20: 3 | AQ20: 3 | AR20: 4 | AS20: 2 | AT20: 3 | AU20: 4 | AV20: 3 | AW20: 3 | AX20: 3 | AY20: 2 | AZ20: 3 | BA20: 3 | BB20: 4 | BC20: 3 | BD20: 4 | BE20: 3 | BF20: 1 | BG20: 4 | BH20: 4 | BI20: 4 | BJ20: 4 | BK20: 4 | BL20: 4 | BM20: 4 | BN20: 2 | BO20: 3 | BP20: 4 | BQ20: 4 | BR20: 4 | BS20: 4 | BT20: 2 | BU20: 4 | BV20: 4 | BW20: 4 | BX20: 3 | BY20: 3 | BZ20: 4 | CA20: 3 | CB20: 3 | CC20: 4 | CD20: 4 | CE20: 4 | CF20: 4 | CG20: 4 | CH20: 1 | CI20: 4 | CJ20: 4 | CK20: 4 | CL20: 4 | CM20: 4 | CN20: 4 | CO20: 2 | CP20: 3 | CQ20: 4 | CR20: 4 | CS20: 4 | CT20: 4 | CU20: 4
A21: 6º ano A | B21: 2 | C21: 2 | D21: 3 | E21: 2 | F21: 2 | G21: 2 | H21: 4 | I21: 2 | J21: 1 | K21: 2 | L21: 2 | M21: 2 | N21: 2 | O21: 4 | P21: 3 | Q21: 3 | R21: 2 | S21: 3 | T21: 3 | U21: 2 | V21: 4 | W21: 4 | X21: 2 | Y21: 4 | Z21: 3 | AA21: 2 | AB21: 3 | AC21: 3 | AD21: 1 | AE21: 1 | AF21: 1 | AG21: 1 | AH21: 1 | AI21: 1 | AJ21: 1 | AK21: 1 | AL21: 2 | AM21: 2 | AN21: 2 | AO21: 2 | AP21: 2 | AQ21: 4 | AR21: 2 | AS21: 4 | AT21: 3 | AU21: 1 | AV21: 1 | AW21: 1 | AX21: 3 | AY21: 2 | AZ21: 1 | BA21: 2 | BB21: 4 | BC21: 3 | BD21: 4 | BE21: 4 | BF21: 1 | BG21: 4 | BH21: 4 | BI21: 4 | BJ21: 1 | BK21: 4 | BL21: 4 | BM21: 4 | BN21: 4 | BO21: 1 | BP21: 4 | BQ21: 1 | BR21: 4 | BS21: 4 | BT21: 4 | BU21: 2 | BV21: 4 | BW21: 4 | BX21: 2 | BY21: 3 | BZ21: 4 | CA21: 1 | CB21: 1 | CC21: 1 | CD21: 2 | CE21: 1 | CF21: 4 | CG21: 2 | CH21: 4 | CI21: 4 | CJ21: 4 | CK21: 4 | CL21: 4 | CM21: 2 | CN21: 4 | CO21: 2 | CP21: 2 | CQ21: 4 | CR21: 4 | CS21: 3 | CT21: 4 | CU21: 4
A22: 6º ano A | C22: 3 | D22: 4 | E22: 3 | F22: 2 | H22: 3 | I22: 4 | J22: 4 | K22: 4 | L22: 4 | M22: 3 | N22: 4 | O22: 3 | P22: 4 | Q22: 4 | R22: 4 | S22: 3 | T22: 2 | U22: 4 | V22: 4 | W22: 4 | X22: 4 | Y22: 4 | Z22: 4 | AA22: 4 | AB22: 4 | AC22: 4 | AD22: 1 | AE22: 4 | AF22: 2 | AG22: 4 | AH22: 1 | AI22: 2 | AJ22: 3 | AK22: 4 | AL22: 4 | AM22: 4 | AN22: 4 | AO22: 4 | AP22: 4 | AQ22: 4 | AR22: 2 | AS22: 3 | AT22: 4 | AU22: 1 | AV22: 4 | AW22: 3 | AX22: 4 | AY22: 1 | AZ22: 4 | BA22: 4 | BB22: 3 | BC22: 3 | BD22: 4 | BE22: 2 | BF22: 4 | BG22: 4 | BH22: 4 | BI22: 4 | BJ22: 4 | BK22: 4 | BL22: 4 | BM22: 4 | BN22: 4 | BO22: 4 | BP22: 4 | BQ22: 4 | BR22: 4 | BS22: 4 | BT22: 4 | BU22: 4 | BV22: 4 | BW22: 4 | BX22: 4 | BY22: 4 | BZ22: 4 | CA22: 4 | CB22: 4 | CC22: 4 | CD22: 4 | CE22: 4 | CF22: 4 | CG22: 4 | CH22: 4 | CI22: 4 | CJ22: 4 | CK22: 4 | CL22: 4 | CM22: 4 | CN22: 4 | CO22: 4 | CP22: 4 | CQ22: 4 | CR22: 4 | CS22: 4 | CT22: 4 | CU22: 4
A23: 6º ano A | B23: 4 | C23: 4 | D23: 4 | E23: 3 | F23: 3 | G23: 3 | H23: 4 | I23: 2 | J23: 1 | K23: 2 | L23: 3 | M23: 3 | N23: 3 | O23: 4 | P23: 4 | Q23: 3 | R23: 4 | S23: 3 | T23: 3 | U23: 3 | V23: 4 | W23: 4 | X23: 4 | Y23: 4 | Z23: 3 | AA23: 3 | AB23: 3 | AC23: 4 | AD23: 4 | AE23: 3 | AF23: 4 | AG23: 3 | AH23: 4 | AI23: 3 | AJ23: 4 | AK23: 4 | AL23: 4 | AM23: 4 | AN23: 3 | AO23: 4 | AP23: 3 | AQ23: 4 | AR23: 3 | AS23: 4 | AT23: 4 | AU23: 3 | AV23: 4 | AW23: 3 | AX23: 4 | AY23: 4 | AZ23: 4 | BA23: 4 | BB23: 4 | BC23: 4 | BD23: 4 | BE23: 4 | BF23: 4 | BG23: 4 | BH23: 4 | BI23: 4 | BJ23: 4 | BK23: 4 | BL23: 4 | BM23: 3 | BN23: 3 | BO23: 2 | BP23: 2 | BQ23: 1 | BR23: 1 | BS23: 2 | BT23: 4 | BU23: 4 | BV23: 4 | BW23: 4 | BX23: 4 | BY23: 4 | BZ23: 4 | CA23: 4 | CB23: 4 | CC23: 4 | CD23: 4 | CE23: 4 | CF23: 4 | CG23: 4 | CH23: 4 | CI23: 4 | CJ23: 4 | CK23: 2 | CL23: 4 | CM23: 2 | CN23: 4 | CO23: 3 | CP23: 1 | CQ23: 2 | CR23: 3 | CS23: 4 | CT23: 3 | CU23: 3
A24: 6º ano A | B24: 4 | C24: 3 | E24: 3 | F24: 3 | G24: 3 | H24: 3 | I24: 2 | J24: 2 | K24: 3 | L24: 2 | M24: 3 | N24: 1 | O24: 3 | P24: 3 | Q24: 3 | R24: 4 | S24: 3 | T24: 2 | U24: 3 | V24: 3 | W24: 3 | X24: 3 | Y24: 3 | Z24: 3 | AA24: 4 | AB24: 4 | AC24: 3 | AD24: 2 | AE24: 2 | AF24: 2 | AG24: 3 | AH24: 2 | AI24: 2 | AJ24: 2 | AK24: 4 | AL24: 3 | AM24: 4 | AN24: 3 | AO24: 4 | AP24: 2 | AQ24: 3 | AR24: 4 | AS24: 4 | AT24: 4 | AV24: 4 | AW24: 4 | AX24: 3 | AY24: 4 | AZ24: 4 | BA24: 3 | BB24: 2 | BC24: 2 | BD24: 2 | BE24: 2 | BF24: 4 | BG24: 3 | BH24: 4 | BI24: 2 | BJ24: 4 | BK24: 4 | BL24: 4 | BM24: 2 | BN24: 2 | BO24: 3 | BP24: 3 | BQ24: 3 | BR24: 2 | BS24: 1 | BT24: 4 | BU24: 4 | BV24: 4 | BW24: 4 | BX24: 4 | BY24: 4 | BZ24: 4 | CA24: 4 | CB24: 4 | CC24: 4 | CD24: 4 | CE24: 4 | CF24: 3 | CG24: 4 | CH24: 3 | CI24: 3 | CJ24: 4 | CK24: 3 | CL24: 4 | CM24: 3 | CN24: 4 | CO24: 3 | CP24: 3 | CQ24: 2 | CS24: 1 | CT24: 2 | CU24: 4
A25: 6º ano A | B25: 4 | C25: 4 | D25: 4 | E25: 4 | F25: 4 | G25: 2 | H25: 4 | I25: 3 | J25: 1 | K25: 3 | L25: 4 | M25: 1 | N25: 3 | O25: 3 | P25: 4 | Q25: 4 | R25: 4 | S25: 4 | T25: 4 | U25: 3 | V25: 4 | W25: 4 | X25: 4 | Y25: 4 | Z25: 4 | AA25: 4 | AB25: 4 | AC25: 4 | AD25: 3 | AE25: 2 | AF25: 3 | AG25: 4 | AH25: 4 | AI25: 3 | AJ25: 4 | AK25: 4 | AL25: 4 | AM25: 3 | AN25: 4 | AO25: 4 | AP25: 4 | AQ25: 4 | AR25: 4 | AS25: 4 | AT25: 4 | AU25: 3 | AV25: 4 | AW25: 3 | AX25: 4 | AY25: 4 | AZ25: 2 | BA25: 3 | BB25: 4 | BC25: 4 | BD25: 4 | BE25: 3 | BF25: 4 | BG25: 4 | BH25: 4 | BI25: 4 | BK25: 4 | BM25: 4 | BN25: 4 | BO25: 2 | BP25: 4 | BQ25: 4 | BR25: 3 | BS25: 4 | BT25: 4 | BU25: 4 | BV25: 4 | BW25: 4 | BX25: 4 | BY25: 4 | BZ25: 4 | CA25: 4 | CB25: 4 | CC25: 4 | CD25: 4 | CE25: 4 | CF25: 4 | CG25: 4 | CH25: 4 | CI25: 4 | CJ25: 4 | CK25: 2 | CL25: 4 | CM25: 3 | CN25: 4 | CO25: 4 | CP25: 3 | CQ25: 4 | CR25: 4 | CS25: 4 | CT25: 4 | CU25: 4
A26: 6º ano A | B26: 2 | C26: 1 | D26: 3 | E26: 3 | F26: 1 | G26: 1 | H26: 2 | I26: 1 | J26: 1 | K26: 1 | L26: 2 | M26: 3 | N26: 2 | O26: 1 | P26: 4 | Q26: 4 | R26: 4 | S26: 3 | T26: 3 | U26: 3 | V26: 4 | W26: 4 | X26: 4 | Y26: 4 | Z26: 3 | AA26: 4 | AB26: 3 | AC26: 4 | AD26: 4 | AE26: 1 | AF26: 4 | AG26: 4 | AH26: 4 | AI26: 2 | AJ26: 4 | AK26: 4 | AL26: 4 | AM26: 4 | AN26: 4 | AO26: 4 | AP26: 2 | AQ26: 3 | AR26: 3 | AS26: 2 | AT26: 4 | AU26: 1 | AV26: 4 | AW26: 3 | AX26: 2 | AY26: 4 | AZ26: 1 | BA26: 4 | BB26: 4 | BC26: 4 | BD26: 4 | BE26: 4 | BF26: 4 | BG26: 4 | BH26: 4 | BI26: 4 | BJ26: 4 | BK26: 4 | BL26: 4 | BM26: 4 | BN26: 2 | BO26: 3 | BP26: 4 | BQ26: 4 | BR26: 4 | BS26: 4 | BT26: 4 | BU26: 1 | BV26: 4 | BW26: 3 | BX26: 4 | BY26: 2 | BZ26: 4 | CA26: 4 | CB26: 4 | CC26: 4 | CD26: 4 | CE26: 4 | CF26: 4 | CG26: 1 | CH26: 4 | CI26: 1 | CJ26: 4 | CK26: 4 | CL26: 4 | CM26: 3 | CN26: 2 | CO26: 1 | CP26: 1 | CQ26: 1 | CR26: 3 | CS26: 4 | CT26: 1 | CU26: 1
A27: 6º ano A | B27: 3 | C27: 3 | D27: 3 | E27: 3 | F27: 2 | G27: 2 | H27: 3 | I27: 4 | J27: 3 | K27: 4 | L27: 4 | M27: 4 | N27: 3 | O27: 4 | P27: 4 | Q27: 4 | R27: 3 | S27: 3 | T27: 4 | U27: 3 | V27: 4 | W27: 4 | X27: 4 | Y27: 4 | Z27: 4 | AA27: 4 | AB27: 4 | AC27: 4 | AD27: 3 | AE27: 2 | AF27: 3 | AG27: 3 | AH27: 3 | AI27: 2 | AJ27: 3 | AK27: 3 | AL27: 4 | AM27: 4 | AN27: 4 | AO27: 3 | AP27: 3 | AQ27: 4 | AR27: 3 | AS27: 3 | AT27: 3 | AU27: 2 | AV27: 3 | AW27: 2 | AX27: 4 | AY27: 2 | AZ27: 2 | BA27: 2 | BB27: 3 | BC27: 4 | BD27: 4 | BE27: 2 | BF27: 4 | BG27: 4 | BH27: 4 | BI27: 4 | BJ27: 4 | BK27: 4 | BL27: 4 | BM27: 2 | BN27: 3 | BO27: 3 | BP27: 3 | BQ27: 1 | BR27: 2 | BS27: 2 | BT27: 3 | BU27: 3 | BV27: 4 | BW27: 3 | BX27: 4 | BY27: 3 | BZ27: 3 | CA27: 3 | CB27: 3 | CC27: 4 | CD27: 4 | CE27: 4 | CF27: 4 | CG27: 4 | CH27: 3 | CI27: 3 | CJ27: 3 | CK27: 3 | CL27: 3 | CM27: 2 | CN27: 3 | CO27: 2 | CP27: 2 | CQ27: 3 | CR27: 2 | CS27: 3 | CT27: 2 | CU27: 2
A28: 6º ano B | B28: 4 | C28: 4 | D28: 4 | E28: 4 | F28: 4 | G28: 3 | H28: 4 | I28: 1 | J28: 1 | K28: 1 | L28: 1 | M28: 1 | N28: 1 | O28: 1 | P28: 4 | Q28: 4 | R28: 4 | S28: 4 | T28: 4 | U28: 4 | V28: 4 | W28: 4 | X28: 4 | Y28: 4 | Z28: 4 | AA28: 4 | AB28: 4 | AC28: 4 | AD28: 2 | AE28: 1 | AF28: 1 | AG28: 1 | AH28: 1 | AI28: 1 | AJ28: 3 | AK28: 3 | AL28: 3 | AM28: 3 | AN28: 3 | AO28: 3 | AP28: 3 | AQ28: 3 | AR28: 3 | AS28: 3 | AT28: 3 | AU28: 3 | AV28: 3 | AW28: 3 | AX28: 3 | AY28: 1 | AZ28: 1 | BA28: 1 | BB28: 3 | BC28: 3 | BD28: 1 | BE28: 1 | BF28: 4 | BG28: 4 | BH28: 4 | BI28: 4 | BJ28: 4 | BK28: 4 | BL28: 4 | BM28: 4 | BN28: 4 | BO28: 4 | BP28: 4 | BQ28: 4 | BR28: 4 | BS28: 4 | BT28: 4 | BU28: 4 | BV28: 4 | BW28: 4 | BX28: 4 | BY28: 4 | BZ28: 4 | CA28: 4 | CB28: 4 | CC28: 4 | CD28: 4 | CE28: 4 | CF28: 4 | CG28: 4 | CH28: 4 | CI28: 4 | CJ28: 4 | CK28: 4 | CL28: 4 | CM28: 4 | CN28: 4 | CO28: 4 | CP28: 4 | CQ28: 4 | CR28: 4 | CS28: 4 | CT28: 4 | CU28: 4
A29: 6º ano B | B29: 4 | C29: 4 | D29: 4 | E29: 4 | F29: 4 | G29: 4 | H29: 4 | I29: 4 | J29: 4 | K29: 4 | L29: 4 | M29: 4 | N29: 4 | O29: 4 | P29: 4 | Q29: 4 | R29: 3 | S29: 4 | T29: 3 | U29: 4 | V29: 4 | W29: 4 | X29: 4 | Y29: 4 | Z29: 4 | AA29: 4 | AB29: 4 | AC29: 4 | AD29: 3 | AE29: 4 | AF29: 4 | AG29: 4 | AH29: 3 | AI29: 4 | AJ29: 4 | AK29: 4 | AL29: 4 | AM29: 4 | AN29: 4 | AO29: 4 | AP29: 4 | AQ29: 4 | AR29: 3 | AS29: 3 | AT29: 3 | AU29: 3 | AV29: 3 | AW29: 3 | AX29: 3 | AY29: 4 | AZ29: 4 | BA29: 4 | BB29: 4 | BC29: 4 | BD29: 4 | BE29: 4 | BF29: 3 | BG29: 3 | BH29: 3 | BI29: 3 | BJ29: 3 | BK29: 3 | BL29: 3 | BM29: 4 | BN29: 4 | BO29: 4 | BP29: 4 | BQ29: 4 | BR29: 4 | BS29: 4 | BT29: 4 | BU29: 4 | BV29: 4 | BW29: 4 | BX29: 4 | BY29: 4 | BZ29: 4 | CA29: 3 | CB29: 4 | CC29: 4 | CD29: 3 | CE29: 4 | CF29: 4 | CG29: 4 | CH29: 4 | CI29: 4 | CJ29: 4 | CK29: 4 | CL29: 4 | CM29: 4 | CN29: 4 | CO29: 2 | CP29: 3 | CQ29: 4 | CR29: 3 | CS29: 3 | CT29: 3 | CU29: 4
A30: 6º ano B | B30: 3 | C30: 3 | D30: 3 | E30: 2 | F30: 4 | G30: 2 | H30: 2 | I30: 2 | J30: 1 | K30: 2 | L30: 1 | M30: 3 | N30: 1 | O30: 2 | P30: 4 | Q30: 4 | R30: 4 | S30: 4 | T30: 4 | U30: 4 | V30: 4 | W30: 4 | X30: 4 | Y30: 4 | Z30: 4 | AA30: 4 | AB30: 4 | AC30: 4 | AD30: 1 | AE30: 2 | AF30: 1 | AG30: 2 | AH30: 1 | AI30: 2 | AJ30: 1 | AK30: 2 | AL30: 2 | AM30: 1 | AN30: 2 | AO30: 2 | AP30: 1 | AQ30: 2 | AR30: 3 | AS30: 4 | AT30: 3 | AU30: 4 | AV30: 3 | AW30: 4 | AX30: 3 | AY30: 3 | AZ30: 3 | BA30: 3 | BB30: 3 | BC30: 3 | BD30: 3 | BE30: 3 | BF30: 4 | BG30: 4 | BH30: 3 | BI30: 4 | BJ30: 4 | BK30: 3 | BL30: 4 | BM30: 4 | BN30: 4 | BO30: 4 | BP30: 3 | BQ30: 4 | BR30: 4 | BS30: 4 | BT30: 4 | BU30: 4 | BV30: 4 | BW30: 4 | BX30: 4 | BY30: 4 | BZ30: 4 | CA30: 4 | CB30: 4 | CC30: 3 | CD30: 4 | CE30: 4 | CF30: 3 | CG30: 4 | CH30: 4 | CI30: 3 | CJ30: 4 | CK30: 3 | CL30: 4 | CM30: 3 | CN30: 4 | CO30: 2 | CP30: 2 | CQ30: 1 | CR30: 2 | CS30: 2 | CT30: 1
A31: 6º ano B | B31: 2 | C31: 3 | D31: 2 | E31: 4 | F31: 4 | G31: 3 | H31: 4 | I31: 4 | J31: 2 | K31: 3 | L31: 4 | M31: 4 | N31: 2 | O31: 4 | P31: 3 | Q31: 4 | R31: 3 | S31: 4 | T31: 3 | U31: 3 | V31: 4 | W31: 4 | X31: 4 | Y31: 4 | Z31: 4 | AA31: 4 | AB31: 4 | AC31: 4 | AD31: 2 | AE31: 1 | AF31: 3 | AG31: 4 | AH31: 4 | AI31: 2 | AJ31: 4 | AK31: 4 | AL31: 4 | AM31: 4 | AN31: 4 | AO31: 4 | AP31: 4 | AQ31: 4 | AR31: 3 | AS31: 2 | AT31: 2 | AU31: 4 | AV31: 4 | AW31: 2 | AX31: 4 | AY31: 4 | AZ31: 3 | BA31: 3 | BB31: 4 | BC31: 4 | BD31: 4 | BE31: 3 | BF31: 4 | BG31: 4 | BH31: 4 | BI31: 4 | BJ31: 4 | BK31: 4 | BL31: 4 | BM31: 3 | BN31: 4 | BO31: 1 | BP31: 4 | BQ31: 2 | BR31: 2 | BS31: 2 | BT31: 4 | BU31: 4 | BV31: 4 | BW31: 4 | BX31: 4 | BY31: 4 | BZ31: 4 | CA31: 4 | CB31: 4 | CC31: 4 | CD31: 4 | CE31: 4 | CF31: 4 | CG31: 4 | CH31: 4 | CI31: 4 | CJ31: 4 | CK31: 4 | CL31: 4 | CM31: 4 | CN31: 4 | CO31: 3 | CP31: 4 | CQ31: 3 | CR31: 4 | CS31: 3 | CT31: 4 | CU31: 3
A32: 6º ano B | B32: 3 | C32: 3 | D32: 3 | E32: 3 | F32: 3 | G32: 3 | H32: 3 | I32: 1 | J32: 1 | K32: 1 | L32: 1 | M32: 1 | N32: 1 | O32: 1 | P32: 4 | Q32: 4 | R32: 4 | S32: 3 | T32: 3 | U32: 3 | V32: 4 | W32: 3 | X32: 3 | Y32: 3 | Z32: 3 | AA32: 3 | AB32: 3 | AC32: 3 | AD32: 2 | AE32: 2 | AF32: 2 | AG32: 2 | AH32: 2 | AI32: 2 | AJ32: 2 | AK32: 3 | AL32: 3 | AM32: 3 | AN32: 3 | AO32: 3 | AP32: 3 | AQ32: 3 | AR32: 3 | AS32: 3 | AT32: 3 | AU32: 3 | AV32: 3 | AW32: 3 | AX32: 3 | AY32: 1 | AZ32: 1 | BA32: 1 | BB32: 1 | BC32: 3 | BD32: 2 | BE32: 3 | BF32: 4 | BG32: 4 | BH32: 4 | BI32: 4 | BJ32: 4 | BK32: 4 | BL32: 4 | BM32: 4 | BN32: 4 | BO32: 4 | BP32: 4 | BQ32: 4 | BR32: 4 | BS32: 4 | BT32: 3 | BU32: 3 | BV32: 3 | BW32: 4 | BX32: 4 | BY32: 4 | BZ32: 4 | CA32: 3 | CB32: 3 | CC32: 3 | CD32: 3 | CE32: 3 | CF32: 3 | CG32: 3 | CH32: 4 | CI32: 4 | CJ32: 4 | CK32: 4 | CL32: 4 | CM32: 4 | CN32: 4 | CO32: 1 | CP32: 1 | CQ32: 1 | CR32: 1 | CS32: 1 | CT32: 1 | CU32: 1
A33: 6º ano B | B33: 3 | C33: 2 | D33: 3 | E33: 4 | F33: 4 | G33: 3 | H33: 4 | I33: 3 | J33: 2 | K33: 3 | L33: 2 | M33: 4 | N33: 3 | O33: 4 | P33: 4 | Q33: 4 | R33: 4 | S33: 4 | T33: 4 | U33: 4 | V33: 4 | W33: 4 | X33: 4 | Y33: 4 | Z33: 4 | AA33: 4 | AB33: 4 | AC33: 4 | AD33: 3 | AE33: 2 | AF33: 3 | AG33: 2 | AH33: 4 | AI33: 3 | AJ33: 4 | AK33: 3 | AL33: 4 | AM33: 3 | AN33: 3 | AO33: 4 | AP33: 2 | AQ33: 4 | AR33: 3 | AS33: 4 | AT33: 4 | AU33: 4 | AV33: 4 | AW33: 4 | AX33: 4 | AY33: 2 | AZ33: 1 | BA33: 1 | BB33: 4 | BC33: 3 | BD33: 4 | BE33: 2 | BF33: 4 | BG33: 4 | BH33: 4 | BI33: 4 | BJ33: 4 | BK33: 4 | BL33: 4 | BM33: 3 | BN33: 4 | BO33: 3 | BP33: 4 | BQ33: 4 | BR33: 3 | BS33: 2 | BT33: 4 | BU33: 4 | BV33: 4 | BW33: 4 | BX33: 4 | BY33: 4 | BZ33: 4 | CA33: 4 | CB33: 4 | CC33: 4 | CD33: 4 | CE33: 4 | CF33: 4 | CG33: 4 | CH33: 3 | CI33: 4 | CJ33: 4 | CK33: 3 | CL33: 2 | CM33: 3 | CN33: 4 | CO33: 4 | CP33: 4 | CQ33: 4 | CR33: 4 | CS33: 4 | CT33: 4 | CU33: 4
A34: 6º ano B | B34: 4 | C34: 3 | D34: 4 | E34: 4 | F34: 4 | G34: 2 | H34: 4 | I34: 2 | J34: 2 | K34: 2 | L34: 4 | M34: 3 | N34: 3 | O34: 2 | P34: 4 | Q34: 4 | R34: 4 | S34: 4 | T34: 4 | U34: 4 | V34: 4 | W34: 4 | X34: 2 | Y34: 3 | Z34: 3 | AA34: 4 | AB34: 2 | AC34: 1 | AD34: 3 | AE34: 3 | AF34: 4 | AG34: 2 | AH34: 3 | AI34: 4 | AJ34: 1 | AK34: 4 | AL34: 4 | AM34: 4 | AN34: 4 | AO34: 4 | AP34: 4 | AQ34: 4 | AR34: 4 | AS34: 4 | AT34: 4 | AU34: 4 | AV34: 4 | AW34: 4 | AX34: 4 | AY34: 4 | AZ34: 4 | BA34: 4 | BB34: 4 | BC34: 4 | BD34: 4 | BE34: 4 | BF34: 2 | BG34: 3 | BH34: 2 | BI34: 3 | BJ34: 2 | BK34: 3 | BL34: 2 | BM34: 4 | BN34: 4 | BO34: 4 | BP34: 4 | BQ34: 4 | BR34: 4 | BS34: 4 | BT34: 4 | BU34: 4 | BV34: 4 | BW34: 4 | BX34: 4 | BY34: 4 | BZ34: 4 | CA34: 4 | CB34: 4 | CC34: 4 | CD34: 4 | CE34: 4 | CF34: 4 | CG34: 4 | CH34: 4 | CI34: 4 | CJ34: 4 | CK34: 4 | CL34: 4 | CM34: 4 | CN34: 4 | CO34: 3 | CP34: 3 | CQ34: 4 | CR34: 3 | CS34: 4 | CT34: 4 | CU34: 4
A35: 6º ano B | B35: 4 | C35: 4 | D35: 4 | E35: 4 | F35: 4 | G35: 4 | H35: 4 | I35: 1 | J35: 1 | K35: 1 | L35: 1 | M35: 1 | N35: 1 | O35: 1 | P35: 3 | Q35: 3 | R35: 3 | S35: 3 | T35: 3 | U35: 3 | V35: 3 | W35: 4 | X35: 4 | Y35: 4 | Z35: 4 | AA35: 4 | AB35: 4 | AC35: 4 | AD35: 2 | AE35: 2 | AF35: 2 | AG35: 2 | AH35: 2 | AI35: 2 | AJ35: 2 | AK35: 3 | AL35: 3 | AM35: 3 | AN35: 3 | AO35: 3 | AP35: 3 | AQ35: 3 | AR35: 3 | AS35: 3 | AT35: 3 | AU35: 3 | AV35: 3 | AW35: 3 | AX35: 3 | AY35: 1 | AZ35: 1 | BA35: 1 | BB35: 1 | BC35: 1 | BD35: 1 | BE35: 1 | BF35: 4 | BG35: 4 | BH35: 4 | BI35: 4 | BJ35: 4 | BK35: 4 | BL35: 4 | BM35: 4 | BN35: 4 | BO35: 4 | BP35: 4 | BQ35: 4 | BR35: 4 | BS35: 4 | BT35: 4 | BU35: 4 | BV35: 4 | BW35: 4 | BX35: 4 | BY35: 4 | BZ35: 4 | CA35: 4 | CB35: 4 | CC35: 4 | CD35: 4 | CE35: 4 | CF35: 4 | CG35: 4 | CH35: 4 | CI35: 4 | CJ35: 4 | CK35: 4 | CL35: 4 | CM35: 4 | CN35: 4 | CO35: 3 | CP35: 4 | CQ35: 3 | CR35: 4 | CS35: 3 | CT35: 4 | CU35: 4
A36: 6º ano B | B36: 4 | C36: 3 | D36: 3 | E36: 4 | F36: 4 | G36: 1 | H36: 4 | I36: 1 | J36: 2 | K36: 1 | L36: 2 | M36: 4 | N36: 1 | O36: 3 | P36: 4 | Q36: 4 | R36: 4 | S36: 4 | T36: 4 | U36: 4 | V36: 4 | W36: 4 | X36: 4 | Y36: 4 | Z36: 4 | AA36: 4 | AB36: 4 | AC36: 4 | AD36: 2 | AE36: 2 | AF36: 3 | AG36: 3 | AH36: 4 | AI36: 2 | AJ36: 2 | AK36: 4 | AL36: 4 | AM36: 2 | AN36: 4 | AO36: 4 | AP36: 4 | AQ36: 4 | AR36: 1 | AS36: 2 | AT36: 2 | AU36: 2 | AV36: 3 | AW36: 1 | AX36: 2 | AY36: 3 | AZ36: 2 | BA36: 3 | BB36: 4 | BC36: 4 | BD36: 3 | BE36: 4 | BF36: 4 | BG36: 4 | BH36: 4 | BI36: 4 | BJ36: 4 | BK36: 4 | BL36: 4 | BM36: 4 | BN36: 4 | BO36: 4 | BP36: 3 | BQ36: 3 | BR36: 3 | BS36: 3 | BT36: 4 | BU36: 4 | BV36: 4 | BW36: 4 | BX36: 4 | BY36: 4 | BZ36: 4 | CA36: 3 | CB36: 3 | CC36: 3 | CD36: 3 | CE36: 3 | CF36: 3 | CG36: 3 | CH36: 4 | CI36: 4 | CJ36: 4 | CK36: 4 | CL36: 4 | CM36: 4 | CN36: 4 | CO36: 2 | CP36: 2 | CQ36: 3 | CR36: 2 | CS36: 4 | CT36: 2 | CU36: 2
A37: 6º ano B | B37: 4 | C37: 3 | D37: 4 | E37: 3 | F37: 4 | G37: 2 | H37: 4 | I37: 3 | J37: 3 | K37: 3 | L37: 4 | M37: 3 | N37: 3 | O37: 3 | P37: 4 | Q37: 4 | R37: 3 | S37: 4 | T37: 3 | U37: 4 | V37: 4 | W37: 4 | X37: 4 | Y37: 4 | Z37: 3 | AA37: 4 | AB37: 4 | AC37: 4 | AD37: 3 | AE37: 2 | AF37: 3 | AG37: 4 | AH37: 3 | AI37: 3 | AJ37: 3 | AK37: 4 | AL37: 4 | AM37: 3 | AN37: 4 | AO37: 3 | AP37: 4 | AQ37: 4 | AR37: 3 | AS37: 2 | AT37: 3 | AU37: 2 | AV37: 2 | AW37: 3 | AX37: 4 | AY37: 3 | AZ37: 2 | BA37: 3 | BB37: 4 | BC37: 4 | BD37: 4 | BE37: 4 | BF37: 4 | BG37: 4 | BH37: 4 | BI37: 2 | BJ37: 4 | BK37: 2 | BL37: 4 | BM37: 4 | BN37: 4 | BO37: 3 | BP37: 4 | BQ37: 4 | BR37: 4 | BS37: 4 | BT37: 4 | BU37: 3 | BV37: 4 | BW37: 4 | BX37: 4 | BY37: 3 | BZ37: 4 | CA37: 3 | CB37: 3 | CC37: 4 | CD37: 4 | CE37: 4 | CF37: 3 | CG37: 4 | CH37: 4 | CI37: 3 | CJ37: 4 | CK37: 3 | CL37: 4 | CM37: 3 | CN37: 4 | CO37: 4 | CP37: 3 | CQ37: 4 | CR37: 3 | CS37: 4 | CT37: 4 | CU37: 4
A38: 6º ano B | B38: 3 | C38: 4 | D38: 4 | E38: 4 | F38: 3 | G38: 2 | H38: 2 | I38: 3 | J38: 1 | K38: 2 | L38: 4 | M38: 4 | N38: 3 | O38: 2 | P38: 4 | Q38: 4 | R38: 4 | S38: 4 | T38: 4 | U38: 4 | V38: 4 | W38: 3 | X38: 2 | Y38: 4 | Z38: 4 | AA38: 4 | AB38: 2 | AC38: 2 | AD38: 3 | AE38: 1 | AF38: 4 | AG38: 4 | AH38: 3 | AI38: 2 | AJ38: 3 | AK38: 4 | AL38: 4 | AM38: 3 | AN38: 4 | AO38: 4 | AP38: 4 | AQ38: 4 | AR38: 3 | AS38: 4 | AT38: 4 | AU38: 2 | AV38: 4 | AW38: 2 | AX38: 2 | AY38: 2 | AZ38: 1 | BA38: 1 | BB38: 4 | BC38: 3 | BD38: 4 | BE38: 2 | BF38: 4 | BG38: 2 | BH38: 4 | BI38: 4 | BJ38: 4 | BK38: 4 | BL38: 4 | BM38: 4 | BN38: 4 | BO38: 3 | BP38: 4 | BQ38: 4 | BR38: 3 | BS38: 4 | BT38: 4 | BU38: 4 | BV38: 4 | BW38: 4 | BX38: 4 | BY38: 4 | BZ38: 4 | CA38: 4 | CB38: 4 | CC38: 4 | CD38: 4 | CE38: 4 | CF38: 4 | CG38: 1 | CH38: 4 | CI38: 4 | CJ38: 4 | CK38: 4 | CL38: 4 | CM38: 4 | CN38: 4 | CO38: 4 | CP38: 4 | CQ38: 4 | CR38: 4 | CS38: 4 | CT38: 4 | CU38: 4
A39: 6º ano B | B39: 2 | C39: 3 | D39: 3 | E39: 1 | F39: 2 | G39: 1 | H39: 3 | I39: 3 | J39: 2 | K39: 2 | L39: 1 | M39: 3 | N39: 2 | O39: 4 | P39: 3 | Q39: 3 | R39: 3 | S39: 3 | T39: 3 | U39: 3 | V39: 3 | W39: 3 | X39: 4 | Y39: 4 | Z39: 3 | AA39: 3 | AB39: 2 | AC39: 4 | AD39: 2 | AE39: 1 | AF39: 2 | AG39: 2 | AH39: 2 | AI39: 1 | AJ39: 4 | AK39: 2 | AL39: 4 | AM39: 3 | AN39: 3 | AO39: 4 | AP39: 2 | AR39: 2 | AS39: 2 | AT39: 3 | AU39: 1 | AV39: 1 | AW39: 1 | AX39: 2 | AY39: 3 | AZ39: 1 | BA39: 3 | BB39: 4 | BC39: 4 | BD39: 4 | BE39: 4 | BF39: 3 | BG39: 4 | BH39: 4 | BI39: 1 | BJ39: 1 | BK39: 1 | BL39: 4 | BM39: 4 | BN39: 2 | BO39: 1 | BP39: 2 | BQ39: 3 | BR39: 1 | BS39: 2 | BT39: 4 | BU39: 4 | BV39: 4 | BW39: 3 | BX39: 4 | BY39: 2 | BZ39: 4 | CA39: 4 | CB39: 4 | CC39: 3 | CD39: 4 | CE39: 4 | CF39: 4 | CG39: 3 | CH39: 4 | CI39: 2 | CJ39: 4 | CK39: 4 | CL39: 4 | CM39: 4 | CN39: 4 | CO39: 2 | CP39: 1 | CQ39: 3 | CR39: 1 | CS39: 2 | CT39: 1 | CU39: 2
A40: 6º ano B | B40: 3 | C40: 3 | D40: 4 | E40: 3 | F40: 4 | G40: 2 | H40: 4 | I40: 4 | J40: 3 | K40: 4 | L40: 4 | M40: 4 | N40: 3 | O40: 3 | P40: 4 | Q40: 3 | R40: 4 | S40: 3 | T40: 4 | U40: 4 | V40: 4 | W40: 4 | X40: 4 | Y40: 4 | Z40: 4 | AA40: 4 | AB40: 3 | AC40: 4 | AD40: 3 | AE40: 2 | AF40: 3 | AG40: 4 | AH40: 3 | AI40: 3 | AJ40: 4 | AK40: 3 | AL40: 4 | AM40: 3 | AN40: 4 | AO40: 4 | AP40: 3 | AQ40: 4 | AR40: 4 | AS40: 3 | AT40: 4 | AU40: 3 | AV40: 4 | AW40: 3 | AX40: 4 | AY40: 4 | AZ40: 4 | BA40: 4 | BB40: 4 | BC40: 4 | BD40: 4 | BE40: 4 | BF40: 3 | BG40: 4 | BH40: 4 | BI40: 2 | BJ40: 4 | BK40: 3 | BL40: 4 | BM40: 4 | BN40: 4 | BO40: 4 | BP40: 4 | BQ40: 4 | BR40: 3 | BS40: 4 | BT40: 4 | BU40: 4 | BV40: 4 | BW40: 4 | BX40: 4 | BY40: 4 | BZ40: 4 | CA40: 4 | CB40: 4 | CC40: 4 | CD40: 4 | CE40: 4 | CF40: 4 | CG40: 4 | CH40: 4 | CI40: 4 | CJ40: 4 | CK40: 4 | CL40: 4 | CM40: 4 | CN40: 4 | CO40: 3 | CP40: 2 | CQ40: 3 | CR40: 3 | CS40: 4 | CT40: 3 | CU40: 4
...

Sheet 7° Ano
B1: Alberto - Matemática | I1: Andreia - Ciências Sociais | P1: Ariany - Arte e música | W1: Daniela - Ciência aplicada | AD1: Danielle - Ciência Aplicada | AK1: Karen - Redação | AR1: Márcia - Arte Visual | AY1: Mário - Geografia | BF1: Monique - LIV | BM1: Pavarina - Educação Física | BT1: Renata - Inglês CLIL | CA1: Ricardo - História | CH1: Rita - Leitura e Gramática | CO1: Samarina - Ciências | CV1: Thomas - Ciência aplicada | DC1: Valeska - Inglês
A2: Perguntas | B2: 1 | C2: 2 | D2: 3 | E2: 4 | F2: 5 | G2: 6 | H2: 7 | I2: 1 | J2: 2 | K2: 3 | L2: 4 | M2: 5 | N2: 6 | O2: 7 | P2: 1 | Q2: 2 | R2: 3 | S2: 4 | T2: 5 | U2: 6 | V2: 7 | W2: 1 | X2: 2 | Y2: 3 | Z2: 4 | AA2: 5 | AB2: 6 | AC2: 7 | AD2: 1 | AE2: 2 | AF2: 3 | AG2: 4 | AH2: 5 | AI2: 6 | AJ2: 7 | AK2: 1 | AL2: 2 | AM2: 3 | AN2: 4 | AO2: 5 | AP2: 6 | AQ2: 7 | AR2: 1 | AS2: 2 | AT2: 3 | AU2: 4 | AV2: 5 | AW2: 6 | AX2: 7 | AY2: 1 | AZ2: 2 | BA2: 3 | BB2: 4 | BC2: 5 | BD2: 6 | BE2: 7 | BF2: 1 | BG2: 2 | BH2: 3 | BI2: 4 | BJ2: 5 | BK2: 6 | BL2: 7 | BM2: 1 | BN2: 2 | BO2: 3 | BP2: 4 | BQ2: 5 | BR2: 6 | BS2: 7 | BT2: 1 | BU2: 2 | BV2: 3 | BW2: 4 | BX2: 5 | BY2: 6 | BZ2: 7 | CA2: 1 | CB2: 2 | CC2: 3 | CD2: 4 | CE2: 5 | CF2: 6 | CG2: 7 | CH2: 1 | CI2: 2 | CJ2: 3 | CK2: 4 | CL2: 5 | CM2: 6 | CN2: 7 | CO2: 1 | CP2: 2 | CQ2: 3 | CR2: 4 | CS2: 5 | CT2: 6 | CU2: 7 | CV2: 1 | CW2: 2 | CX2: 3 | CY2: 4 | CZ2: 5 | DA2: 6 | DB2: 7 | DC2: 1 | DD2: 2 | DE2: 3 | DF2: 4 | DG2: 5 | DH2: 6 | DI2: 7
A3: 7º ano A | B3: 4 | C3: 4 | D3: 4 | E3: 3 | F3: 4 | G3: 3 | H3: 4 | I3: 4 | J3: 4 | K3: 4 | L3: 3 | M3: 4 | N3: 4 | O3: 4 | P3: 3 | Q3: 3 | R3: 3 | S3: 3 | T3: 4 | U3: 2 | V3: 4 | W3: 3 | X3: 4 | Y3: 3 | Z3: 4 | AA3: 4 | AB3: 2 | AC3: 4 | AD3: 4 | AE3: 4 | AF3: 4 | AG3: 4 | AH3: 4 | AI3: 4 | AJ3: 4 | AK3: 4 | AL3: 3 | AM3: 4 | AN3: 3 | AO3: 4 | AP3: 2 | AQ3: 4 | AR3: 3 | AS3: 3 | AT3: 2 | AU3: 2 | AV3: 3 | AW3: 1 | AX3: 3 | AY3: 4 | AZ3: 3 | BA3: 4 | BB3: 4 | BC3: 3 | BD3: 4 | BE3: 4 | BF3: 4 | BG3: 4 | BH3: 4 | BI3: 4 | BJ3: 4 | BK3: 4 | BL3: 4 | BM3: 1 | BN3: 1 | BO3: 1 | BP3: 1 | BQ3: 1 | BR3: 1 | BS3: 1 | BT3: 4 | BU3: 4 | BV3: 4 | BW3: 3 | BX3: 4 | BY3: 4 | BZ3: 4 | CA3: 4 | CB3: 4 | CC3: 4 | CD3: 4 | CE3: 4 | CF3: 4 | CG3: 4 | CH3: 4 | CI3: 4 | CJ3: 4 | CK3: 4 | CL3: 4 | CM3: 4 | CN3: 4 | CO3: 4 | CP3: 4 | CQ3: 4 | CR3: 3 | CS3: 4 | CT3: 2 | CU3: 4 | CV3: 4 | CW3: 4 | CX3: 4 | CY3: 4 | CZ3: 4 | DA3: 4 | DB3: 4 | DC3: 4 | DD3: 4 | DE3: 4 | DF3: 4 | DG3: 4 | DH3: 4 | DI3: 4
A4: 7º ano A | B4: 2 | C4: 3 | D4: 4 | E4: 3 | F4: 4 | G4: 2 | H4: 3 | I4: 4 | J4: 4 | K4: 4 | L4: 4 | M4: 4 | N4: 4 | O4: 4 | P4: 4 | Q4: 1 | R4: 4 | S4: 4 | T4: 4 | U4: 4 | V4: 4 | W4: 2 | X4: 4 | Y4: 4 | Z4: 4 | AA4: 4 | AB4: 3 | AC4: 4 | AD4: 4 | AE4: 3 | AF4: 3 | AG4: 4 | AH4: 4 | AI4: 3 | AJ4: 4 | AK4: 4 | AL4: 1 | AM4: 4 | AN4: 3 | AO4: 4 | AP4: 3 | AQ4: 3 | AR4: 4 | AS4: 2 | AT4: 2 | AU4: 4 | AV4: 4 | AW4: 2 | AX4: 3 | AY4: 4 | AZ4: 1 | BA4: 2 | BB4: 4 | BC4: 3 | BD4: 4 | BE4: 2 | BF4: 4 | BG4: 4 | BH4: 4 | BI4: 4 | BJ4: 4 | BK4: 4 | BL4: 4 | BM4: 4 | BN4: 4 | BO4: 3 | BP4: 4 | BQ4: 4 | BR4: 3 | BS4: 3 | BT4: 4 | BU4: 4 | BV4: 4 | BW4: 4 | BX4: 4 | BY4: 4 | BZ4: 4 | CA4: 4 | CB4: 2 | CC4: 2 | CD4: 4 | CE4: 3 | CF4: 4 | CG4: 4 | CH4: 4 | CI4: 4 | CJ4: 4 | CK4: 4 | CL4: 4 | CM4: 4 | CN4: 4 | CO4: 4 | CP4: 2 | CQ4: 4 | CR4: 4 | CS4: 4 | CT4: 3 | CU4: 4 | CV4: 2 | CW4: 3 | CX4: 4 | CY4: 4 | CZ4: 4 | DA4: 3 | DB4: 4 | DC4: 4 | DD4: 2 | DE4: 3 | DF4: 4 | DG4: 3 | DH4: 3 | DI4: 3
A5: 7º ano A | B5: 2 | C5: 3 | D5: 4 | E5: 3 | F5: 4 | G5: 2 | H5: 3 | I5: 4 | J5: 4 | K5: 4 | L5: 4 | M5: 4 | N5: 4 | O5: 4 | P5: 4 | Q5: 1 | R5: 4 | S5: 4 | T5: 4 | U5: 4 | V5: 4 | W5: 2 | X5: 4 | Y5: 4 | Z5: 4 | AA5: 4 | AB5: 3 | AC5: 4 | AD5: 4 | AE5: 3 | AF5: 3 | AG5: 4 | AH5: 4 | AI5: 3 | AJ5: 4 | AK5: 4 | AL5: 1 | AM5: 4 | AN5: 3 | AO5: 4 | AP5: 3 | AQ5: 3 | AR5: 4 | AS5: 2 | AT5: 2 | AU5: 4 | AV5: 4 | AW5: 2 | AX5: 3 | AY5: 4 | AZ5: 1 | BA5: 2 | BB5: 4 | BC5: 4 | BD5: 4 | BE5: 3 | BF5: 4 | BG5: 4 | BH5: 4 | BI5: 4 | BJ5: 4 | BK5: 4 | BL5: 4 | BM5: 4 | BN5: 4 | BO5: 3 | BP5: 4 | BQ5: 4 | BR5: 3 | BS5: 3 | BT5: 4 | BU5: 4 | BV5: 4 | BW5: 4 | BX5: 4 | BY5: 4 | BZ5: 4 | CA5: 4 | CB5: 2 | CC5: 2 | CD5: 4 | CE5: 3 | CF5: 4 | CG5: 4 | CH5: 4 | CI5: 4 | CJ5: 4 | CK5: 4 | CL5: 4 | CM5: 4 | CN5: 4 | CO5: 4 | CP5: 2 | CQ5: 4 | CR5: 4 | CS5: 4 | CT5: 3 | CU5: 4 | CV5: 2 | CW5: 3 | CX5: 4 | CY5: 4 | CZ5: 4 | DA5: 3 | DB5: 4 | DC5: 4 | DD5: 2 | DE5: 3 | DF5: 4 | DG5: 3 | DH5: 3 | DI5: 3
A6: 7º ano A | B6: 4 | C6: 4 | D6: 4 | E6: 3 | F6: 4 | G6: 3 | H6: 4 | I6: 3 | J6: 4 | K6: 3 | L6: 4 | M6: 3 | N6: 4 | O6: 4 | P6: 2 | Q6: 2 | R6: 2 | S6: 2 | T6: 1 | U6: 2 | V6: 3 | W6: 4 | X6: 3 | Y6: 3 | Z6: 3 | AA6: 3 | AB6: 3 | AC6: 3 | AD6: 3 | AE6: 3 | AF6: 3 | AG6: 3 | AH6: 3 | AI6: 3 | AJ6: 3 | AK6: 2 | AL6: 2 | AM6: 2 | AN6: 2 | AO6: 4 | AP6: 2 | AQ6: 3 | AR6: 4 | AS6: 3 | AT6: 3 | AU6: 4 | AV6: 4 | AW6: 2 | AX6: 4 | AY6: 4 | AZ6: 4 | BA6: 4 | BB6: 4 | BC6: 4 | BD6: 4 | BE6: 4 | BF6: 4 | BG6: 4 | BH6: 4 | BI6: 4 | BJ6: 4 | BK6: 4 | BL6: 4 | BM6: 1 | BN6: 1 | BO6: 1 | BP6: 1 | BQ6: 1 | BR6: 1 | BS6: 1 | BT6: 4 | BU6: 4 | BV6: 4 | BW6: 4 | BX6: 4 | BY6: 4 | BZ6: 4 | CA6: 4 | CB6: 4 | CC6: 4 | CD6: 4 | CE6: 4 | CF6: 4 | CG6: 4 | CH6: 4 | CI6: 4 | CJ6: 4 | CK6: 4 | CL6: 4 | CM6: 4 | CN6: 4 | CO6: 3 | CP6: 3 | CQ6: 3 | CR6: 3 | CS6: 3 | CT6: 3 | CU6: 4 | CV6: 4 | CW6: 4 | CX6: 4 | CY6: 4 | CZ6: 4 | DA6: 4 | DB6: 4 | DC6: 4 | DD6: 4 | DE6: 4 | DF6: 4 | DG6: 4 | DH6: 4 | DI6: 4
