Workbook

Sheet Valores Gerais
A1: Segmento | B1: Turma | C1: Nome | D1: Disciplina | E1: Didática | F1: Apoio | G1: Tempo | H1: Avaliação | I1: Clima | J1: Respeito | K1: Domínio | L1: Média Geral por turma | M1: Média geral do ano
A2: Ensino Fundamental | B2: 6°A | C2: Alice | D2: Arte e Dança | E2: =AVERAGE('6°Ano'!B3:B27) -> 3.4166667 | F2: =AVERAGE('6°Ano'!C3:C27) -> 3.2 | G2: =AVERAGE('6°Ano'!D3:D27) -> 3.3333333 | H2: =AVERAGE('6°Ano'!E3:E27) -> 3.16 | I2: =AVERAGE('6°Ano'!F3:F27) -> 3.4 | J2: =AVERAGE('6°Ano'!G3:G27) -> 2.6521739 | K2: =AVERAGE('6°Ano'!H3:H27) -> 3.375 | L2: =AVERAGE(E2:K2) -> 3.2195963 | M2: =AVERAGE(L2:L5) -> 3.2388666
A3: Ensino Fundamental | B3: 6°B | C3: Alice | D3: Arte e Dança | E3: =AVERAGE('6°Ano'!B28:B48) -> 3.1904762 | F3: =AVERAGE('6°Ano'!C28:C48) -> 3.3 | G3: =AVERAGE('6°Ano'!D28:D48) -> 3.3333333 | H3: =AVERAGE('6°Ano'!E28:E48) -> 3.1428571 | I3: =AVERAGE('6°Ano'!F28:F48) -> 3.4761905 | J3: =AVERAGE('6°Ano'!G28:G48) -> 2.4285714 | K3: =AVERAGE('6°Ano'!H28:H48) -> 3.5238095 | L3: =AVERAGE(E3:K3) -> 3.1993197
A4: Ensino Fundamental | B4: 6°C | C4: Alice | D4: Arte e Dança | E4: =AVERAGE('6°Ano'!B49:B75) -> 3.3076923 | F4: =AVERAGE('6°Ano'!C49:C75) -> 3.4230769 | G4: =AVERAGE('6°Ano'!D49:D75) -> 3.6923077 | H4: =AVERAGE('6°Ano'!E49:E75) -> 3.2692308 | I4: =AVERAGE('6°Ano'!F49:F75) -> 3.4615385 | J4: =AVERAGE('6°Ano'!G49:G75) -> 2.5769231 | K4: =AVERAGE('6°Ano'!H49:H75) -> 3.8076923 | L4: =AVERAGE(E4:K4) -> 3.3626374
A5: Ensino Fundamental | B5: 6°D | C5: Alice | D5: Arte e Dança | E5: =AVERAGE('6°Ano'!B76:B98) -> 3.2173913 | F5: =AVERAGE('6°Ano'!C76:C98) -> 3.0869565 | G5: =AVERAGE('6°Ano'!D76:D98) -> 3.5217391 | H5: =AVERAGE('6°Ano'!E76:E98) -> 2.9565217 | I5: =AVERAGE('6°Ano'!F76:F98) -> 3.3913043 | J5: =AVERAGE('6°Ano'!G76:G98) -> 2.3913043 | K5: =AVERAGE('6°Ano'!H76:H98) -> 3.6521739 | L5: =AVERAGE(E5:K5) -> 3.173913
A6: Ensino Fundamental | B6: 6°A | C6: Daniela | D6: Ciências e Ciência Aplicada | E6: =AVERAGE('6°Ano'!I3:I27) -> 2.28 | F6: =AVERAGE('6°Ano'!J3:J27) -> 1.88 | G6: =AVERAGE('6°Ano'!K3:K27) -> 2.4 | H6: =AVERAGE('6°Ano'!L3:L27) -> 2.56 | I6: =AVERAGE('6°Ano'!M3:M27) -> 2.84 | J6: =AVERAGE('6°Ano'!N3:N27) -> 2.2 | K6: =AVERAGE('6°Ano'!O3:O27) -> 2.68 | L6: =AVERAGE(E6:K6) -> 2.4057143 | M6: =AVERAGE(L6:L9) -> 2.7098626
A7: Ensino Fundamental | B7: 6°B | C7: Daniela | D7: Ciências e Ciência Aplicada | E7: =AVERAGE('6°Ano'!I28:I48) -> 2.5238095 | F7: =AVERAGE('6°Ano'!J28:J48) -> 2.0952381 | G7: =AVERAGE('6°Ano'!K28:K48) -> 2.4285714 | H7: =AVERAGE('6°Ano'!L28:L48) -> 2.8095238 | I7: =AVERAGE('6°Ano'!M28:M48) -> 2.9047619 | J7: =AVERAGE('6°Ano'!N28:N48) -> 2.3809524 | K7: =AVERAGE('6°Ano'!O28:O48) -> 2.6190476 | L7: =AVERAGE(E7:K7) -> 2.537415
A8: Ensino Fundamental | B8: 6°C | C8: Daniela | D8: Ciências e Ciência Aplicada | E8: =AVERAGE('6°Ano'!I49:I75) -> 3.0384615 | F8: =AVERAGE('6°Ano'!J49:J75) -> 2.3461538 | G8: =AVERAGE('6°Ano'!K49:K75) -> 3.1153846 | H8: =AVERAGE('6°Ano'!L49:L75) -> 3.1923077 | I8: =AVERAGE('6°Ano'!M49:M75) -> 3.5384615 | J8: =AVERAGE('6°Ano'!N49:N75) -> 2.8076923 | K8: =AVERAGE('6°Ano'!O49:O75) -> 3.1923077 | L8: =AVERAGE(E8:K8) -> 3.032967
A9: Ensino Fundamental | B9: 6°D | C9: Daniela | D9: Ciências e Ciência Aplicada | E9: =AVERAGE('6°Ano'!I76:I98) -> 2.9130435 | F9: =AVERAGE('6°Ano'!J76:J98) -> 2.4782609 | G9: =AVERAGE('6°Ano'!K76:K98) -> 2.7826087 | H9: =AVERAGE('6°Ano'!L76:L98) -> 3.0434783 | I9: =AVERAGE('6°Ano'!M76:M98) -> 3.2608696 | J9: =AVERAGE('6°Ano'!N76:N98) -> 2.3913043 | K9: =AVERAGE('6°Ano'!O76:O98) -> 3.173913 | L9: =AVERAGE(E9:K9) -> 2.863354
A10: Ensino Fundamental | B10: 6°A | C10: Danielle | D10: Ciências e Ciência Aplicada | E10: =AVERAGE('6°Ano'!P3:P27) -> 3.12 | F10: =AVERAGE('6°Ano'!Q3:Q27) -> 3.04 | G10: =AVERAGE('6°Ano'!R3:R27) -> 3.16 | H10: =AVERAGE('6°Ano'!S3:S27) -> 3.08 | I10: =AVERAGE('6°Ano'!T3:T27) -> 2.88 | J10: =AVERAGE('6°Ano'!U3:U27) -> 2.88 | K10: =AVERAGE('6°Ano'!V3:V27) -> 3.04 | L10: =AVERAGE(E10:K10) -> 3.0285714 | M10: =AVERAGE(L10:L13) -> 3.3158056
A11: Ensino Fundamental | B11: 6°B | C11: Danielle | D11: Ciências e Ciência Aplicada | E11: =AVERAGE('6°Ano'!P28:P48) -> 3.5 | F11: =AVERAGE('6°Ano'!Q28:Q48) -> 3.3 | G11: =AVERAGE('6°Ano'!R28:R48) -> 3.55 | H11: =AVERAGE('6°Ano'!S28:S48) -> 3.5 | I11: =AVERAGE('6°Ano'!T28:T48) -> 3.2 | J11: =AVERAGE('6°Ano'!U28:U48) -> 3.35 | K11: =AVERAGE('6°Ano'!V28:V48) -> 3.55 | L11: =AVERAGE(E11:K11) -> 3.4214286
A12: Ensino Fundamental | B12: 6°C | C12: Danielle | D12: Ciências e Ciência Aplicada | E12: =AVERAGE('6°Ano'!P49:P75) -> 3.6538462 | F12: =AVERAGE('6°Ano'!Q49:Q75) -> 3.3076923 | G12: =AVERAGE('6°Ano'!R49:R75) -> 3.5 | H12: =AVERAGE('6°Ano'!S49:S75) -> 3.4615385 | I12: =AVERAGE('6°Ano'!T49:T75) -> 3.88 | J12: =AVERAGE('6°Ano'!U49:U75) -> 3.1538462 | K12: =AVERAGE('6°Ano'!V49:V75) -> 3.7692308 | L12: =AVERAGE(E12:K12) -> 3.5323077
A13: Ensino Fundamental | B13: 6°D | C13: Danielle | D13: Ciências e Ciência Aplicada | E13: =AVERAGE('6°Ano'!P76:P98) -> 3.3478261 | F13: =AVERAGE('6°Ano'!Q76:Q98) -> 2.9090909 | G13: =AVERAGE('6°Ano'!R76:R98) -> 3.3181818 | H13: =AVERAGE('6°Ano'!S76:S98) -> 3.3913043 | I13: =AVERAGE('6°Ano'!T76:T98) -> 3.4782609 | J13: =AVERAGE('6°Ano'!U76:U98) -> 3 | K13: =AVERAGE('6°Ano'!V76:V98) -> 3.5217391 | L13: =AVERAGE(E13:K13) -> 3.2809147
A14: Ensino Fundamental | B14: 6°A | C14: Diego | D14: Matemática | E14: =AVERAGE('6°Ano'!W3:W27) -> 3.64 | F14: =AVERAGE('6°Ano'!X3:X27) -> 3.6 | G14: =AVERAGE('6°Ano'!Y3:Y27) -> 3.64 | H14: =AVERAGE('6°Ano'!Z3:Z27) -> 3.48 | I14: =AVERAGE('6°Ano'!AA3:AA27) -> 3.6 | J14: =AVERAGE('6°Ano'!AB3:AB27) -> 3.44 | K14: =AVERAGE('6°Ano'!AC3:AC27) -> 3.64 | L14: =AVERAGE(E14:K14) -> 3.5771429 | M14: =AVERAGE(L14:L17) -> 3.6525755
A15: Ensino Fundamental | B15: 6°B | C15: Diego | D15: Matemática | E15: =AVERAGE('6°Ano'!W28:W48) -> 3.8095238 | F15: =AVERAGE('6°Ano'!X28:X48) -> 3.4761905 | G15: =AVERAGE('6°Ano'!Y28:Y48) -> 3.8571429 | H15: =AVERAGE('6°Ano'!Z28:Z48) -> 3.7619048 | I15: =AVERAGE('6°Ano'!AA28:AA48) -> 3.6666667 | J15: =AVERAGE('6°Ano'!AB28:AB48) -> 3.5238095 | K15: =AVERAGE('6°Ano'!AC28:AC48) -> 3.6666667 | L15: =AVERAGE(E15:K15) -> 3.6802721
A16: Ensino Fundamental | B16: 6°C | C16: Diego | D16: Matemática | E16: =AVERAGE('6°Ano'!W49:W75) -> 3.8888889 | F16: =AVERAGE('6°Ano'!X49:X75) -> 3.3703704 | G16: =AVERAGE('6°Ano'!Y49:Y75) -> 3.5925926 | H16: =AVERAGE('6°Ano'!Z49:Z75) -> 3.7037037 | I16: =AVERAGE('6°Ano'!AA49:AA75) -> 3.8518519 | J16: =AVERAGE('6°Ano'!AB49:AB75) -> 3.4814815 | K16: =AVERAGE('6°Ano'!AC49:AC75) -> 3.4074074 | L16: =AVERAGE(E16:K16) -> 3.6137566
A17: Ensino Fundamental | B17: 6°D | C17: Diego | D17: Matemática | E17: =AVERAGE('6°Ano'!W76:W98) -> 3.9130435 | F17: =AVERAGE('6°Ano'!X76:X98) -> 3.7826087 | G17: =AVERAGE('6°Ano'!Y76:Y98) -> 3.8695652 | H17: =AVERAGE('6°Ano'!Z76:Z98) -> 3.5217391 | I17: =AVERAGE('6°Ano'!AA76:AA98) -> 3.9130435 | J17: =AVERAGE('6°Ano'!AB76:AB98) -> 3.3478261 | K17: =AVERAGE('6°Ano'!AC76:AC98) -> 3.826087 | L17: =AVERAGE(E17:K17) -> 3.7391304
A18: Ensino Fundamental | B18: 6°A | C18: Karen | D18: Redação | E18: =AVERAGE('6°Ano'!AD3:AD27) -> 2.16 | F18: =AVERAGE('6°Ano'!AE3:AE27) -> 1.88 | G18: =AVERAGE('6°Ano'!AF3:AF27) -> 2.32 | H18: =AVERAGE('6°Ano'!AG3:AG27) -> 2.56 | I18: =AVERAGE('6°Ano'!AH3:AH27) -> 2.52 | J18: =AVERAGE('6°Ano'!AI3:AI27) -> 2.04 | K18: =AVERAGE('6°Ano'!AJ3:AJ27) -> 2.52 | L18: =AVERAGE(E18:K18) -> 2.2857143 | M18: =AVERAGE(L18:L21) -> 2.8255102
A19: Ensino Fundamental | B19: 6°B | C19: Karen | D19: Redação | E19: =AVERAGE('6°Ano'!AD28:AD48) -> 2.3809524 | F19: =AVERAGE('6°Ano'!AE28:AE48) -> 1.8095238 | G19: =AVERAGE('6°Ano'!AF28:AF48) -> 2.5714286 | H19: =AVERAGE('6°Ano'!AG28:AG48) -> 3 | I19: =AVERAGE('6°Ano'!AH28:AH48) -> 2.7142857 | J19: =AVERAGE('6°Ano'!AI28:AI48) -> 2.5238095 | K19: =AVERAGE('6°Ano'!AJ28:AJ48) -> 2.952381 | L19: =AVERAGE(E19:K19) -> 2.5646259
A20: Ensino Fundamental | B20: 6°C | C20: Karen | D20: Redação | E20: =AVERAGE('6°Ano'!AD49:AD75) -> 3.3461538 | F20: =AVERAGE('6°Ano'!AE49:AE75) -> 2.3461538 | G20: =AVERAGE('6°Ano'!AF49:AF75) -> 3.4230769 | H20: =AVERAGE('6°Ano'!AG49:AG75) -> 3.3461538 | I20: =AVERAGE('6°Ano'!AH49:AH75) -> 3.8076923 | J20: =AVERAGE('6°Ano'!AI49:AI75) -> 3.0384615 | K20: =AVERAGE('6°Ano'!AJ49:AJ75) -> 3.7692308 | L20: =AVERAGE(E20:K20) -> 3.2967033
A21: Ensino Fundamental | B21: 6°D | C21: Karen | D21: Redação | E21: =AVERAGE('6°Ano'!AD76:AD98) -> 3.3043478 | F21: =AVERAGE('6°Ano'!AE76:AE98) -> 2.6956522 | G21: =AVERAGE('6°Ano'!AF76:AF98) -> 3.3043478 | H21: =AVERAGE('6°Ano'!AG76:AG98) -> 2.9545455 | I21: =AVERAGE('6°Ano'!AH76:AH98) -> 3.6521739 | J21: =AVERAGE('6°Ano'!AI76:AI98) -> 2.7391304 | K21: =AVERAGE('6°Ano'!AJ76:AJ98) -> 3.4347826 | L21: =AVERAGE(E21:K21) -> 3.1549972
A22: Ensino Fundamental | B22: 6°A | C22: Luana | D22: Ciência Aplicada | E22: =AVERAGE('6°Ano'!AK3:AK27) -> 3.48 | F22: =AVERAGE('6°Ano'!AL3:AL27) -> 3.56 | G22: =AVERAGE('6°Ano'!AM3:AM27) -> 3.52 | H22: =AVERAGE('6°Ano'!AN3:AN27) -> 3.48 | I22: =AVERAGE('6°Ano'!AO3:AO27) -> 3.56 | J22: =AVERAGE('6°Ano'!AP3:AP27) -> 3.25 | K22: =AVERAGE('6°Ano'!AQ3:AQ27) -> 3.56 | L22: =AVERAGE(E22:K22) -> 3.4871429 | M22: =AVERAGE(L22:L25) -> 3.4212806
A23: Ensino Fundamental | B23: 6°B | C23: Luana | D23: Ciência Aplicada | E23: =AVERAGE('6°Ano'!AK28:AK48) -> 3.3333333 | F23: =AVERAGE('6°Ano'!AL28:AL48) -> 3.4285714 | G23: =AVERAGE('6°Ano'!AM28:AM48) -> 2.952381 | H23: =AVERAGE('6°Ano'!AN28:AN48) -> 3.3333333 | I23: =AVERAGE('6°Ano'!AO28:AO48) -> 3.2857143 | J23: =AVERAGE('6°Ano'!AP28:AP48) -> 3.2 | K23: =AVERAGE('6°Ano'!AQ28:AQ48) -> 3.55 | L23: =AVERAGE(E23:K23) -> 3.297619
A24: Ensino Fundamental | B24: 6°C | C24: Luana | D24: Ciência Aplicada | E24: =AVERAGE('6°Ano'!AK49:AK75) -> 3.3461538 | F24: =AVERAGE('6°Ano'!AL49:AL75) -> 3.2307692 | G24: =AVERAGE('6°Ano'!AM49:AM75) -> 3.2692308 | H24: =AVERAGE('6°Ano'!AN49:AN75) -> 3.3461538 | I24: =AVERAGE('6°Ano'!AO49:AO75) -> 3.5384615 | J24: =AVERAGE('6°Ano'!AP49:AP75) -> 3.1153846 | K24: =AVERAGE('6°Ano'!AQ49:AQ75) -> 3.5769231 | L24: =AVERAGE(E24:K24) -> 3.3461538
A25: Ensino Fundamental | B25: 6°D | C25: Luana | D25: Ciência Aplicada | E25: =AVERAGE('6°Ano'!AK76:AK98) -> 3.5217391 | F25: =AVERAGE('6°Ano'!AL76:AL98) -> 3.3913043 | G25: =AVERAGE('6°Ano'!AM76:AM98) -> 3.5652174 | H25: =AVERAGE('6°Ano'!AN76:AN98) -> 3.5217391 | I25: =AVERAGE('6°Ano'!AO76:AO98) -> 3.7826087 | J25: =AVERAGE('6°Ano'!AP76:AP98) -> 3.2272727 | K25: =AVERAGE('6°Ano'!AQ76:AQ98) -> 3.8695652 | L25: =AVERAGE(E25:K25) -> 3.5542067
A26: Ensino Fundamental | B26: 6°A | C26: Marcia | D26: Arte Visual | E26: =AVERAGE('6°Ano'!AR3:AR27) -> 3.12 | F26: =AVERAGE('6°Ano'!AS3:AS27) -> 3.24 | G26: =AVERAGE('6°Ano'!AT3:AT27) -> 3.36 | H26: =AVERAGE('6°Ano'!AU3:AU27) -> 2.7916667 | I26: =AVERAGE('6°Ano'!AV3:AV27) -> 3.32 | J26: =AVERAGE('6°Ano'!AW3:AW27) -> 2.96 | K26: =AVERAGE('6°Ano'!AX3:AX27) -> 3.24 | L26: =AVERAGE(E26:K26) -> 3.147381 | M26: =AVERAGE(L26:L29) -> 2.8849418
A27: Ensino Fundamental | B27: 6°B | C27: Marcia | D27: Arte Visual | E27: =AVERAGE('6°Ano'!AR28:AR48) -> 2.6666667 | F27: =AVERAGE('6°Ano'!AS28:AS48) -> 2.7142857 | G27: =AVERAGE('6°Ano'!AT28:AT48) -> 2.7619048 | H27: =AVERAGE('6°Ano'!AU28:AU48) -> 2.6190476 | I27: =AVERAGE('6°Ano'!AV28:AV48) -> 3 | J27: =AVERAGE('6°Ano'!AW28:AW48) -> 2.5714286 | K27: =AVERAGE('6°Ano'!AX28:AX48) -> 3.047619 | L27: =AVERAGE(E27:K27) -> 2.7687075
A28: Ensino Fundamental | B28: 6°C | C28: Marcia | D28: Arte Visual | E28: =AVERAGE('6°Ano'!AR49:AR75) -> 3.1153846 | F28: =AVERAGE('6°Ano'!AS49:AS75) -> 3.2307692 | G28: =AVERAGE('6°Ano'!AT49:AT75) -> 3.0769231 | H28: =AVERAGE('6°Ano'!AU49:AU75) -> 3 | I28: =AVERAGE('6°Ano'!AV49:AV75) -> 3.64 | J28: =AVERAGE('6°Ano'!AW49:AW75) -> 2.8076923 | K28: =AVERAGE('6°Ano'!AX49:AX75) -> 3.5384615 | L28: =AVERAGE(E28:K28) -> 3.2013187
A29: Ensino Fundamental | B29: 6°D | C29: Marcia | D29: Arte Visual | E29: =AVERAGE('6°Ano'!AR76:AR98) -> 2.3043478 | F29: =AVERAGE('6°Ano'!AS76:AS98) -> 2.6086957 | G29: =AVERAGE('6°Ano'!AT76:AT98) -> 2.0869565 | H29: =AVERAGE('6°Ano'!AU76:AU98) -> 2.3043478 | I29: =AVERAGE('6°Ano'!AV76:AV98) -> 3.1304348 | J29: =AVERAGE('6°Ano'!AW76:AW98) -> 2.2608696 | K29: =AVERAGE('6°Ano'!AX76:AX98) -> 2.2608696 | L29: =AVERAGE(E29:K29) -> 2.4223602
A30: Ensino Fundamental | B30: 6°A | C30: Mário | D30: Geografia | E30: =AVERAGE('6°Ano'!AY3:AY27) -> 2.88 | F30: =AVERAGE('6°Ano'!AZ3:AZ27) -> 2.72 | G30: =AVERAGE('6°Ano'!BA3:BA27) -> 3.04 | H30: =AVERAGE('6°Ano'!BB3:BB27) -> 3.52 | I30: =AVERAGE('6°Ano'!BC3:BC27) -> 3.36 | J30: =AVERAGE('6°Ano'!BD3:BD27) -> 3.64 | K30: =AVERAGE('6°Ano'!BE3:BE27) -> 3.08 | L30: =AVERAGE(E30:K30) -> 3.1771429 | M30: =AVERAGE(L30:L33) -> 3.1490252
A31: Ensino Fundamental | B31: 6°B | C31: Mário | D31: Geografia | E31: =AVERAGE('6°Ano'!AY28:AY48) -> 2.9047619 | F31: =AVERAGE('6°Ano'!AZ28:AZ48) -> 2.1904762 | G31: =AVERAGE('6°Ano'!BA28:BA48) -> 2.7619048 | H31: =AVERAGE('6°Ano'!BB28:BB48) -> 3.3809524 | I31: =AVERAGE('6°Ano'!BC28:BC48) -> 3.1904762 | J31: =AVERAGE('6°Ano'!BD28:BD48) -> 3.2380952 | K31: =AVERAGE('6°Ano'!BE28:BE48) -> 3 | L31: =AVERAGE(E31:K31) -> 2.952381
A32: Ensino Fundamental | B32: 6°C | C32: Mário | D32: Geografia | E32: =AVERAGE('6°Ano'!AY49:AY75) -> 3.4230769 | F32: =AVERAGE('6°Ano'!AZ49:AZ75) -> 2.8076923 | G32: =AVERAGE('6°Ano'!BA49:BA75) -> 3.0769231 | H32: =AVERAGE('6°Ano'!BB49:BB75) -> 3.9230769 | I32: =AVERAGE('6°Ano'!BC49:BC75) -> 3.5384615 | J32: =AVERAGE('6°Ano'!BD49:BD75) -> 4 | K32: =AVERAGE('6°Ano'!BE49:BE75) -> 3.6153846 | L32: =AVERAGE(E32:K32) -> 3.4835165
A33: Ensino Fundamental | B33: 6°D | C33: Mário | D33: Geografia | E33: =AVERAGE('6°Ano'!AY76:AY98) -> 2.7391304 | F33: =AVERAGE('6°Ano'!AZ76:AZ98) -> 2.6086957 | G33: =AVERAGE('6°Ano'!BA76:BA98) -> 2.6086957 | H33: =AVERAGE('6°Ano'!BB76:BB98) -> 3.3478261 | I33: =AVERAGE('6°Ano'!BC76:BC98) -> 3.3478261 | J33: =AVERAGE('6°Ano'!BD76:BD98) -> 3.2727273 | K33: =AVERAGE('6°Ano'!BE76:BE98) -> 2.9565217 | L33: =AVERAGE(E33:K33) -> 2.9830604
A34: Ensino Fundamental | B34: 6°A | C34: Monique | D34: LIV | E34: =AVERAGE('6°Ano'!BF3:BF27) -> 3.72 | F34: =AVERAGE('6°Ano'!BG3:BG27) -> 3.84 | G34: =AVERAGE('6°Ano'!BH3:BH27) -> 3.96 | H34: =AVERAGE('6°Ano'!BI3:BI27) -> 3.84 | I34: =AVERAGE('6°Ano'!BJ3:BJ27) -> 3.8333333 | J34: =AVERAGE('6°Ano'!BK3:BK27) -> 3.8 | K34: =AVERAGE('6°Ano'!BL3:BL27) -> 3.9166667 | L34: =AVERAGE(E34:K34) -> 3.8442857 | M34: =AVERAGE(L34:L37) -> 3.784096
A35: Ensino Fundamental | B35: 6°B | C35: Monique | D35: LIV | E35: =AVERAGE('6°Ano'!BF28:BF48) -> 3.7619048 | F35: =AVERAGE('6°Ano'!BG28:BG48) -> 3.7142857 | G35: =AVERAGE('6°Ano'!BH28:BH48) -> 3.8095238 | H35: =AVERAGE('6°Ano'!BI28:BI48) -> 3.4285714 | I35: =AVERAGE('6°Ano'!BJ28:BJ48) -> 3.4 | J35: =AVERAGE('6°Ano'!BK28:BK48) -> 3.4285714 | K35: =AVERAGE('6°Ano'!BL28:BL48) -> 3.8095238 | L35: =AVERAGE(E35:K35) -> 3.6217687
A36: Ensino Fundamental | B36: 6°C | C36: Monique | D36: LIV | E36: =AVERAGE('6°Ano'!BF49:BF75) -> 3.9230769 | F36: =AVERAGE('6°Ano'!BG49:BG75) -> 3.8461538 | G36: =AVERAGE('6°Ano'!BH49:BH75) -> 3.9230769 | H36: =AVERAGE('6°Ano'!BI49:BI75) -> 3.6923077 | I36: =AVERAGE('6°Ano'!BJ49:BJ75) -> 3.8076923 | J36: =AVERAGE('6°Ano'!BK49:BK75) -> 3.5384615 | K36: =AVERAGE('6°Ano'!BL49:BL75) -> 3.9615385 | L36: =AVERAGE(E36:K36) -> 3.8131868
A37: Ensino Fundamental | B37: 6°D | C37: Monique | D37: LIV | E37: =AVERAGE('6°Ano'!BF76:BF98) -> 3.9130435 | F37: =AVERAGE('6°Ano'!BG76:BG98) -> 3.9565217 | G37: =AVERAGE('6°Ano'!BH76:BH98) -> 3.9565217 | H37: =AVERAGE('6°Ano'!BI76:BI98) -> 3.6086957 | I37: =AVERAGE('6°Ano'!BJ76:BJ98) -> 3.9565217 | J37: =AVERAGE('6°Ano'!BK76:BK98) -> 3.6086957 | K37: =AVERAGE('6°Ano'!BL76:BL98) -> 4 | L37: =AVERAGE(E37:K37) -> 3.8571429
A38: Ensino Fundamental | B38: 6°A | C38: Pavarina | D38: Educação Física | E38: =AVERAGE('6°Ano'!BM3:BM27) -> 3.52 | F38: =AVERAGE('6°Ano'!BN3:BN27) -> 3.48 | G38: =AVERAGE('6°Ano'!BO3:BO27) -> 3.32 | H38: =AVERAGE('6°Ano'!BP3:BP27) -> 3.68 | I38: =AVERAGE('6°Ano'!BQ3:BQ27) -> 3.4 | J38: =AVERAGE('6°Ano'!BR3:BR27) -> 3.56 | K38: =AVERAGE('6°Ano'!BS3:BS27) -> 3.36 | L38: =AVERAGE(E38:K38) -> 3.4742857 | M38: =AVERAGE(L38:L41) -> 3.4671487
A39: Ensino Fundamental | B39: 6°B | C39: Pavarina | D39: Educação Física | E39: =AVERAGE('6°Ano'!BM28:BM48) -> 3.7 | F39: =AVERAGE('6°Ano'!BN28:BN48) -> 3.6190476 | G39: =AVERAGE('6°Ano'!BO28:BO48) -> 3.1904762 | H39: =AVERAGE('6°Ano'!BP28:BP48) -> 3.5238095 | I39: =AVERAGE('6°Ano'!BQ28:BQ48) -> 3.5714286 | J39: =AVERAGE('6°Ano'!BR28:BR48) -> 3.047619 | K39: =AVERAGE('6°Ano'!BS28:BS48) -> 3 | L39: =AVERAGE(E39:K39) -> 3.3789116
A40: Ensino Fundamental | B40: 6°C | C40: Pavarina | D40: Educação Física | E40: =AVERAGE('6°Ano'!BM49:BM75) -> 3.8461538 | F40: =AVERAGE('6°Ano'!BN49:BN75) -> 3.6923077 | G40: =AVERAGE('6°Ano'!BO49:BO75) -> 3.6923077 | H40: =AVERAGE('6°Ano'!BP49:BP75) -> 3.8076923 | I40: =AVERAGE('6°Ano'!BQ49:BQ75) -> 3.5 | J40: =AVERAGE('6°Ano'!BR49:BR75) -> 3.5384615 | K40: =AVERAGE('6°Ano'!BS49:BS75) -> 3.3846154 | L40: =AVERAGE(E40:K40) -> 3.6373626
...

Sheet 9°Ano
B1: Andreia - Ciências Sociais | I1: Carla - Matemática | P1: Carlos Dias - Matemática | W1: Ciro - Leitura e Gramática | AD1: Daniela - Inglês Language | AK1: Daniela - Ciência Aplicada | AR1: Danielle - Ciência Aplicada | AY1: Emerson - História | BF1: Jéssica - Redação | BM1: Kaique - Geografia | BT1: Luana - Ciências - Biologia e Química | CA1: Márcia - Arte Visual | CH1: Monique - LIV | CO1: Rafael Pavani - Atualidades | CV1: Pavarina - Educação Física | DC1: Valeska - Inglês CLIL | DJ1: Vitor - Ciência Aplicada | DQ1: Zé Eduardo - Física
A2: Perguntas | B2: 1 | C2: 2 | D2: 3 | E2: 4 | F2: 5 | G2: 6 | H2: 7 | I2: 1 | J2: 2 | K2: 3 | L2: 4 | M2: 5 | N2: 6 | O2: 7 | P2: 1 | Q2: 2 | R2: 3 | S2: 4 | T2: 5 | U2: 6 | V2: 7 | W2: 1 | X2: 2 | Y2: 3 | Z2: 4 | AA2: 5 | AB2: 6 | AC2: 7 | AD2: 1 | AE2: 2 | AF2: 3 | AG2: 4 | AH2: 5 | AI2: 6 | AJ2: 7 | AK2: 1 | AL2: 2 | AM2: 3 | AN2: 4 | AO2: 5 | AP2: 6 | AQ2: 7 | AR2: 1 | AS2: 2 | AT2: 3 | AU2: 4 | AV2: 5 | AW2: 6 | AX2: 7 | AY2: 1 | AZ2: 2 | BA2: 3 | BB2: 4 | BC2: 5 | BD2: 6 | BE2: 7 | BF2: 1 | BG2: 2 | BH2: 3 | BI2: 4 | BJ2: 5 | BK2: 6 | BL2: 7 | BM2: 1 | BN2: 2 | BO2: 3 | BP2: 4 | BQ2: 5 | BR2: 6 | BS2: 7 | BT2: 1 | BU2: 2 | BV2: 3 | BW2: 4 | BX2: 5 | BY2: 6 | BZ2: 7 | CA2: 1 | CB2: 2 | CC2: 3 | CD2: 4 | CE2: 5 | CF2: 6 | CG2: 7 | CH2: 1 | CI2: 2 | CJ2: 3 | CK2: 4 | CL2: 5 | CM2: 6 | CN2: 7 | CO2: 1 | CP2: 2 | CQ2: 3 | CR2: 4 | CS2: 5 | CT2: 6 | CU2: 7 | CV2: 1 | CW2: 2 | CX2: 3 | CY2: 4 | CZ2: 5 | DA2: 6 | DB2: 7 | DC2: 1 | DD2: 2 | DE2: 3 | DF2: 4 | DG2: 5 | DH2: 6 | DI2: 7 | DJ2: 1 | DK2: 2 | DL2: 3 | DM2: 4 | DN2: 5 | DO2: 6 | DP2: 7 | DQ2: 1 | DR2: 2 | DS2: 3 | DT2: 4 | DU2: 5 | DV2: 6 | DW2: 7
A3: 9º ano A | B3: 4 | C3: 4 | D3: 4 | E3: 4 | F3: 4 | G3: 4 | H3: 4 | I3: 4 | J3: 4 | K3: 4 | L3: 4 | M3: 4 | N3: 4 | O3: 4 | P3: 4 | Q3: 4 | R3: 4 | S3: 4 | T3: 4 | U3: 4 | V3: 4 | W3: 4 | X3: 4 | Y3: 4 | Z3: 4 | AA3: 4 | AB3: 4 | AC3: 4 | AD3: 4 | AE3: 4 | AF3: 4 | AG3: 4 | AH3: 4 | AI3: 4 | AJ3: 4 | AK3: 4 | AL3: 4 | AM3: 4 | AN3: 4 | AO3: 4 | AP3: 4 | AQ3: 4 | AR3: 4 | AS3: 4 | AT3: 4 | AU3: 4 | AV3: 4 | AW3: 4 | AX3: 4 | AY3: 4 | AZ3: 4 | BA3: 4 | BB3: 4 | BC3: 4 | BD3: 4 | BE3: 4 | BF3: 1 | BG3: 1 | BH3: 1 | BI3: 1 | BJ3: 1 | BK3: 1 | BL3: 1 | BM3: 4 | BN3: 4 | BO3: 4 | BP3: 4 | BQ3: 4 | BR3: 4 | BS3: 4 | BT3: 4 | BU3: 4 | BV3: 4 | BW3: 4 | BX3: 4 | BY3: 4 | BZ3: 4 | CA3: 1 | CB3: 1 | CC3: 1 | CD3: 1 | CE3: 1 | CF3: 1 | CG3: 2 | CH3: 4 | CI3: 4 | CJ3: 4 | CK3: 4 | CL3: 4 | CM3: 4 | CN3: 4 | CO3: 4 | CP3: 4 | CQ3: 4 | CR3: 4 | CS3: 4 | CT3: 4 | CU3: 4 | CV3: 1 | CW3: 1 | CX3: 1 | CY3: 1 | CZ3: 1 | DA3: 1 | DB3: 1 | DC3: 1 | DD3: 1 | DE3: 1 | DF3: 1 | DG3: 1 | DH3: 1 | DI3: 1 | DJ3: 4 | DK3: 4 | DL3: 4 | DM3: 4 | DN3: 4 | DO3: 4 | DP3: 4 | DQ3: 4 | DR3: 4 | DS3: 4 | DT3: 4 | DU3: 4 | DV3: 4 | DW3: 4
A4: 9º ano A | B4: 4 | C4: 4 | D4: 4 | E4: 4 | F4: 3 | G4: 4 | H4: 4 | I4: 4 | J4: 4 | K4: 4 | L4: 4 | M4: 3 | N4: 4 | O4: 4 | P4: 4 | Q4: 4 | R4: 4 | S4: 3 | T4: 3 | U4: 4 | V4: 4 | W4: 4 | X4: 3 | Y4: 4 | Z4: 4 | AA4: 4 | AB4: 4 | AC4: 4 | AD4: 3 | AE4: 3 | AF4: 3 | AG4: 3 | AH4: 2 | AI4: 4 | AJ4: 4 | AK4: 3 | AL4: 3 | AM4: 4 | AN4: 4 | AO4: 2 | AP4: 4 | AQ4: 3 | AR4: 4 | AS4: 3 | AT4: 4 | AU4: 4 | AV4: 3 | AW4: 4 | AX4: 4 | AY4: 4 | AZ4: 4 | BA4: 3 | BB4: 4 | BC4: 3 | BD4: 4 | BE4: 4 | BF4: 3 | BG4: 4 | BH4: 4 | BI4: 4 | BJ4: 2 | BK4: 4 | BL4: 4 | BM4: 4 | BN4: 4 | BO4: 4 | BP4: 4 | BQ4: 3 | BR4: 4 | BS4: 4 | BT4: 4 | BU4: 4 | BV4: 4 | BW4: 3 | BX4: 3 | BY4: 3 | BZ4: 4 | CA4: 3 | CB4: 4 | CC4: 4 | CD4: 4 | CE4: 3 | CF4: 4 | CG4: 3 | CH4: 4 | CI4: 4 | CJ4: 4 | CK4: 4 | CL4: 3 | CM4: 4 | CN4: 4 | CO4: 4 | CP4: 4 | CQ4: 4 | CR4: 4 | CS4: 4 | CT4: 4 | CU4: 4 | CV4: 3 | CW4: 4 | CX4: 3 | CY4: 3 | CZ4: 2 | DA4: 3 | DB4: 4 | DC4: 3 | DD4: 2 | DE4: 3 | DF4: 2 | DG4: 2 | DH4: 2 | DI4: 2 | DJ4: 3 | DK4: 4 | DL4: 2 | DM4: 3 | DN4: 3 | DO4: 3 | DP4: 4 | DQ4: 4 | DR4: 3 | DS4: 3 | DT4: 3 | DU4: 3 | DV4: 3 | DW4: 3
A5: 9º ano A | B5: 4 | C5: 4 | D5: 3 | E5: 4 | F5: 2 | G5: 4 | H5: 4 | I5: 4 | J5: 4 | K5: 4 | L5: 4 | M5: 2 | N5: 4 | O5: 4 | P5: 4 | Q5: 4 | R5: 4 | S5: 4 | T5: 4 | U5: 4 | V5: 4 | W5: 4 | X5: 4 | Y5: 4 | Z5: 4 | AA5: 4 | AB5: 4 | AC5: 4 | AD5: 3 | AE5: 4 | AF5: 3 | AG5: 3 | AH5: 2 | AI5: 4 | AJ5: 3 | AK5: 4 | AL5: 4 | AM5: 4 | AN5: 4 | AO5: 4 | AP5: 4 | AQ5: 4 | AR5: 4 | AS5: 4 | AT5: 4 | AU5: 4 | AV5: 4 | AW5: 4 | AX5: 4 | AY5: 4 | AZ5: 4 | BA5: 4 | BB5: 4 | BC5: 4 | BD5: 4 | BE5: 4 | BF5: 3 | BG5: 4 | BH5: 2 | BI5: 4 | BJ5: 1 | BK5: 4 | BL5: 4 | BM5: 3 | BN5: 3 | BO5: 3 | BP5: 3 | BQ5: 3 | BR5: 3 | BS5: 4 | BT5: 4 | BU5: 4 | BV5: 4 | BW5: 4 | BX5: 4 | BY5: 4 | BZ5: 4 | CA5: 3 | CB5: 2 | CC5: 3 | CD5: 4 | CE5: 1 | CF5: 2 | CG5: 4 | CH5: 4 | CI5: 4 | CJ5: 4 | CK5: 4 | CL5: 4 | CM5: 4 | CN5: 4 | CO5: 4 | CP5: 3 | CQ5: 3 | CR5: 4 | CS5: 4 | CT5: 4 | CU5: 4 | CV5: 4 | CW5: 4 | CX5: 2 | CY5: 4 | CZ5: 4 | DA5: 4 | DB5: 4 | DC5: 4 | DD5: 4 | DE5: 4 | DF5: 4 | DG5: 4 | DH5: 4 | DI5: 4 | DJ5: 4 | DK5: 4 | DL5: 4 | DM5: 4 | DN5: 4 | DO5: 4 | DP5: 4 | DQ5: 4 | DR5: 2 | DS5: 4 | DT5: 4 | DU5: 4 | DV5: 4 | DW5: 4
A6: 9º ano A | B6: 4 | C6: 4 | D6: 4 | E6: 4 | F6: 4 | G6: 4 | H6: 4 | I6: 4 | J6: 4 | K6: 3 | L6: 3 | M6: 3 | P6: 4 | Q6: 4 | R6: 4 | S6: 4 | T6: 4 | U6: 4 | V6: 4 | W6: 2 | X6: 3 | Y6: 3 | Z6: 2 | AA6: 3 | AB6: 3 | AC6: 2 | AD6: 3 | AE6: 2 | AF6: 2 | AG6: 2 | AH6: 2 | AI6: 3 | AJ6: 2 | AK6: 3 | AL6: 3 | AM6: 3 | AN6: 3 | AO6: 3 | AP6: 3 | AQ6: 3 | AR6: 3 | AS6: 3 | AT6: 3 | AU6: 3 | AV6: 3 | AW6: 3 | AX6: 3 | AY6: 3 | AZ6: 3 | BA6: 3 | BB6: 3 | BC6: 3 | BD6: 3 | BE6: 3 | BF6: 1 | BG6: 1 | BH6: 1 | BI6: 1 | BJ6: 1 | BK6: 1 | BL6: 1 | BM6: 3 | BN6: 3 | BO6: 3 | BP6: 3 | BQ6: 3 | BR6: 3 | BS6: 3 | BT6: 4 | BU6: 4 | BV6: 4 | BW6: 4 | BX6: 4 | BY6: 4 | BZ6: 4 | CA6: 2 | CB6: 2 | CC6: 2 | CD6: 2 | CE6: 2 | CF6: 2 | CG6: 3 | CH6: 4 | CI6: 4 | CJ6: 4 | CK6: 4 | CL6: 4 | CM6: 4 | CN6: 4 | CO6: 3 | CP6: 3 | CQ6: 4 | CR6: 3 | CS6: 4 | CT6: 4 | CU6: 3 | CV6: 4 | CW6: 4 | CX6: 4 | CY6: 4 | CZ6: 4 | DA6: 4 | DB6: 4 | DC6: 4 | DD6: 3 | DE6: 4 | DF6: 4 | DG6: 4 | DH6: 3 | DI6: 4 | DJ6: 3 | DK6: 3 | DL6: 4 | DM6: 4 | DN6: 3 | DO6: 4 | DP6: 3 | DQ6: 2 | DR6: 2 | DS6: 3 | DT6: 3 | DU6: 3 | DV6: 3 | DW6: 3
A7: 9º ano A | B7: 4 | C7: 4 | D7: 3 | E7: 4 | F7: 3 | G7: 4 | H7: 4 | I7: 4 | J7: 4 | K7: 4 | L7: 4 | M7: 3 | N7: 4 | O7: 4 | P7: 3 | Q7: 4 | R7: 4 | S7: 4 | T7: 3 | U7: 4 | V7: 3 | W7: 3 | X7: 4 | Y7: 3 | Z7: 4 | AA7: 3 | AB7: 4 | AC7: 4 | AD7: 3 | AE7: 3 | AF7: 2 | AG7: 4 | AH7: 1 | AI7: 3 | AJ7: 2 | AK7: 4 | AL7: 4 | AM7: 4 | AN7: 4 | AO7: 4 | AP7: 4 | AQ7: 4 | AR7: 4 | AS7: 4 | AT7: 4 | AU7: 4 | AV7: 4 | AW7: 4 | AX7: 4 | AY7: 4 | AZ7: 4 | BA7: 4 | BB7: 4 | BC7: 4 | BD7: 4 | BE7: 4 | BF7: 2 | BG7: 3 | BH7: 2 | BI7: 3 | BJ7: 2 | BK7: 3 | BL7: 3 | BM7: 4 | BN7: 4 | BO7: 4 | BP7: 4 | BQ7: 4 | BR7: 4 | BS7: 4 | BT7: 4 | BU7: 4 | BV7: 4 | BW7: 4 | BX7: 4 | BY7: 4 | BZ7: 4 | CA7: 4 | CB7: 4 | CC7: 4 | CD7: 4 | CE7: 4 | CF7: 4 | CG7: 4 | CH7: 4 | CI7: 4 | CJ7: 4 | CK7: 4 | CL7: 4 | CM7: 4 | CN7: 4 | CO7: 4 | CP7: 4 | CQ7: 4 | CR7: 4 | CS7: 4 | CT7: 4 | CU7: 4 | CV7: 4 | CW7: 4 | CX7: 4 | CY7: 3 | CZ7: 2 | DA7: 2 | DB7: 4 | DC7: 4 | DD7: 4 | DE7: 4 | DF7: 4 | DG7: 4 | DH7: 4 | DI7: 4 | DJ7: 4 | DK7: 4 | DL7: 4 | DM7: 4 | DN7: 4 | DO7: 4 | DP7: 4 | DQ7: 2 | DR7: 2 | DS7: 2 | DT7: 4 | DU7: 2 | DV7: 3 | DW7: 3
A8: 9º ano A | B8: 3 | C8: 4 | D8: 4 | E8: 4 | F8: 4 | G8: 4 | H8: 4 | I8: 4 | J8: 4 | K8: 3 | L8: 4 | M8: 3 | N8: 4 | O8: 4 | P8: 4 | Q8: 4 | R8: 4 | S8: 4 | T8: 4 | U8: 4 | V8: 4 | W8: 3 | X8: 4 | Y8: 3 | Z8: 3 | AA8: 3 | AB8: 4 | AC8: 4 | AD8: 2 | AE8: 3 | AF8: 2 | AG8: 4 | AH8: 1 | AI8: 2 | AJ8: 1 | AK8: 3 | AL8: 3 | AM8: 3 | AN8: 3 | AO8: 3 | AP8: 2 | AQ8: 2 | AR8: 4 | AS8: 4 | AT8: 4 | AU8: 4 | AV8: 4 | AW8: 4 | AX8: 4 | AY8: 4 | AZ8: 4 | BA8: 4 | BB8: 4 | BC8: 4 | BD8: 4 | BE8: 4 | BF8: 1 | BG8: 1 | BH8: 1 | BI8: 1 | BJ8: 1 | BK8: 1 | BL8: 1 | BM8: 4 | BN8: 4 | BO8: 4 | BP8: 4 | BQ8: 4 | BR8: 4 | BS8: 4 | BT8: 4 | BU8: 4 | BV8: 4 | BW8: 4 | BX8: 4 | BY8: 4 | BZ8: 4 | CA8: 1 | CB8: 1 | CC8: 1 | CD8: 1 | CE8: 1 | CF8: 1 | CG8: 1 | CH8: 4 | CI8: 4 | CJ8: 4 | CK8: 4 | CL8: 4 | CM8: 4 | CN8: 4 | CO8: 4 | CP8: 4 | CQ8: 4 | CR8: 4 | CS8: 4 | CT8: 4 | CU8: 4 | CV8: 4 | CW8: 4 | CX8: 4 | CY8: 4 | CZ8: 4 | DA8: 4 | DB8: 4 | DC8: 3 | DD8: 4 | DE8: 3 | DF8: 3 | DG8: 4 | DH8: 3 | DI8: 4 | DJ8: 4 | DK8: 4 | DL8: 4 | DM8: 4 | DN8: 4 | DO8: 4 | DP8: 4 | DQ8: 4 | DR8: 4 | DS8: 4 | DT8: 4 | DU8: 4 | DV8: 4 | DW8: 4
A9: 9º ano A | B9: 4 | C9: 4 | D9: 4 | E9: 4 | F9: 4 | G9: 4 | H9: 4 | I9: 4 | J9: 4 | K9: 4 | L9: 4 | M9: 4 | N9: 4 | O9: 4 | P9: 4 | Q9: 4 | R9: 4 | S9: 4 | T9: 4 | U9: 4 | V9: 4 | W9: 4 | X9: 3 | Y9: 3 | Z9: 4 | AA9: 3 | AB9: 4 | AC9: 4 | AD9: 2 | AE9: 1 | AF9: 1 | AG9: 2 | AH9: 1 | AI9: 1 | AJ9: 1 | AK9: 3 | AL9: 3 | AM9: 3 | AN9: 2 | AO9: 3 | AP9: 2 | AQ9: 2 | AR9: 4 | AS9: 4 | AT9: 3 | AU9: 4 | AV9: 2 | AW9: 4 | AX9: 3 | AY9: 4 | AZ9: 4 | BA9: 4 | BB9: 4 | BC9: 4 | BD9: 4 | BE9: 4 | BF9: 2 | BG9: 2 | BH9: 2 | BI9: 2 | BJ9: 2 | BK9: 2 | BL9: 1 | BM9: 3 | BN9: 3 | BO9: 4 | BP9: 4 | BQ9: 3 | BR9: 3 | BS9: 4 | BT9: 4 | BU9: 4 | BV9: 4 | BW9: 4 | BX9: 4 | BY9: 4 | BZ9: 4 | CA9: 2 | CB9: 2 | CC9: 2 | CD9: 3 | CE9: 2 | CF9: 2 | CG9: 2 | CH9: 4 | CI9: 4 | CJ9: 4 | CK9: 4 | CL9: 4 | CM9: 4 | CN9: 4 | CO9: 4 | CP9: 4 | CQ9: 4 | CR9: 4 | CS9: 4 | CT9: 4 | CU9: 4 | CV9: 4 | CW9: 4 | CX9: 4 | CY9: 4 | CZ9: 4 | DA9: 4 | DB9: 4 | DC9: 4 | DD9: 4 | DE9: 3 | DF9: 4 | DG9: 4 | DH9: 4 | DI9: 4 | DJ9: 4 | DK9: 4 | DL9: 4 | DM9: 4 | DN9: 4 | DO9: 4 | DP9: 4 | DQ9: 3 | DR9: 3 | DS9: 3 | DT9: 3 | DU9: 3 | DV9: 3 | DW9: 4
A10: 9º ano A
A11: 9º ano A | B11: 4 | C11: 4 | D11: 4 | E11: 4 | F11: 4 | G11: 4 | H11: 4 | I11: 4 | J11: 3 | K11: 4 | L11: 4 | M11: 4 | N11: 2 | O11: 4 | P11: 4 | Q11: 4 | R11: 4 | S11: 4 | T11: 4 | U11: 4 | V11: 4 | W11: 2 | X11: 2 | Y11: 3 | Z11: 2 | AA11: 3 | AB11: 2 | AC11: 3 | AD11: 1 | AE11: 1 | AF11: 1 | AG11: 1 | AH11: 1 | AI11: 1 | AJ11: 1 | AK11: 3 | AL11: 2 | AM11: 3 | AN11: 2 | AO11: 3 | AP11: 2 | AQ11: 3 | AR11: 4 | AS11: 4 | AT11: 4 | AU11: 4 | AV11: 4 | AW11: 4 | AX11: 4 | AY11: 3 | AZ11: 3 | BA11: 4 | BB11: 4 | BC11: 4 | BD11: 3 | BE11: 4 | BF11: 2 | BG11: 2 | BH11: 2 | BI11: 2 | BJ11: 2 | BK11: 3 | BL11: 3 | BM11: 4 | BN11: 3 | BO11: 4 | BP11: 3 | BQ11: 4 | BR11: 3 | BS11: 4 | BT11: 4 | BU11: 4 | BV11: 4 | BW11: 4 | BX11: 4 | BY11: 4 | BZ11: 4 | CA11: 1 | CB11: 1 | CC11: 1 | CD11: 3 | CE11: 1 | CF11: 1 | CG11: 2 | CH11: 4 | CI11: 4 | CJ11: 4 | CK11: 4 | CL11: 4 | CM11: 4 | CN11: 4 | CO11: 4 | CP11: 4 | CQ11: 4 | CR11: 4 | CS11: 4 | CT11: 4 | CU11: 4 | CV11: 4 | CW11: 4 | CX11: 4 | CY11: 4 | CZ11: 4 | DA11: 4 | DB11: 4 | DC11: 4 | DD11: 4 | DE11: 4 | DF11: 4 | DG11: 4 | DH11: 4 | DI11: 4 | DJ11: 4 | DK11: 3 | DL11: 4 | DM11: 3 | DN11: 4 | DO11: 3 | DP11: 4 | DQ11: 4 | DR11: 3 | DS11: 4 | DT11: 4 | DU11: 4 | DV11: 4 | DW11: 4
A12: 9º ano A | B12: 3 | C12: 4 | D12: 3 | E12: 4 | F12: 2 | G12: 4 | H12: 3 | I12: 4 | J12: 4 | K12: 3 | L12: 3 | M12: 3 | N12: 4 | O12: 4 | P12: 3 | Q12: 3 | R12: 3 | S12: 4 | T12: 3 | U12: 4 | V12: 4 | W12: 2 | X12: 3 | Y12: 4 | Z12: 2 | AA12: 2 | AB12: 3 | AC12: 4 | AD12: 1 | AE12: 2 | AF12: 1 | AG12: 3 | AH12: 1 | AI12: 1 | AJ12: 1 | AK12: 3 | AL12: 3 | AM12: 4 | AN12: 4 | AO12: 4 | AP12: 3 | AQ12: 3 | AR12: 2 | AS12: 2 | AT12: 3 | AU12: 2 | AV12: 2 | AW12: 3 | AX12: 2 | AY12: 4 | AZ12: 4 | BA12: 4 | BB12: 4 | BC12: 4 | BD12: 4 | BE12: 4 | BF12: 1 | BG12: 2 | BH12: 1 | BI12: 1 | BJ12: 1 | BK12: 3 | BL12: 2 | BM12: 3 | BN12: 4 | BO12: 3 | BP12: 4 | BQ12: 3 | BR12: 4 | BS12: 3 | BT12: 4 | BU12: 3 | BV12: 2 | BW12: 3 | BX12: 3 | BY12: 3 | BZ12: 3 | CA12: 1 | CB12: 2 | CC12: 1 | CD12: 2 | CE12: 1 | CF12: 2 | CG12: 2 | CH12: 4 | CI12: 4 | CJ12: 4 | CK12: 4 | CL12: 4 | CM12: 4 | CN12: 4 | CO12: 4 | CP12: 4 | CQ12: 4 | CR12: 4 | CS12: 4 | CT12: 4 | CU12: 4 | CV12: 4 | CW12: 4 | CX12: 4 | CY12: 4 | CZ12: 4 | DA12: 4 | DB12: 4 | DC12: 4 | DD12: 4 | DE12: 4 | DF12: 4 | DG12: 4 | DH12: 4 | DI12: 4 | DJ12: 3 | DK12: 3 | DL12: 3 | DM12: 3 | DN12: 3 | DO12: 2 | DP12: 3 | DQ12: 4 | DR12: 4 | DS12: 4 | DT12: 4 | DU12: 4 | DV12: 4 | DW12: 4
A13: 9º ano A | B13: 4 | C13: 4 | D13: 4 | E13: 4 | F13: 4 | G13: 4 | H13: 4 | I13: 3 | J13: 2 | K13: 4 | L13: 3 | M13: 2 | N13: 3 | O13: 2 | P13: 4 | Q13: 3 | R13: 3 | S13: 2 | T13: 3 | U13: 3 | V13: 3 | W13: 1 | X13: 1 | Y13: 2 | Z13: 2 | AA13: 1 | AB13: 1 | AC13: 1 | AD13: 2 | AE13: 1 | AF13: 2 | AG13: 1 | AH13: 2 | AI13: 1 | AJ13: 1 | AK13: 3 | AL13: 4 | AM13: 4 | AN13: 4 | AO13: 4 | AP13: 4 | AQ13: 4 | AR13: 3 | AS13: 2 | AT13: 3 | AU13: 2 | AV13: 2 | AW13: 3 | AX13: 3 | AY13: 4 | AZ13: 4 | BB13: 4 | BC13: 3 | BD13: 3 | BE13: 4 | BF13: 2 | BG13: 2 | BH13: 2 | BI13: 2 | BJ13: 2 | BK13: 2 | BL13: 2 | BM13: 1 | BN13: 1 | BO13: 1 | BP13: 1 | BQ13: 1 | BR13: 1 | BS13: 1 | BT13: 3 | BU13: 3 | BV13: 3 | BW13: 3 | BX13: 3 | BY13: 3 | BZ13: 3 | CA13: 1 | CB13: 1 | CC13: 1 | CD13: 1 | CE13: 1 | CF13: 1 | CG13: 1 | CH13: 4 | CI13: 4 | CJ13: 4 | CK13: 4 | CL13: 4 | CM13: 4 | CN13: 4 | CO13: 3 | CP13: 3 | CQ13: 3 | CR13: 3 | CS13: 3 | CT13: 3 | CU13: 3 | CV13: 3 | CW13: 3 | CX13: 3 | CY13: 3 | CZ13: 3 | DA13: 3 | DB13: 3 | DC13: 3 | DD13: 3 | DE13: 3 | DF13: 3 | DG13: 3 | DH13: 2 | DI13: 2 | DJ13: 2 | DK13: 2 | DL13: 2 | DM13: 2 | DN13: 2 | DO13: 2 | DP13: 2 | DQ13: 2 | DR13: 2 | DS13: 2 | DT13: 2 | DU13: 2 | DV13: 2 | DW13: 2
A14: 9º ano A | B14: 4 | C14: 3 | D14: 3 | E14: 4 | F14: 3 | G14: 4 | H14: 4 | I14: 4 | J14: 3 | K14: 3 | M14: 3 | N14: 4 | O14: 4 | P14: 3 | Q14: 4 | R14: 4 | S14: 4 | T14: 3 | U14: 3 | V14: 4 | W14: 4 | X14: 3 | Y14: 4 | Z14: 4 | AA14: 4 | AB14: 4 | AC14: 3 | AD14: 3 | AE14: 4 | AF14: 4 | AG14: 4 | AH14: 2 | AI14: 4 | AJ14: 3 | AK14: 4 | AL14: 3 | AM14: 3 | AN14: 4 | AO14: 4 | AP14: 4 | AQ14: 4 | AR14: 3 | AS14: 4 | AT14: 4 | AU14: 4 | AV14: 3 | AW14: 4 | AX14: 4 | AY14: 4 | AZ14: 4 | BA14: 4 | BB14: 4 | BC14: 4 | BD14: 4 | BE14: 4 | BF14: 3 | BG14: 3 | BH14: 4 | BI14: 3 | BJ14: 4 | BK14: 3 | BL14: 4 | BM14: 4 | BN14: 3 | BO14: 4 | BP14: 4 | BQ14: 4 | BR14: 4 | BS14: 4 | BT14: 4 | BU14: 4 | BV14: 4 | BW14: 4 | BX14: 4 | BY14: 4 | BZ14: 4 | CA14: 3 | CB14: 4 | CC14: 4 | CD14: 4 | CE14: 3 | CF14: 3 | CG14: 4 | CH14: 4 | CI14: 4 | CJ14: 4 | CK14: 4 | CL14: 3 | CM14: 4 | CN14: 3 | CO14: 3 | CP14: 3 | CQ14: 4 | CR14: 3 | CS14: 4 | CT14: 4 | CU14: 4 | CV14: 3 | CW14: 4 | CX14: 3 | CY14: 3 | CZ14: 3 | DA14: 3 | DB14: 3 | DC14: 3 | DD14: 4 | DE14: 4 | DF14: 4 | DG14: 4 | DH14: 4 | DI14: 4 | DJ14: 4 | DK14: 4 | DL14: 4 | DM14: 4 | DN14: 4 | DO14: 4 | DP14: 4 | DQ14: 3 | DR14: 2 | DS14: 3 | DT14: 4 | DU14: 2 | DV14: 3 | DW14: 3
A15: 9º ano A | B15: 4 | C15: 3 | D15: 4 | E15: 3 | F15: 3 | G15: 4 | H15: 3 | I15: 4 | J15: 4 | K15: 4 | L15: 4 | M15: 4 | N15: 4 | O15: 4 | P15: 4 | Q15: 4 | R15: 4 | S15: 4 | T15: 4 | U15: 4 | V15: 4 | W15: 3 | X15: 4 | Y15: 3 | Z15: 2 | AA15: 3 | AB15: 4 | AC15: 3 | AD15: 3 | AE15: 3 | AF15: 3 | AG15: 3 | AH15: 4 | AI15: 4 | AJ15: 3 | AK15: 3 | AL15: 3 | AM15: 4 | AN15: 3 | AO15: 3 | AP15: 4 | AQ15: 4 | AR15: 3 | AS15: 3 | AT15: 3 | AU15: 3 | AV15: 3 | AW15: 3 | AX15: 4 | AY15: 4 | AZ15: 3 | BA15: 4 | BB15: 4 | BC15: 4 | BD15: 3 | BE15: 4 | BF15: 1 | BG15: 1 | BH15: 1 | BI15: 3 | BJ15: 3 | BK15: 2 | BL15: 3 | BM15: 3 | BN15: 4 | BO15: 3 | BP15: 4 | BQ15: 3 | BR15: 4 | BS15: 3 | BT15: 3 | BU15: 4 | BV15: 3 | BW15: 4 | BX15: 3 | BY15: 4 | BZ15: 4 | CA15: 1 | CB15: 1 | CC15: 1 | CD15: 1 | CE15: 1 | CF15: 1 | CG15: 2 | CH15: 4 | CI15: 4 | CJ15: 4 | CK15: 4 | CL15: 4 | CM15: 4 | CN15: 4 | CO15: 4 | CP15: 4 | CQ15: 3 | CR15: 4 | CS15: 4 | CT15: 3 | CU15: 4 | CV15: 2 | CW15: 4 | CX15: 2 | CY15: 4 | CZ15: 4 | DA15: 3 | DB15: 2 | DC15: 4 | DD15: 4 | DE15: 4 | DF15: 4 | DG15: 4 | DH15: 4 | DI15: 4 | DJ15: 3 | DK15: 3 | DL15: 3 | DM15: 3 | DN15: 3 | DO15: 4 | DP15: 4 | DQ15: 4 | DR15: 3 | DS15: 4 | DT15: 4 | DU15: 4 | DV15: 2 | DW15: 3
A16: 9º ano A | B16: 4 | C16: 4 | D16: 3 | E16: 4 | F16: 3 | G16: 3 | H16: 3 | I16: 3 | J16: 4 | K16: 4 | L16: 4 | M16: 4 | N16: 4 | O16: 4 | P16: 2 | Q16: 2 | R16: 4 | S16: 4 | T16: 3 | U16: 3 | V16: 2 | W16: 4 | X16: 4 | Y16: 2 | Z16: 4 | AA16: 3 | AB16: 4 | AC16: 4 | AD16: 2 | AE16: 2 | AF16: 2 | AG16: 2 | AH16: 2 | AI16: 2 | AJ16: 2 | AK16: 4 | AL16: 4 | AM16: 4 | AN16: 4 | AO16: 4 | AP16: 4 | AQ16: 4 | AR16: 4 | AS16: 4 | AT16: 4 | AU16: 4 | AV16: 4 | AW16: 4 | AX16: 4 | AY16: 4 | AZ16: 4 | BA16: 4 | BB16: 4 | BC16: 4 | BD16: 4 | BE16: 4 | BF16: 3 | BG16: 4 | BH16: 3 | BI16: 4 | BJ16: 1 | BK16: 3 | BL16: 3 | BM16: 4 | BN16: 4 | BO16: 4 | BP16: 4 | BQ16: 4 | BR16: 4 | BS16: 4 | BT16: 4 | BU16: 4 | BV16: 4 | BW16: 4 | BX16: 4 | BY16: 4 | BZ16: 4 | CA16: 2 | CB16: 2 | CC16: 2 | CD16: 4 | CE16: 2 | CF16: 2 | CG16: 3 | CH16: 4 | CI16: 4 | CJ16: 4 | CK16: 4 | CL16: 4 | CM16: 4 | CN16: 4 | CO16: 4 | CP16: 4 | CQ16: 4 | CR16: 4 | CS16: 4 | CT16: 4 | CU16: 4 | CV16: 2 | CW16: 4 | CX16: 3 | CY16: 3 | CZ16: 2 | DA16: 3 | DB16: 1 | DC16: 3 | DD16: 4 | DE16: 4 | DF16: 4 | DG16: 4 | DH16: 2 | DI16: 3 | DJ16: 4 | DK16: 4 | DL16: 4 | DM16: 4 | DN16: 4 | DO16: 4 | DP16: 4 | DQ16: 2 | DR16: 2 | DS16: 2 | DT16: 3 | DU16: 2 | DV16: 3 | DW16: 2
A17: 9º ano A | B17: 4 | C17: 4 | D17: 3 | E17: 4 | F17: 3 | G17: 4 | H17: 4 | I17: 4 | J17: 4 | K17: 4 | L17: 4 | M17: 4 | N17: 4 | O17: 4 | P17: 4 | Q17: 4 | R17: 4 | S17: 4 | T17: 4 | U17: 4 | V17: 4 | W17: 4 | X17: 4 | Y17: 3 | Z17: 2 | AA17: 2 | AB17: 4 | AC17: 3 | AD17: 1 | AE17: 1 | AF17: 1 | AG17: 1 | AH17: 1 | AI17: 4 | AJ17: 1 | AK17: 4 | AL17: 4 | AM17: 4 | AN17: 4 | AO17: 4 | AP17: 4 | AQ17: 4 | AR17: 4 | AS17: 4 | AT17: 4 | AU17: 4 | AV17: 4 | AW17: 4 | AX17: 4 | AY17: 4 | AZ17: 4 | BA17: 4 | BB17: 4 | BC17: 4 | BD17: 4 | BE17: 4 | BF17: 1 | BG17: 1 | BH17: 1 | BI17: 1 | BJ17: 1 | BK17: 1 | BL17: 1 | BM17: 4 | BN17: 4 | BO17: 4 | BP17: 2 | BQ17: 2 | BR17: 4 | BS17: 4 | BT17: 4 | BU17: 3 | BV17: 4 | BW17: 2 | BX17: 3 | BY17: 3 | BZ17: 3 | CA17: 1 | CB17: 1 | CC17: 1 | CD17: 1 | CE17: 1 | CF17: 1 | CG17: 1 | CH17: 4 | CI17: 4 | CJ17: 4 | CK17: 4 | CL17: 4 | CM17: 4 | CN17: 4 | CO17: 4 | CP17: 4 | CQ17: 4 | CR17: 4 | CS17: 4 | CT17: 4 | CU17: 4 | CV17: 3 | CW17: 3 | CX17: 3 | CY17: 4 | CZ17: 3 | DA17: 4 | DB17: 2 | DC17: 2 | DD17: 2 | DE17: 2 | DF17: 4 | DG17: 3 | DH17: 4 | DI17: 3 | DJ17: 4 | DK17: 4 | DL17: 4 | DM17: 4 | DN17: 4 | DO17: 4 | DP17: 4 | DQ17: 4 | DR17: 4 | DS17: 4 | DT17: 4 | DU17: 4 | DV17: 4 | DW17: 4
A18: 9º ano A | B18: 4 | C18: 4 | D18: 3 | E18: 3 | F18: 2 | G18: 4 | H18: 4 | I18: 4 | J18: 4 | K18: 4 | L18: 4 | M18: 4 | N18: 4 | O18: 4 | P18: 4 | Q18: 4 | R18: 4 | S18: 4 | T18: 4 | U18: 4 | V18: 4 | W18: 4 | X18: 4 | Y18: 4 | Z18: 4 | AA18: 4 | AB18: 4 | AC18: 4 | AD18: 1 | AE18: 1 | AF18: 1 | AG18: 1 | AH18: 1 | AI18: 1 | AJ18: 1 | AK18: 4 | AL18: 4 | AM18: 4 | AN18: 4 | AO18: 4 | AP18: 4 | AQ18: 4 | AR18: 4 | AS18: 4 | AT18: 4 | AU18: 4 | AV18: 4 | AW18: 4 | AX18: 4 | AY18: 4 | AZ18: 4 | BA18: 4 | BB18: 4 | BC18: 4 | BD18: 4 | BE18: 4 | BF18: 2 | BG18: 2 | BH18: 2 | BI18: 2 | BJ18: 2 | BK18: 2 | BL18: 2 | BM18: 4 | BN18: 4 | BO18: 4 | BP18: 4 | BQ18: 4 | BR18: 4 | BS18: 4 | BT18: 4 | BU18: 4 | BV18: 4 | BW18: 4 | BX18: 4 | BY18: 4 | BZ18: 4 | CA18: 3 | CB18: 3 | CC18: 3 | CD18: 3 | CE18: 3 | CF18: 3 | CG18: 3 | CH18: 4 | CI18: 4 | CJ18: 4 | CK18: 4 | CL18: 4 | CM18: 4 | CN18: 4 | CO18: 4 | CP18: 4 | CQ18: 4 | CR18: 4 | CS18: 4 | CT18: 4 | CU18: 4 | CV18: 4 | CW18: 4 | CX18: 4 | CY18: 4 | CZ18: 4 | DA18: 4 | DB18: 4 | DC18: 4 | DD18: 4 | DE18: 4 | DF18: 4 | DG18: 4 | DH18: 4 | DI18: 4 | DJ18: 4 | DK18: 4 | DL18: 4 | DM18: 4 | DN18: 4 | DO18: 4 | DP18: 4 | DQ18: 2 | DR18: 2 | DS18: 2 | DT18: 2 | DU18: 2 | DV18: 2 | DW18: 2
A19: 9º ano A | B19: 4 | C19: 4 | D19: 4 | E19: 4 | F19: 4 | G19: 4 | H19: 4 | I19: 2 | J19: 2 | K19: 4 | L19: 3 | M19: 3 | N19: 3 | O19: 3 | P19: 4 | Q19: 4 | R19: 4 | S19: 4 | T19: 4 | U19: 4 | V19: 4 | W19: 2 | X19: 2 | Y19: 2 | Z19: 2 | AA19: 2 | AB19: 2 | AC19: 2 | AD19: 2 | AE19: 2 | AF19: 2 | AG19: 2 | AH19: 2 | AI19: 2 | AJ19: 2 | AK19: 2 | AL19: 2 | AM19: 2 | AN19: 2 | AO19: 2 | AP19: 2 | AQ19: 2 | AR19: 2 | AS19: 2 | AT19: 2 | AU19: 2 | AV19: 2 | AW19: 2 | AX19: 2 | AY19: 4 | AZ19: 4 | BA19: 4 | BB19: 4 | BC19: 4 | BD19: 4 | BE19: 4 | BF19: 2 | BG19: 2 | BH19: 2 | BI19: 2 | BJ19: 2 | BK19: 2 | BL19: 2 | BM19: 1 | BN19: 2 | BO19: 1 | BP19: 2 | BQ19: 1 | BR19: 2 | BS19: 1 | BT19: 4 | BU19: 4 | BV19: 4 | BW19: 4 | BX19: 4 | BY19: 4 | BZ19: 4 | CA19: 1 | CB19: 1 | CC19: 1 | CD19: 1 | CE19: 1 | CF19: 1 | CG19: 1 | CH19: 4 | CI19: 4 | CJ19: 4 | CK19: 4 | CL19: 4 | CM19: 4 | CN19: 4 | CO19: 3 | CP19: 2 | CQ19: 3 | CR19: 2 | CS19: 3 | CT19: 2 | CU19: 3 | CV19: 2 | CW19: 3 | CX19: 2 | CY19: 4 | CZ19: 2 | DA19: 2 | DB19: 2 | DC19: 4 | DD19: 4 | DE19: 4 | DF19: 4 | DG19: 4 | DH19: 4 | DI19: 4 | DJ19: 2 | DK19: 1 | DL19: 2 | DM19: 1 | DN19: 2 | DO19: 1 | DP19: 2 | DQ19: 4 | DR19: 4 | DS19: 4 | DT19: 4 | DU19: 4 | DV19: 4 | DW19: 4
A20: 9º ano A | B20: 4 | C20: 4 | D20: 3 | E20: 4 | F20: 3 | G20: 4 | H20: 4 | I20: 4 | J20: 4 | K20: 3 | L20: 4 | M20: 4 | N20: 4 | O20: 3 | P20: 4 | Q20: 4 | R20: 4 | S20: 4 | T20: 4 | U20: 4 | V20: 4 | W20: 4 | X20: 3 | Y20: 3 | Z20: 4 | AA20: 4 | AB20: 3 | AC20: 4 | AD20: 1 | AE20: 4 | AF20: 3 | AG20: 2 | AH20: 4 | AI20: 4 | AJ20: 1 | AK20: 4 | AL20: 4 | AM20: 4 | AN20: 4 | AO20: 4 | AP20: 4 | AQ20: 4 | AR20: 3 | AS20: 3 | AT20: 4 | AU20: 4 | AV20: 4 | AW20: 4 | AX20: 3 | AY20: 4 | AZ20: 3 | BA20: 2 | BB20: 4 | BC20: 2 | BD20: 4 | BE20: 4 | BF20: 4 | BG20: 4 | BH20: 2 | BI20: 4 | BJ20: 2 | BK20: 4 | BL20: 4 | BM20: 4 | BN20: 4 | BO20: 4 | BP20: 4 | BQ20: 4 | BR20: 4 | BS20: 4 | BT20: 4 | BU20: 4 | BV20: 4 | BW20: 4 | BX20: 4 | BY20: 4 | BZ20: 4 | CA20: 1 | CB20: 2 | CC20: 2 | CD20: 4 | CE20: 2 | CF20: 4 | CG20: 4 | CH20: 4 | CI20: 4 | CJ20: 4 | CK20: 4 | CL20: 4 | CM20: 4 | CN20: 4 | CO20: 4 | CP20: 4 | CQ20: 4 | CR20: 4 | CS20: 3 | CT20: 4 | CU20: 4 | CV20: 1 | CW20: 4 | CX20: 3 | CY20: 4 | CZ20: 4 | DA20: 4 | DB20: 4 | DC20: 3 | DD20: 3 | DE20: 3 | DF20: 3 | DG20: 3 | DH20: 3 | DI20: 3 | DJ20: 3 | DK20: 3 | DL20: 3 | DM20: 3 | DN20: 3 | DO20: 3 | DP20: 4 | DQ20: 4 | DR20: 2 | DS20: 4 | DT20: 3 | DU20: 4 | DV20: 4 | DW20: 4
A21: 9º ano A | B21: 4 | C21: 4 | D21: 3 | E21: 3 | F21: 2 | G21: 3 | H21: 4 | I21: 4 | J21: 4 | K21: 4 | L21: 4 | M21: 2 | N21: 4 | O21: 4 | P21: 4 | Q21: 4 | R21: 4 | S21: 4 | T21: 2 | U21: 4 | V21: 4 | W21: 1 | X21: 2 | Y21: 2 | Z21: 1 | AA21: 1 | AB21: 3 | AC21: 2 | AD21: 3 | AE21: 4 | AF21: 4 | AG21: 4 | AH21: 2 | AI21: 4 | AJ21: 4 | AK21: 1 | AL21: 1 | AM21: 1 | AN21: 1 | AO21: 1 | AP21: 1 | AQ21: 1 | AR21: 3 | AS21: 2 | AT21: 3 | AU21: 4 | AV21: 2 | AW21: 2 | AX21: 4 | AY21: 3 | AZ21: 4 | BA21: 4 | BB21: 4 | BC21: 1 | BD21: 4 | BE21: 4 | BF21: 3 | BG21: 3 | BH21: 4 | BI21: 4 | BJ21: 3 | BK21: 4 | BL21: 4 | BM21: 4 | BN21: 4 | BO21: 4 | BP21: 4 | BQ21: 3 | BR21: 4 | BS21: 4 | BT21: 4 | BU21: 4 | BV21: 4 | BW21: 4 | BX21: 3 | BY21: 4 | BZ21: 4 | CA21: 4 | CB21: 1 | CC21: 2 | CD21: 2 | CE21: 1 | CF21: 3 | CG21: 4 | CH21: 4 | CI21: 4 | CJ21: 4 | CK21: 4 | CL21: 4 | CM21: 4 | CN21: 4 | CO21: 4 | CP21: 3 | CQ21: 3 | CR21: 4 | CS21: 3 | CT21: 4 | CU21: 4 | CV21: 4 | CW21: 3 | CX21: 2 | CY21: 4 | CZ21: 2 | DA21: 4 | DB21: 4 | DC21: 2 | DD21: 1 | DE21: 2 | DF21: 1 | DG21: 3 | DH21: 1 | DI21: 1 | DJ21: 3 | DK21: 2 | DL21: 2 | DM21: 2 | DN21: 3 | DO21: 1 | DP21: 3 | DQ21: 4 | DR21: 4 | DS21: 3 | DT21: 4 | DU21: 4 | DV21: 4 | DW21: 4
A22: 9º ano A | B22: 4 | C22: 4 | D22: 3 | E22: 4 | F22: 3 | G22: 4 | H22: 4 | I22: 4 | J22: 4 | K22: 4 | L22: 4 | M22: 3 | N22: 4 | O22: 4 | P22: 4 | Q22: 4 | R22: 4 | S22: 4 | T22: 4 | U22: 4 | V22: 4 | W22: 2 | X22: 2 | Y22: 3 | Z22: 4 | AA22: 3 | AB22: 2 | AC22: 3 | AD22: 3 | AE22: 3 | AF22: 3 | AG22: 3 | AH22: 2 | AI22: 3 | AJ22: 2 | AK22: 4 | AL22: 4 | AM22: 4 | AN22: 4 | AO22: 4 | AP22: 4 | AQ22: 4 | AR22: 4 | AS22: 4 | AT22: 4 | AU22: 4 | AV22: 4 | AW22: 4 | AX22: 4 | AY22: 4 | AZ22: 4 | BA22: 4 | BB22: 4 | BC22: 4 | BD22: 4 | BE22: 4 | BF22: 2 | BG22: 3 | BH22: 2 | BI22: 4 | BJ22: 1 | BK22: 4 | BL22: 3 | BM22: 4 | BN22: 4 | BO22: 4 | BP22: 4 | BQ22: 4 | BR22: 4 | BS22: 4 | BT22: 4 | BU22: 4 | BV22: 4 | BW22: 4 | BX22: 4 | BY22: 4 | BZ22: 4 | CA22: 3 | CB22: 2 | CC22: 2 | CD22: 4 | CE22: 2 | CF22: 3 | CG22: 2 | CH22: 4 | CI22: 4 | CJ22: 4 | CK22: 4 | CL22: 4 | CM22: 4 | CN22: 4 | CO22: 4 | CP22: 4 | CQ22: 4 | CR22: 4 | CS22: 4 | CT22: 4 | CU22: 4 | CV22: 4 | CW22: 4 | CX22: 4 | CY22: 4 | CZ22: 4 | DA22: 4 | DB22: 4 | DC22: 3 | DD22: 3 | DE22: 3 | DF22: 3 | DG22: 3 | DH22: 3 | DI22: 3 | DJ22: 4 | DK22: 3 | DL22: 4 | DM22: 4 | DN22: 3 | DO22: 2 | DP22: 4 | DQ22: 4 | DR22: 2 | DS22: 4 | DT22: 4 | DU22: 3 | DV22: 3 | DW22: 4
A23: 9º ano A | B23: 4 | C23: 4 | D23: 4 | E23: 4 | F23: 4 | G23: 4 | H23: 4 | I23: 4 | J23: 4 | K23: 3 | L23: 4 | M23: 2 | N23: 4 | O23: 4 | P23: 4 | Q23: 4 | R23: 4 | S23: 4 | T23: 3 | U23: 4 | V23: 4 | W23: 3 | X23: 3 | Y23: 3 | Z23: 4 | AA23: 2 | AB23: 3 | AC23: 4 | AD23: 4 | AE23: 4 | AF23: 4 | AG23: 4 | AH23: 3 | AI23: 4 | AJ23: 4 | AK23: 4 | AL23: 4 | AM23: 4 | AN23: 4 | AO23: 4 | AP23: 4 | AQ23: 4 | AR23: 4 | AS23: 4 | AT23: 4 | AU23: 4 | AV23: 4 | AW23: 4 | AX23: 4 | AY23: 4 | AZ23: 4 | BA23: 4 | BB23: 4 | BC23: 4 | BD23: 4 | BE23: 4 | BF23: 4 | BG23: 4 | BH23: 4 | BI23: 3 | BJ23: 3 | BK23: 3 | BL23: 4 | BM23: 4 | BN23: 4 | BO23: 4 | BP23: 4 | BQ23: 4 | BR23: 4 | BS23: 4 | BT23: 4 | BU23: 4 | BV23: 4 | BW23: 4 | BX23: 4 | BY23: 4 | BZ23: 4 | CA23: 3 | CB23: 3 | CC23: 2 | CD23: 3 | CE23: 2 | CF23: 4 | CG23: 4 | CH23: 4 | CI23: 4 | CJ23: 4 | CK23: 4 | CL23: 4 | CM23: 4 | CN23: 4 | CO23: 4 | CP23: 4 | CQ23: 4 | CR23: 4 | CS23: 4 | CT23: 4 | CU23: 4 | CV23: 4 | CW23: 4 | CX23: 4 | CY23: 4 | CZ23: 4 | DA23: 4 | DB23: 4 | DC23: 4 | DD23: 4 | DE23: 4 | DF23: 4 | DG23: 4 | DH23: 4 | DI23: 4 | DJ23: 4 | DK23: 4 | DL23: 4 | DM23: 4 | DN23: 3 | DO23: 4 | DP23: 4 | DQ23: 4 | DR23: 2 | DS23: 4 | DT23: 4 | DU23: 4 | DV23: 4 | DW23: 4
A24: 9º ano A | B24: 3 | C24: 4 | D24: 4 | E24: 4 | F24: 3 | G24: 4 | H24: 3 | I24: 4 | J24: 4 | K24: 3 | L24: 4 | M24: 3 | N24: 4 | O24: 4 | P24: 4 | Q24: 4 | R24: 3 | S24: 4 | T24: 3 | U24: 4 | V24: 4 | W24: 4 | X24: 4 | Y24: 3 | Z24: 4 | AA24: 3 | AB24: 4 | AC24: 4 | AD24: 3 | AE24: 4 | AF24: 2 | AG24: 4 | AH24: 2 | AI24: 4 | AJ24: 3 | AK24: 2 | AL24: 3 | AM24: 2 | AN24: 3 | AO24: 3 | AP24: 4 | AQ24: 2 | AR24: 4 | AS24: 4 | AT24: 3 | AU24: 4 | AV24: 4 | AW24: 4 | AX24: 3 | AY24: 4 | AZ24: 4 | BA24: 4 | BB24: 4 | BC24: 4 | BD24: 4 | BE24: 4 | BF24: 3 | BG24: 4 | BH24: 2 | BI24: 3 | BJ24: 2 | BK24: 4 | BL24: 3 | BM24: 4 | BN24: 4 | BO24: 4 | BP24: 4 | BQ24: 3 | BR24: 4 | BS24: 4 | BT24: 4 | BU24: 4 | BV24: 4 | BW24: 4 | BX24: 3 | BY24: 4 | BZ24: 4 | CA24: 4 | CB24: 4 | CC24: 2 | CD24: 4 | CE24: 2 | CF24: 4 | CG24: 4 | CH24: 4 | CI24: 4 | CJ24: 4 | CK24: 4 | CL24: 4 | CM24: 4 | CN24: 4 | CO24: 4 | CP24: 4 | CQ24: 4 | CR24: 4 | CS24: 4 | CT24: 4 | CU24: 4 | CV24: 3 | CW24: 2 | CX24: 3 | CY24: 4 | CZ24: 1 | DA24: 4 | DB24: 4 | DC24: 4 | DD24: 4 | DE24: 3 | DF24: 3 | DG24: 3 | DH24: 4 | DI24: 4 | DJ24: 4 | DK24: 4 | DL24: 3 | DM24: 4 | DN24: 3 | DO24: 4 | DP24: 4 | DQ24: 2 | DR24: 2 | DS24: 4 | DT24: 4 | DU24: 4 | DV24: 4 | DW24: 4
A25: 9º ano A | B25: 4 | C25: 4 | D25: 4 | E25: 4 | F25: 3 | G25: 2 | H25: 4 | I25: 2 | J25: 4 | K25: 3 | L25: 4 | M25: 2 | N25: 4 | O25: 4 | P25: 4 | Q25: 4 | R25: 4 | S25: 3 | T25: 3 | U25: 4 | V25: 4 | W25: 4 | X25: 4 | Y25: 4 | Z25: 4 | AA25: 4 | AB25: 4 | AC25: 4 | AD25: 2 | AE25: 2 | AF25: 3 | AG25: 2 | AH25: 3 | AI25: 2 | AJ25: 4 | AK25: 2 | AL25: 2 | AM25: 2 | AN25: 2 | AO25: 2 | AP25: 2 | AQ25: 2 | AR25: 4 | AS25: 4 | AT25: 4 | AU25: 4 | AV25: 4 | AW25: 4 | AX25: 4 | AY25: 4 | AZ25: 4 | BA25: 4 | BB25: 4 | BC25: 4 | BD25: 4 | BE25: 4 | BF25: 2 | BG25: 3 | BH25: 2 | BI25: 2 | BJ25: 1 | BK25: 3 | BL25: 3 | BM25: 4 | BN25: 4 | BO25: 4 | BP25: 3 | BQ25: 4 | BR25: 4 | BS25: 4 | BT25: 4 | BU25: 4 | BV25: 4 | BW25: 3 | BX25: 4 | BY25: 4 | BZ25: 4 | CA25: 1 | CB25: 3 | CC25: 2 | CD25: 4 | CE25: 1 | CF25: 2 | CG25: 4 | CH25: 4 | CI25: 4 | CJ25: 4 | CK25: 4 | CL25: 4 | CM25: 4 | CN25: 4 | CO25: 4 | CP25: 4 | CQ25: 4 | CR25: 4 | CS25: 4 | CT25: 4 | CU25: 4 | CV25: 1 | CW25: 4 | CX25: 3 | CY25: 2 | CZ25: 2 | DA25: 4 | DB25: 4 | DC25: 3 | DD25: 3 | DE25: 4 | DF25: 3 | DG25: 4 | DH25: 4 | DI25: 4 | DJ25: 4 | DK25: 4 | DL25: 4 | DM25: 4 | DN25: 4 | DO25: 4 | DP25: 4 | DQ25: 2 | DR25: 2 | DS25: 4 | DT25: 4 | DU25: 4 | DV25: 1 | DW25: 4
A26: 9º ano A | B26: 4 | C26: 4 | D26: 3 | E26: 3 | F26: 3 | G26: 4 | H26: 4 | I26: 3 | J26: 3 | K26: 2 | L26: 4 | M26: 3 | N26: 2 | O26: 3 | P26: 2 | Q26: 3 | R26: 4 | S26: 3 | T26: 3 | U26: 2 | V26: 2 | W26: 2 | X26: 3 | Y26: 3 | Z26: 3 | AA26: 3 | AB26: 3 | AC26: 2 | AD26: 3 | AE26: 3 | AF26: 3 | AG26: 3 | AH26: 3 | AI26: 3 | AJ26: 3 | AK26: 3 | AL26: 3 | AM26: 3 | AN26: 3 | AO26: 3 | AP26: 3 | AQ26: 3 | AR26: 3 | AS26: 3 | AT26: 3 | AU26: 3 | AV26: 3 | AW26: 3 | AX26: 3 | AY26: 4 | AZ26: 3 | BA26: 2 | BB26: 4 | BC26: 3 | BD26: 3 | BE26: 3 | BF26: 3 | BG26: 3 | BH26: 3 | BI26: 3 | BJ26: 1 | BK26: 3 | BL26: 2 | BM26: 3 | BN26: 3 | BO26: 3 | BP26: 4 | BQ26: 3 | BR26: 3 | BS26: 3 | BT26: 4 | BU26: 4 | BV26: 3 | BW26: 4 | BX26: 3 | BY26: 3 | BZ26: 4 | CA26: 3 | CB26: 2 | CC26: 3 | CD26: 3 | CE26: 2 | CF26: 2 | CG26: 3 | CH26: 4 | CI26: 4 | CJ26: 3 | CK26: 3 | CL26: 4 | CM26: 4 | CN26: 4 | CO26: 4 | CP26: 3 | CQ26: 3 | CR26: 4 | CS26: 4 | CT26: 4 | CU26: 4 | CV26: 3 | CW26: 4 | CX26: 4 | CY26: 3 | CZ26: 4 | DA26: 4 | DB26: 4 | DC26: 3 | DD26: 4 | DE26: 3 | DF26: 4 | DG26: 3 | DH26: 3 | DI26: 4 | DJ26: 4 | DK26: 4 | DL26: 4 | DM26: 4 | DN26: 4 | DO26: 3 | DP26: 3 | DQ26: 2 | DR26: 3 | DS26: 3 | DT26: 4 | DU26: 3 | DV26: 3 | DW26: 3
A27: 9º ano A | B27: 4 | C27: 4 | D27: 3 | E27: 4 | F27: 3 | G27: 2 | H27: 4 | I27: 4 | J27: 4 | K27: 4 | L27: 4 | M27: 4 | N27: 4 | O27: 4 | P27: 4 | Q27: 4 | R27: 4 | S27: 4 | T27: 4 | U27: 4 | V27: 4 | W27: 3 | X27: 4 | Y27: 4 | Z27: 4 | AA27: 4 | AB27: 4 | AC27: 3 | AD27: 4 | AE27: 4 | AF27: 3 | AG27: 4 | AH27: 2 | AI27: 4 | AJ27: 2 | AK27: 4 | AL27: 4 | AM27: 4 | AN27: 4 | AO27: 4 | AP27: 4 | AQ27: 4 | AR27: 4 | AS27: 4 | AT27: 4 | AU27: 4 | AV27: 4 | AW27: 4 | AX27: 4 | AY27: 4 | AZ27: 4 | BA27: 4 | BB27: 4 | BC27: 4 | BD27: 4 | BF27: 2 | BG27: 4 | BH27: 4 | BI27: 4 | BJ27: 4 | BK27: 4 | BL27: 4 | BM27: 4 | BN27: 4 | BO27: 4 | BP27: 4 | BQ27: 4 | BR27: 4 | BS27: 4 | BT27: 4 | BU27: 4 | BV27: 4 | BW27: 4 | BX27: 4 | BY27: 4 | BZ27: 4 | CA27: 2 | CB27: 2 | CC27: 1 | CD27: 4 | CE27: 1 | CF27: 3 | CG27: 1 | CH27: 4 | CI27: 4 | CJ27: 4 | CK27: 4 | CL27: 4 | CM27: 4 | CN27: 4 | CO27: 4 | CP27: 4 | CQ27: 3 | CR27: 3 | CS27: 4 | CT27: 4 | CU27: 4 | CV27: 4 | CW27: 4 | CX27: 4 | CY27: 4 | CZ27: 3 | DA27: 4 | DB27: 4 | DC27: 3 | DD27: 4 | DE27: 4 | DF27: 4 | DG27: 4 | DH27: 3 | DI27: 3 | DJ27: 4 | DK27: 4 | DL27: 4 | DM27: 4 | DN27: 4 | DO27: 4 | DP27: 4 | DQ27: 3 | DR27: 2 | DS27: 3 | DT27: 4 | DU27: 3 | DV27: 4 | DW27: 4
A28: 9º ano A | B28: 4 | C28: 4 | D28: 3 | E28: 3 | F28: 3 | G28: 4 | H28: 3 | I28: 4 | J28: 4 | K28: 4 | L28: 4 | M28: 3 | N28: 4 | O28: 4 | P28: 4 | Q28: 4 | R28: 4 | S28: 4 | T28: 4 | U28: 4 | V28: 4 | W28: 3 | X28: 4 | Y28: 4 | Z28: 4 | AA28: 3 | AB28: 4 | AC28: 4 | AD28: 2 | AE28: 3 | AF28: 2 | AG28: 4 | AH28: 2 | AI28: 4 | AJ28: 2 | AK28: 3 | AL28: 3 | AM28: 4 | AN28: 3 | AO28: 3 | AP28: 4 | AQ28: 4 | AR28: 4 | AS28: 4 | AT28: 4 | AU28: 3 | AV28: 3 | AW28: 4 | AX28: 3 | AY28: 4 | AZ28: 3 | BA28: 3 | BB28: 4 | BC28: 3 | BD28: 4 | BE28: 3 | BF28: 2 | BG28: 3 | BH28: 2 | BI28: 3 | BJ28: 2 | BK28: 4 | BL28: 2 | BM28: 4 | BN28: 4 | BO28: 3 | BP28: 3 | BQ28: 3 | BR28: 4 | BS28: 3 | BT28: 4 | BU28: 4 | BV28: 4 | BW28: 4 | BX28: 4 | BY28: 4 | BZ28: 4 | CA28: 2 | CB28: 1 | CC28: 2 | CD28: 3 | CE28: 2 | CF28: 2 | CG28: 2 | CH28: 4 | CI28: 4 | CJ28: 4 | CK28: 4 | CL28: 4 | CM28: 4 | CN28: 4 | CO28: 4 | CP28: 4 | CQ28: 4 | CR28: 3 | CS28: 3 | CT28: 4 | CU28: 4 | CV28: 3 | CW28: 3 | CX28: 2 | CY28: 3 | CZ28: 4 | DA28: 3 | DB28: 3 | DC28: 4 | DD28: 4 | DE28: 4 | DF28: 4 | DG28: 4 | DH28: 4 | DI28: 4 | DJ28: 4 | DK28: 4 | DL28: 4 | DM28: 4 | DN28: 4 | DO28: 4 | DP28: 4 | DQ28: 2 | DR28: 2 | DS28: 2 | DT28: 3 | DU28: 2 | DV28: 4 | DW28: 2
A29: 9º ano A | B29: 4 | C29: 4 | D29: 4 | E29: 4 | F29: 3 | G29: 4 | H29: 4 | I29: 4 | J29: 4 | K29: 4 | L29: 3 | M29: 3 | N29: 4 | O29: 4 | P29: 4 | Q29: 4 | R29: 3 | S29: 4 | T29: 3 | U29: 4 | V29: 4 | W29: 3 | X29: 3 | Y29: 3 | Z29: 4 | AA29: 3 | AB29: 3 | AC29: 2 | AD29: 3 | AE29: 3 | AF29: 3 | AG29: 4 | AH29: 1 | AI29: 4 | AJ29: 3 | AK29: 4 | AL29: 4 | AM29: 4 | AN29: 4 | AO29: 4 | AP29: 4 | AQ29: 4 | AR29: 4 | AS29: 4 | AT29: 4 | AU29: 4 | AV29: 4 | AW29: 4 | AX29: 4 | AY29: 4 | AZ29: 4 | BA29: 4 | BB29: 4 | BC29: 4 | BD29: 4 | BE29: 3 | BF29: 3 | BG29: 4 | BH29: 3 | BI29: 2 | BJ29: 2 | BK29: 4 | BL29: 3 | BM29: 4 | BN29: 4 | BO29: 3 | BP29: 3 | BQ29: 3 | BR29: 4 | BS29: 3 | BT29: 4 | BU29: 4 | BV29: 4 | BW29: 4 | BX29: 4 | BY29: 4 | BZ29: 4 | CA29: 3 | CB29: 4 | CC29: 2 | CD29: 3 | CE29: 1 | CF29: 3 | CG29: 2 | CH29: 4 | CI29: 4 | CJ29: 4 | CK29: 4 | CL29: 4 | CM29: 4 | CN29: 4 | CO29: 4 | CP29: 4 | CQ29: 4 | CR29: 4 | CS29: 4 | CT29: 4 | CU29: 4 | CV29: 3 | CW29: 3 | CX29: 2 | CY29: 3 | CZ29: 3 | DA29: 3 | DB29: 3 | DC29: 4 | DD29: 4 | DE29: 4 | DF29: 4 | DG29: 4 | DH29: 4 | DI29: 4 | DJ29: 4 | DK29: 3 | DL29: 4 | DM29: 3 | DN29: 4 | DO29: 3 | DP29: 3 | DQ29: 3 | DR29: 2 | DS29: 3 | DT29: 4 | DU29: 4 | DV29: 3 | DW29: 3
A30: 9º ano A | B30: 4 | C30: 4 | D30: 3 | E30: 3 | F30: 3 | G30: 2 | H30: 3 | I30: 4 | J30: 4 | K30: 4 | L30: 4 | M30: 3 | N30: 4 | O30: 4 | P30: 4 | Q30: 4 | R30: 4 | S30: 4 | T30: 3 | U30: 4 | V30: 4 | W30: 4 | X30: 4 | Y30: 4 | Z30: 3 | AA30: 3 | AB30: 4 | AC30: 4 | AD30: 4 | AE30: 4 | AF30: 1 | AG30: 4 | AH30: 2 | AI30: 4 | AJ30: 3 | AK30: 4 | AL30: 3 | AM30: 4 | AN30: 4 | AO30: 3 | AP30: 3 | AQ30: 3 | AR30: 3 | AS30: 4 | AT30: 4 | AU30: 4 | AV30: 4 | AW30: 4 | AX30: 4 | AY30: 4 | AZ30: 3 | BA30: 4 | BB30: 4 | BC30: 3 | BD30: 4 | BE30: 4 | BF30: 2 | BG30: 2 | BH30: 1 | BI30: 2 | BJ30: 1 | BK30: 3 | BL30: 2 | BM30: 4 | BN30: 4 | BO30: 4 | BP30: 2 | BQ30: 3 | BR30: 4 | BS30: 4 | BT30: 4 | BU30: 4 | BV30: 4 | BW30: 4 | BX30: 4 | BY30: 4 | BZ30: 4 | CA30: 3 | CB30: 2 | CC30: 2 | CD30: 3 | CE30: 1 | CF30: 3 | CG30: 3 | CH30: 4 | CI30: 4 | CJ30: 4 | CK30: 4 | CL30: 4 | CM30: 4 | CN30: 4 | CO30: 3 | CP30: 4 | CQ30: 4 | CR30: 3 | CS30: 4 | CT30: 3 | CU30: 4 | CV30: 4 | CW30: 4 | CX30: 4 | CY30: 4 | CZ30: 4 | DA30: 4 | DB30: 4 | DC30: 3 | DD30: 3 | DE30: 4 | DF30: 4 | DG30: 4 | DH30: 2 | DI30: 4 | DJ30: 4 | DK30: 4 | DL30: 4 | DM30: 4 | DN30: 4 | DO30: 4 | DP30: 4 | DQ30: 2 | DR30: 2 | DS30: 2 | DT30: 2 | DU30: 2 | DV30: 3 | DW30: 2
A31: 9º ano A | B31: 4 | C31: 4 | D31: 3 | E31: 4 | F31: 2 | G31: 4 | H31: 4 | I31: 4 | J31: 3 | K31: 4 | L31: 4 | M31: 3 | N31: 4 | O31: 4 | P31: 4 | Q31: 4 | R31: 4 | S31: 4 | T31: 4 | U31: 4 | V31: 4 | W31: 4 | X31: 4 | Y31: 3 | Z31: 3 | AA31: 3 | AB31: 4 | AC31: 4 | AD31: 3 | AE31: 4 | AF31: 4 | AG31: 4 | AH31: 2 | AI31: 4 | AJ31: 4 | AK31: 3 | AL31: 4 | AM31: 2 | AN31: 4 | AO31: 2 | AP31: 4 | AQ31: 3 | AR31: 3 | AS31: 3 | AT31: 3 | AU31: 3 | AV31: 2 | AW31: 4 | AX31: 3 | AY31: 4 | AZ31: 4 | BA31: 4 | BB31: 4 | BC31: 4 | BD31: 4 | BE31: 4 | BF31: 3 | BG31: 4 | BH31: 4 | BI31: 4 | BJ31: 2 | BK31: 4 | BL31: 4 | BM31: 4 | BN31: 3 | BO31: 3 | BP31: 2 | BQ31: 2 | BR31: 3 | BS31: 4 | BT31: 4 | BU31: 3 | BV31: 4 | BW31: 4 | BX31: 4 | BY31: 3 | BZ31: 4 | CA31: 3 | CB31: 3 | CC31: 2 | CD31: 4 | CE31: 1 | CF31: 4 | CG31: 4 | CH31: 4 | CI31: 4 | CJ31: 4 | CK31: 4 | CL31: 4 | CM31: 4 | CN31: 4 | CO31: 3 | CP31: 3 | CQ31: 4 | CR31: 3 | CS31: 3 | CT31: 4 | CU31: 3 | CV31: 2 | CW31: 3 | CX31: 1 | CY31: 4 | CZ31: 4 | DA31: 3 | DB31: 4 | DC31: 2 | DD31: 4 | DE31: 4 | DF31: 3 | DG31: 4 | DH31: 4 | DI31: 3 | DJ31: 4 | DK31: 4 | DL31: 4 | DM31: 4 | DN31: 4 | DO31: 4 | DP31: 4 | DQ31: 4 | DR31: 4 | DS31: 2 | DT31: 4 | DU31: 3 | DV31: 4 | DW31: 4
A32: 9º ano A | B32: 4 | C32: 4 | D32: 4 | E32: 3 | F32: 4 | G32: 4 | H32: 4 | I32: 4 | J32: 4 | K32: 4 | L32: 4 | M32: 4 | N32: 4 | O32: 4 | P32: 4 | Q32: 4 | R32: 4 | S32: 4 | T32: 4 | U32: 4 | V32: 4 | W32: 3 | X32: 4 | Y32: 3 | Z32: 4 | AA32: 2 | AB32: 4 | AC32: 4 | AD32: 4 | AE32: 4 | AF32: 3 | AG32: 4 | AH32: 3 | AI32: 4 | AJ32: 4 | AK32: 4 | AL32: 4 | AM32: 4 | AN32: 4 | AO32: 3 | AP32: 4 | AQ32: 4 | AR32: 4 | AS32: 4 | AT32: 4 | AU32: 4 | AV32: 4 | AW32: 4 | AX32: 4 | AY32: 3 | AZ32: 2 | BA32: 3 | BB32: 2 | BC32: 3 | BD32: 3 | BE32: 4 | BF32: 4 | BG32: 4 | BH32: 4 | BI32: 3 | BJ32: 4 | BK32: 4 | BL32: 4 | BM32: 2 | BN32: 2 | BO32: 2 | BP32: 2 | BQ32: 3 | BR32: 2 | BS32: 3 | BT32: 3 | BU32: 4 | BV32: 4 | BW32: 4 | BX32: 4 | BY32: 4 | BZ32: 4 | CA32: 1 | CB32: 1 | CC32: 1 | CD32: 1 | CE32: 1 | CF32: 2 | CG32: 1 | CH32: 4 | CI32: 4 | CJ32: 4 | CK32: 4 | CL32: 4 | CM32: 4 | CN32: 4 | CO32: 4 | CP32: 4 | CQ32: 4 | CR32: 2 | CS32: 4 | CT32: 4 | CU32: 4 | CV32: 4 | CW32: 4 | CX32: 4 | CY32: 4 | CZ32: 4 | DA32: 3 | DB32: 4 | DC32: 4 | DD32: 4 | DE32: 4 | DF32: 4 | DG32: 4 | DH32: 4 | DI32: 4 | DJ32: 4 | DK32: 4 | DL32: 4 | DM32: 4 | DN32: 4 | DO32: 3 | DP32: 4 | DQ32: 4 | DR32: 4 | DS32: 4 | DT32: 4 | DU32: 4 | DV32: 4 | DW32: 4
A33: 9º ano A | B33: 4 | C33: 3 | D33: 3 | E33: 3 | F33: 2 | G33: 4 | H33: 3 | I33: 4 | J33: 4 | K33: 3 | L33: 3 | M33: 2 | N33: 3 | O33: 4 | P33: 2 | Q33: 3 | R33: 2 | S33: 2 | T33: 2 | U33: 2 | V33: 3 | W33: 2 | X33: 2 | Y33: 2 | Z33: 2 | AA33: 2 | AB33: 2 | AC33: 2 | AD33: 1 | AE33: 2 | AF33: 2 | AG33: 2 | AH33: 2 | AI33: 2 | AJ33: 2 | AK33: 3 | AM33: 3 | AN33: 3 | AO33: 3 | AP33: 3 | AQ33: 3 | AR33: 3 | AS33: 3 | AT33: 3 | AU33: 3 | AV33: 2 | AW33: 3 | AX33: 3 | AY33: 4 | AZ33: 4 | BA33: 4 | BB33: 4 | BC33: 4 | BD33: 4 | BE33: 4 | BF33: 1 | BG33: 1 | BH33: 2 | BI33: 2 | BJ33: 1 | BK33: 2 | BL33: 2 | BM33: 2 | BN33: 2 | BO33: 2 | BP33: 2 | BQ33: 2 | BR33: 2 | BS33: 2 | BT33: 3 | BU33: 3 | BV33: 3 | BW33: 3 | BX33: 3 | BY33: 3 | BZ33: 3 | CA33: 1 | CB33: 1 | CD33: 1 | CE33: 1 | CF33: 1 | CG33: 1 | CH33: 4 | CI33: 4 | CJ33: 4 | CK33: 4 | CL33: 4 | CM33: 4 | CN33: 4 | CO33: 3 | CP33: 3 | CQ33: 3 | CR33: 3 | CS33: 3 | CT33: 3 | CU33: 3 | CV33: 4 | CW33: 4 | CX33: 4 | CY33: 4 | CZ33: 4 | DA33: 4 | DB33: 4 | DC33: 3 | DD33: 3 | DE33: 3 | DF33: 3 | DG33: 2 | DH33: 3 | DI33: 3 | DJ33: 2 | DK33: 2 | DL33: 2 | DM33: 2 | DN33: 2 | DO33: 2 | DP33: 2 | DQ33: 3 | DR33: 3 | DS33: 3 | DT33: 3 | DU33: 3 | DV33: 3 | DW33: 3
A34: 9º ano A | B34: 4 | C34: 4 | D34: 3 | E34: 4 | F34: 2 | G34: 4 | H34: 4 | I34: 4 | J34: 4 | K34: 4 | L34: 4 | M34: 3 | N34: 4 | O34: 4 | P34: 4 | Q34: 4 | R34: 4 | S34: 4 | T34: 3 | U34: 4 | V34: 4 | W34: 2 | X34: 2 | Y34: 3 | Z34: 3 | AA34: 3 | AB34: 2 | AC34: 1 | AD34: 4 | AE34: 4 | AF34: 3 | AG34: 4 | AH34: 1 | AI34: 4 | AJ34: 2 | AK34: 3 | AL34: 4 | AM34: 2 | AN34: 3 | AO34: 1 | AP34: 4 | AQ34: 3 | AR34: 1 | AS34: 3 | AT34: 2 | AU34: 3 | AV34: 1 | AW34: 2 | AX34: 3 | AY34: 4 | AZ34: 4 | BA34: 3 | BB34: 3 | BC34: 3 | BD34: 4 | BE34: 4 | BF34: 2 | BG34: 3 | BH34: 1 | BI34: 4 | BJ34: 1 | BK34: 3 | BL34: 2 | BM34: 1 | BN34: 2 | BO34: 1 | BP34: 1 | BQ34: 1 | BR34: 2 | BS34: 1 | BT34: 3 | BU34: 3 | BV34: 4 | BW34: 4 | BX34: 3 | BY34: 3 | BZ34: 3 | CA34: 2 | CB34: 2 | CC34: 1 | CD34: 1 | CE34: 1 | CF34: 3 | CG34: 1 | CH34: 4 | CI34: 4 | CJ34: 3 | CK34: 3 | CL34: 2 | CM34: 4 | CN34: 4 | CO34: 3 | CP34: 2 | CQ34: 3 | CR34: 2 | CS34: 3 | CT34: 3 | CU34: 2 | CV34: 2 | CW34: 3 | CX34: 1 | CY34: 4 | CZ34: 2 | DA34: 1 | DB34: 1 | DC34: 2 | DD34: 3 | DE34: 4 | DF34: 4 | DG34: 2 | DH34: 1 | DI34: 4 | DJ34: 1 | DK34: 1 | DL34: 1 | DM34: 2 | DN34: 2 | DO34: 1 | DP34: 1 | DQ34: 1 | DR34: 1 | DS34: 3 | DT34: 3 | DU34: 2 | DV34: 3 | DW34: 1
A35: 9º ano B | B35: 3 | C35: 3 | D35: 3 | E35: 4 | F35: 3 | G35: 4 | H35: 4 | I35: 3 | J35: 3 | K35: 3 | L35: 3 | M35: 3 | N35: 3 | O35: 3 | P35: 4 | Q35: 4 | R35: 4 | S35: 4 | T35: 4 | U35: 4 | V35: 4 | W35: 3 | X35: 4 | Y35: 3 | Z35: 4 | AA35: 2 | AB35: 4 | AC35: 2 | AD35: 2 | AE35: 2 | AF35: 2 | AG35: 2 | AH35: 2 | AI35: 2 | AJ35: 2 | AK35: 4 | AL35: 4 | AM35: 4 | AN35: 4 | AO35: 4 | AP35: 4 | AQ35: 4 | AR35: 4 | AS35: 4 | AT35: 4 | AU35: 4 | AV35: 4 | AW35: 4 | AX35: 4 | AY35: 3 | AZ35: 3 | BA35: 4 | BB35: 3 | BC35: 2 | BD35: 4 | BE35: 2 | BF35: 2 | BH35: 2 | BI35: 2 | BJ35: 2 | BK35: 2 | BL35: 2 | BM35: 4 | BN35: 3 | BO35: 3 | BP35: 1 | BQ35: 3 | BR35: 3 | BS35: 2 | BT35: 4 | BU35: 4 | BV35: 4 | BW35: 4 | BX35: 4 | BY35: 4 | BZ35: 4 | CA35: 1 | CB35: 1 | CC35: 1 | CD35: 1 | CE35: 1 | CF35: 1 | CG35: 1 | CH35: 4 | CI35: 4 | CJ35: 4 | CK35: 4 | CL35: 4 | CM35: 4 | CN35: 4 | CO35: 4 | CP35: 4 | CQ35: 4 | CR35: 4 | CS35: 4 | CT35: 4 | CU35: 4 | CV35: 2 | CW35: 2 | CX35: 2 | CY35: 4 | CZ35: 2 | DA35: 3 | DB35: 3 | DC35: 1 | DD35: 1 | DE35: 1 | DF35: 1 | DG35: 1 | DH35: 1 | DI35: 1 | DJ35: 4 | DK35: 4 | DL35: 4 | DM35: 4 | DN35: 4 | DO35: 4 | DP35: 4 | DQ35: 4 | DR35: 4 | DS35: 4 | DT35: 4 | DU35: 3 | DV35: 4 | DW35: 4
A36: 9º ano B | B36: 3 | C36: 4 | D36: 3 | E36: 3 | F36: 3 | G36: 4 | H36: 4 | I36: 4 | J36: 4 | K36: 4 | L36: 4 | M36: 3 | N36: 4 | O36: 4 | P36: 4 | Q36: 4 | R36: 4 | S36: 4 | T36: 3 | U36: 4 | V36: 4 | W36: 4 | X36: 3 | Y36: 4 | Z36: 3 | AA36: 3 | AB36: 4 | AC36: 3 | AD36: 3 | AE36: 2 | AF36: 3 | AG36: 2 | AH36: 3 | AI36: 2 | AJ36: 3 | AK36: 4 | AL36: 4 | AM36: 4 | AN36: 4 | AO36: 4 | AP36: 4 | AQ36: 4 | AR36: 4 | AS36: 4 | AT36: 3 | AU36: 4 | AV36: 4 | AW36: 4 | AX36: 3 | AY36: 3 | AZ36: 4 | BA36: 4 | BB36: 4 | BC36: 3 | BD36: 4 | BE36: 4 | BF36: 2 | BG36: 2 | BH36: 2 | BI36: 2 | BJ36: 2 | BK36: 2 | BL36: 2 | BM36: 4 | BN36: 4 | BO36: 2 | BP36: 4 | BQ36: 4 | BR36: 4 | BS36: 4 | BT36: 4 | BU36: 4 | BV36: 4 | BW36: 4 | BX36: 4 | BY36: 4 | BZ36: 4 | CA36: 4 | CB36: 3 | CC36: 4 | CD36: 3 | CE36: 4 | CF36: 3 | CG36: 4 | CH36: 4 | CI36: 4 | CJ36: 4 | CK36: 4 | CL36: 4 | CM36: 4 | CN36: 4 | CO36: 4 | CP36: 4 | CQ36: 4 | CR36: 4 | CS36: 4 | CT36: 4 | CU36: 4 | CV36: 4 | CW36: 4 | CX36: 3 | CY36: 4 | CZ36: 4 | DA36: 4 | DB36: 4 | DC36: 1 | DD36: 1 | DE36: 1 | DF36: 1 | DG36: 1 | DH36: 1 | DI36: 1 | DJ36: 4 | DK36: 4 | DL36: 4 | DM36: 4 | DN36: 4 | DO36: 4 | DP36: 4 | DQ36: 3 | DR36: 4 | DS36: 3 | DT36: 3 | DU36: 3 | DV36: 2 | DW36: 4
